//Schematic to java Structure by jajo_11 | inspired by "MITHION'S .SCHEMATIC TO JAVA CONVERTINGTOOL"

package net.gargoyles.worldgen;

import java.util.Random;

import net.gargoyles.entity.EntityEvilGargoyle;
import net.gargoyles.registry.GBlocks;
import net.minecraft.block.Block;
import net.minecraft.block.material.Material;
import net.minecraft.block.state.IBlockState;
import net.minecraft.enchantment.Enchantment;
import net.minecraft.enchantment.EnchantmentData;
import net.minecraft.entity.item.EntityItemFrame;
import net.minecraft.entity.monster.EntityIllusionIllager;
import net.minecraft.entity.monster.EntityVindicator;
import net.minecraft.init.Blocks;
import net.minecraft.init.Items;
import net.minecraft.item.ItemEnchantedBook;
import net.minecraft.item.ItemStack;
import net.minecraft.tileentity.TileEntity;
import net.minecraft.tileentity.TileEntityChest;
import net.minecraft.util.EnumFacing;
import net.minecraft.util.ResourceLocation;
import net.minecraft.util.math.BlockPos;
import net.minecraft.util.math.MathHelper;
import net.minecraft.world.World;
import net.minecraft.world.gen.feature.WorldGenerator;
import net.minecraft.world.storage.loot.LootTableList;

public class WorldGenCathedrial extends WorldGenerator
{
	World world;

	@SuppressWarnings("deprecation")
	public boolean LocationIsValidSpawn(World world, int x, int y, int z)
	{

		IBlockState checkBlock = world.getBlockState(new BlockPos(x, y, z));
		IBlockState blockAbove = world.getBlockState(new BlockPos(x, y + 1, z));
		IBlockState blockBelow = world.getBlockState(new BlockPos(x, y - 1, z));

		if (blockAbove.getBlock() != Blocks.AIR)
		{
			return false;
		}
		if (checkBlock.getBlock().isOpaqueCube(checkBlock) && world.canSeeSky(new BlockPos(x, y + 1, z)))
		{
			return true;
		}
		else if (checkBlock.getBlock() == Blocks.SNOW_LAYER && blockBelow.getBlock().isOpaqueCube(blockBelow) && world.canSeeSky(new BlockPos(x, y + 1, z)))
		{
			return true;
		}
		else if (checkBlock.getBlock().getMaterial(checkBlock) == Material.PLANTS && blockBelow.getBlock().isOpaqueCube(blockBelow) && world.canSeeSky(new BlockPos(x, y + 1, z)))
		{
			return true;
		}
		else
		{
			return false;
		}
	}

	public boolean generate(World world, Random rand, BlockPos pos)
	{
		this.world = world;
		
		int x = pos.getX();
		int y = pos.getY();
		int z = pos.getZ();

		if (LocationIsValidSpawn(world, x, y, z))
		{
		    	generate_r0(world, rand, x, y, z);
		       return true;
		}
		else
		{
		       return false;
		}
	}

	public boolean generate_r0(World world, Random rand, int x, int y, int z)
	{
		x -= 6;
		z -= 15;
		
        for (int k2 = 0; k2 <= 11; ++k2)
        {
            for (int l2 = 0; l2 <= 29; ++l2)
            {
                for (int j = 0; j <= 28; ++j)
                {
                    int i3 = x + k2;
                    int k = y + j;
                    int l = z + l2;
                    BlockPos blockpos = new BlockPos(i3, k, l);
                    IBlockState iblockstate = this.world.getBlockState(blockpos);
                    Block block = iblockstate.getBlock();

                    if (!block.isAir(iblockstate, this.world, blockpos))
                    {
                        this.world.destroyBlock(blockpos, false);
                    }
                }
            }
        }
		
		this.setBlock(x + 0, y + 0, z + 0, Blocks.STONEBRICK, 0, 3);
		this.setBlock(x + 1, y + 0, z + 0, Blocks.STONEBRICK, 0, 3);
		this.setBlock(x + 2, y + 0, z + 0, Blocks.STONEBRICK, 0, 3);
		this.setBlock(x + 3, y + 0, z + 0, Blocks.STONEBRICK, 0, 3);
		this.setBlock(x + 4, y + 0, z + 0, Blocks.CONCRETE, 11, 3);
		this.setBlock(x + 5, y + 0, z + 0, Blocks.STONEBRICK, 0, 3);
		this.setBlock(x + 6, y + 0, z + 0, Blocks.STONEBRICK, 0, 3);
		this.setBlock(x + 7, y + 0, z + 0, Blocks.STONEBRICK, 0, 3);
		this.setBlock(x + 8, y + 0, z + 0, Blocks.STONEBRICK, 0, 3);
		this.setBlock(x + 9, y + 0, z + 0, Blocks.STONEBRICK, 0, 3);
		this.setBlock(x + 10, y + 0, z + 0, Blocks.STONEBRICK, 0, 3);
		this.setBlock(x + 11, y + 0, z + 0, Blocks.STONEBRICK, 0, 3);
		this.setBlock(x + 0, y + 0, z + 1, Blocks.STONEBRICK, 0, 3);
		this.setBlock(x + 1, y + 0, z + 1, Blocks.STONEBRICK, 0, 3);
		this.setBlock(x + 2, y + 0, z + 1, Blocks.STONEBRICK, 0, 3);
		this.setBlock(x + 3, y + 0, z + 1, Blocks.STONEBRICK, 0, 3);
		this.setBlock(x + 4, y + 0, z + 1, Blocks.STONEBRICK, 0, 3);
		this.setBlock(x + 5, y + 0, z + 1, Blocks.STONEBRICK, 0, 3);
		this.setBlock(x + 6, y + 0, z + 1, Blocks.STONEBRICK, 0, 3);
		this.setBlock(x + 7, y + 0, z + 1, Blocks.STONEBRICK, 0, 3);
		this.setBlock(x + 8, y + 0, z + 1, Blocks.STONEBRICK, 0, 3);
		this.setBlock(x + 9, y + 0, z + 1, Blocks.STONEBRICK, 0, 3);
		this.setBlock(x + 10, y + 0, z + 1, Blocks.STONEBRICK, 0, 3);
		this.setBlock(x + 11, y + 0, z + 1, Blocks.STONEBRICK, 0, 3);
		this.setBlock(x + 0, y + 0, z + 2, Blocks.STONEBRICK, 0, 3);
		this.setBlock(x + 1, y + 0, z + 2, Blocks.STONEBRICK, 0, 3);
		this.setBlock(x + 2, y + 0, z + 2, Blocks.STONEBRICK, 0, 3);
		this.setBlock(x + 3, y + 0, z + 2, Blocks.STONEBRICK, 0, 3);
		this.setBlock(x + 4, y + 0, z + 2, Blocks.STONEBRICK, 0, 3);
		this.setBlock(x + 5, y + 0, z + 2, Blocks.STONEBRICK, 0, 3);
		this.setBlock(x + 6, y + 0, z + 2, Blocks.STONEBRICK, 0, 3);
		this.setBlock(x + 7, y + 0, z + 2, Blocks.STONEBRICK, 0, 3);
		this.setBlock(x + 8, y + 0, z + 2, Blocks.STONEBRICK, 0, 3);
		this.setBlock(x + 9, y + 0, z + 2, Blocks.STONEBRICK, 0, 3);
		this.setBlock(x + 10, y + 0, z + 2, Blocks.STONEBRICK, 0, 3);
		this.setBlock(x + 11, y + 0, z + 2, Blocks.STONEBRICK, 0, 3);
		this.setBlock(x + 0, y + 0, z + 3, Blocks.STONEBRICK, 0, 3);
		this.setBlock(x + 1, y + 0, z + 3, Blocks.STONEBRICK, 0, 3);
		this.setBlock(x + 2, y + 0, z + 3, Blocks.STONEBRICK, 0, 3);
		this.setBlock(x + 3, y + 0, z + 3, Blocks.STONEBRICK, 0, 3);
		this.setBlock(x + 4, y + 0, z + 3, Blocks.STONEBRICK, 0, 3);
		this.setBlock(x + 5, y + 0, z + 3, Blocks.STONEBRICK, 0, 3);
		this.setBlock(x + 6, y + 0, z + 3, Blocks.STONEBRICK, 0, 3);
		this.setBlock(x + 7, y + 0, z + 3, Blocks.STONEBRICK, 0, 3);
		this.setBlock(x + 8, y + 0, z + 3, Blocks.STONEBRICK, 0, 3);
		this.setBlock(x + 9, y + 0, z + 3, Blocks.STONEBRICK, 0, 3);
		this.setBlock(x + 10, y + 0, z + 3, Blocks.STONEBRICK, 0, 3);
		this.setBlock(x + 11, y + 0, z + 3, Blocks.STONEBRICK, 0, 3);
		this.setBlock(x + 0, y + 0, z + 4, Blocks.STONEBRICK, 0, 3);
		this.setBlock(x + 1, y + 0, z + 4, Blocks.STONEBRICK, 0, 3);
		this.setBlock(x + 2, y + 0, z + 4, Blocks.STONEBRICK, 0, 3);
		this.setBlock(x + 3, y + 0, z + 4, Blocks.STONEBRICK, 0, 3);
		this.setBlock(x + 4, y + 0, z + 4, Blocks.STONEBRICK, 0, 3);
		this.setBlock(x + 5, y + 0, z + 4, Blocks.STONEBRICK, 0, 3);
		this.setBlock(x + 6, y + 0, z + 4, Blocks.STONEBRICK, 0, 3);
		this.setBlock(x + 7, y + 0, z + 4, Blocks.STONEBRICK, 0, 3);
		this.setBlock(x + 8, y + 0, z + 4, Blocks.STONEBRICK, 0, 3);
		this.setBlock(x + 9, y + 0, z + 4, Blocks.STONEBRICK, 0, 3);
		this.setBlock(x + 10, y + 0, z + 4, Blocks.STONEBRICK, 0, 3);
		this.setBlock(x + 11, y + 0, z + 4, Blocks.STONEBRICK, 0, 3);
		this.setBlock(x + 0, y + 0, z + 5, Blocks.STONEBRICK, 0, 3);
		this.setBlock(x + 1, y + 0, z + 5, Blocks.STONEBRICK, 0, 3);
		this.setBlock(x + 2, y + 0, z + 5, Blocks.STONEBRICK, 0, 3);
		this.setBlock(x + 3, y + 0, z + 5, Blocks.STONEBRICK, 0, 3);
		this.setBlock(x + 4, y + 0, z + 5, Blocks.STONEBRICK, 0, 3);
		this.setBlock(x + 5, y + 0, z + 5, Blocks.STONEBRICK, 0, 3);
		this.setBlock(x + 6, y + 0, z + 5, Blocks.STONEBRICK, 0, 3);
		this.setBlock(x + 7, y + 0, z + 5, Blocks.STONEBRICK, 0, 3);
		this.setBlock(x + 8, y + 0, z + 5, Blocks.STONEBRICK, 0, 3);
		this.setBlock(x + 9, y + 0, z + 5, Blocks.STONEBRICK, 0, 3);
		this.setBlock(x + 10, y + 0, z + 5, Blocks.STONEBRICK, 0, 3);
		this.setBlock(x + 11, y + 0, z + 5, Blocks.STONEBRICK, 0, 3);
		this.setBlock(x + 0, y + 0, z + 6, Blocks.STONEBRICK, 0, 3);
		this.setBlock(x + 1, y + 0, z + 6, Blocks.STONEBRICK, 0, 3);
		this.setBlock(x + 2, y + 0, z + 6, Blocks.STONEBRICK, 0, 3);
		this.setBlock(x + 3, y + 0, z + 6, Blocks.STONEBRICK, 0, 3);
		this.setBlock(x + 4, y + 0, z + 6, Blocks.STONEBRICK, 0, 3);
		this.setBlock(x + 5, y + 0, z + 6, Blocks.STONEBRICK, 0, 3);
		this.setBlock(x + 6, y + 0, z + 6, Blocks.STONEBRICK, 0, 3);
		this.setBlock(x + 7, y + 0, z + 6, Blocks.STONEBRICK, 0, 3);
		this.setBlock(x + 8, y + 0, z + 6, Blocks.STONEBRICK, 0, 3);
		this.setBlock(x + 9, y + 0, z + 6, Blocks.STONEBRICK, 0, 3);
		this.setBlock(x + 10, y + 0, z + 6, Blocks.STONEBRICK, 0, 3);
		this.setBlock(x + 11, y + 0, z + 6, Blocks.STONEBRICK, 0, 3);
		this.setBlock(x + 0, y + 0, z + 7, Blocks.STONEBRICK, 0, 3);
		this.setBlock(x + 1, y + 0, z + 7, Blocks.STONEBRICK, 0, 3);
		this.setBlock(x + 2, y + 0, z + 7, Blocks.STONEBRICK, 0, 3);
		this.setBlock(x + 3, y + 0, z + 7, Blocks.STONEBRICK, 0, 3);
		this.setBlock(x + 4, y + 0, z + 7, Blocks.STONEBRICK, 0, 3);
		this.setBlock(x + 5, y + 0, z + 7, Blocks.STONEBRICK, 0, 3);
		this.setBlock(x + 6, y + 0, z + 7, Blocks.STONEBRICK, 0, 3);
		this.setBlock(x + 7, y + 0, z + 7, Blocks.STONEBRICK, 0, 3);
		this.setBlock(x + 8, y + 0, z + 7, Blocks.STONEBRICK, 0, 3);
		this.setBlock(x + 9, y + 0, z + 7, Blocks.STONEBRICK, 0, 3);
		this.setBlock(x + 10, y + 0, z + 7, Blocks.STONEBRICK, 0, 3);
		this.setBlock(x + 11, y + 0, z + 7, Blocks.STONEBRICK, 0, 3);
		this.setBlock(x + 0, y + 0, z + 8, Blocks.STONEBRICK, 0, 3);
		this.setBlock(x + 1, y + 0, z + 8, Blocks.STONEBRICK, 0, 3);
		this.setBlock(x + 2, y + 0, z + 8, Blocks.STONEBRICK, 0, 3);
		this.setBlock(x + 3, y + 0, z + 8, Blocks.STONEBRICK, 0, 3);
		this.setBlock(x + 4, y + 0, z + 8, Blocks.STONEBRICK, 0, 3);
		this.setBlock(x + 5, y + 0, z + 8, Blocks.STONEBRICK, 0, 3);
		this.setBlock(x + 6, y + 0, z + 8, Blocks.STONEBRICK, 0, 3);
		this.setBlock(x + 7, y + 0, z + 8, Blocks.STONEBRICK, 0, 3);
		this.setBlock(x + 8, y + 0, z + 8, Blocks.STONEBRICK, 0, 3);
		this.setBlock(x + 9, y + 0, z + 8, Blocks.STONEBRICK, 0, 3);
		this.setBlock(x + 10, y + 0, z + 8, Blocks.STONEBRICK, 0, 3);
		this.setBlock(x + 11, y + 0, z + 8, Blocks.STONEBRICK, 0, 3);
		this.setBlock(x + 1, y + 0, z + 9, Blocks.STONEBRICK, 0, 3);
		this.setBlock(x + 2, y + 0, z + 9, Blocks.STONEBRICK, 0, 3);
		this.setBlock(x + 3, y + 0, z + 9, Blocks.STONEBRICK, 0, 3);
		this.setBlock(x + 4, y + 0, z + 9, Blocks.STONEBRICK, 0, 3);
		this.setBlock(x + 5, y + 0, z + 9, Blocks.STONEBRICK, 0, 3);
		this.setBlock(x + 6, y + 0, z + 9, Blocks.STONEBRICK, 0, 3);
		this.setBlock(x + 7, y + 0, z + 9, Blocks.STONEBRICK, 0, 3);
		this.setBlock(x + 8, y + 0, z + 9, Blocks.STONEBRICK, 0, 3);
		this.setBlock(x + 9, y + 0, z + 9, Blocks.STONEBRICK, 0, 3);
		this.setBlock(x + 10, y + 0, z + 9, Blocks.STONEBRICK, 0, 3);
		this.setBlock(x + 11, y + 0, z + 9, Blocks.STONEBRICK, 0, 3);
		this.setBlock(x + 1, y + 0, z + 10, Blocks.STONEBRICK, 0, 3);
		this.setBlock(x + 2, y + 0, z + 10, Blocks.STONEBRICK, 0, 3);
		this.setBlock(x + 3, y + 0, z + 10, Blocks.STONEBRICK, 0, 3);
		this.setBlock(x + 4, y + 0, z + 10, Blocks.STONEBRICK, 0, 3);
		this.setBlock(x + 5, y + 0, z + 10, Blocks.STONEBRICK, 0, 3);
		this.setBlock(x + 6, y + 0, z + 10, Blocks.STONEBRICK, 0, 3);
		this.setBlock(x + 7, y + 0, z + 10, Blocks.STONEBRICK, 0, 3);
		this.setBlock(x + 8, y + 0, z + 10, Blocks.STONEBRICK, 0, 3);
		this.setBlock(x + 9, y + 0, z + 10, Blocks.STONEBRICK, 0, 3);
		this.setBlock(x + 10, y + 0, z + 10, Blocks.STONEBRICK, 0, 3);
		this.setBlock(x + 11, y + 0, z + 10, Blocks.STONEBRICK, 0, 3);
		this.setBlock(x + 0, y + 0, z + 11, Blocks.STONEBRICK, 0, 3);
		this.setBlock(x + 1, y + 0, z + 11, Blocks.STONEBRICK, 0, 3);
		this.setBlock(x + 2, y + 0, z + 11, Blocks.STONEBRICK, 0, 3);
		this.setBlock(x + 3, y + 0, z + 11, Blocks.STONEBRICK, 0, 3);
		this.setBlock(x + 4, y + 0, z + 11, Blocks.STONEBRICK, 0, 3);
		this.setBlock(x + 5, y + 0, z + 11, Blocks.STONEBRICK, 0, 3);
		this.setBlock(x + 6, y + 0, z + 11, Blocks.STONEBRICK, 0, 3);
		this.setBlock(x + 7, y + 0, z + 11, Blocks.STONEBRICK, 0, 3);
		this.setBlock(x + 8, y + 0, z + 11, Blocks.STONEBRICK, 0, 3);
		this.setBlock(x + 9, y + 0, z + 11, Blocks.STONEBRICK, 0, 3);
		this.setBlock(x + 10, y + 0, z + 11, Blocks.STONEBRICK, 0, 3);
		this.setBlock(x + 11, y + 0, z + 11, Blocks.STONEBRICK, 0, 3);
		this.setBlock(x + 0, y + 0, z + 12, Blocks.STONEBRICK, 0, 3);
		this.setBlock(x + 1, y + 0, z + 12, Blocks.STONEBRICK, 0, 3);
		this.setBlock(x + 2, y + 0, z + 12, Blocks.STONEBRICK, 0, 3);
		this.setBlock(x + 3, y + 0, z + 12, Blocks.STONEBRICK, 0, 3);
		this.setBlock(x + 4, y + 0, z + 12, Blocks.STONEBRICK, 0, 3);
		this.setBlock(x + 5, y + 0, z + 12, Blocks.STONEBRICK, 0, 3);
		this.setBlock(x + 6, y + 0, z + 12, Blocks.STONEBRICK, 0, 3);
		this.setBlock(x + 7, y + 0, z + 12, Blocks.STONEBRICK, 0, 3);
		this.setBlock(x + 8, y + 0, z + 12, Blocks.STONEBRICK, 0, 3);
		this.setBlock(x + 9, y + 0, z + 12, Blocks.STONEBRICK, 0, 3);
		this.setBlock(x + 10, y + 0, z + 12, Blocks.STONEBRICK, 0, 3);
		this.setBlock(x + 11, y + 0, z + 12, Blocks.STONEBRICK, 0, 3);
		this.setBlock(x + 0, y + 0, z + 13, Blocks.STONEBRICK, 0, 3);
		this.setBlock(x + 1, y + 0, z + 13, Blocks.STONEBRICK, 0, 3);
		this.setBlock(x + 2, y + 0, z + 13, Blocks.STONEBRICK, 0, 3);
		this.setBlock(x + 3, y + 0, z + 13, Blocks.STONEBRICK, 0, 3);
		this.setBlock(x + 4, y + 0, z + 13, Blocks.STONEBRICK, 0, 3);
		this.setBlock(x + 5, y + 0, z + 13, Blocks.STONEBRICK, 0, 3);
		this.setBlock(x + 6, y + 0, z + 13, Blocks.STONEBRICK, 0, 3);
		this.setBlock(x + 7, y + 0, z + 13, Blocks.STONEBRICK, 0, 3);
		this.setBlock(x + 8, y + 0, z + 13, Blocks.STONEBRICK, 0, 3);
		this.setBlock(x + 9, y + 0, z + 13, Blocks.STONEBRICK, 0, 3);
		this.setBlock(x + 10, y + 0, z + 13, Blocks.STONEBRICK, 0, 3);
		this.setBlock(x + 11, y + 0, z + 13, Blocks.STONEBRICK, 0, 3);
		this.setBlock(x + 0, y + 0, z + 14, Blocks.STONEBRICK, 0, 3);
		this.setChest(x + 1, y + 0, z + 14, Blocks.CHEST, 5, 3, LootTableList.CHESTS_DESERT_PYRAMID, rand.nextLong());
		this.setBlock(x + 2, y + 0, z + 14, Blocks.STONEBRICK, 0, 3);
		this.setBlock(x + 3, y + 0, z + 14, Blocks.STONEBRICK, 0, 3);
		this.setBlock(x + 4, y + 0, z + 14, Blocks.STONEBRICK, 0, 3);
		this.setBlock(x + 5, y + 0, z + 14, Blocks.STONEBRICK, 0, 3);
		this.setBlock(x + 6, y + 0, z + 14, Blocks.STONEBRICK, 0, 3);
		this.setBlock(x + 7, y + 0, z + 14, Blocks.STONEBRICK, 0, 3);
		this.setBlock(x + 8, y + 0, z + 14, Blocks.STONEBRICK, 0, 3);
		this.setBlock(x + 9, y + 0, z + 14, Blocks.STONEBRICK, 0, 3);
		this.setChest(x + 10, y + 0, z + 14, Blocks.CHEST, 4, 3, LootTableList.CHESTS_DESERT_PYRAMID, rand.nextLong());
		this.setBlock(x + 11, y + 0, z + 14, Blocks.STONEBRICK, 0, 3);
		this.setBlock(x + 0, y + 0, z + 15, Blocks.STONEBRICK, 0, 3);
		this.setChest(x + 1, y + 0, z + 15, Blocks.CHEST, 5, 3, LootTableList.CHESTS_DESERT_PYRAMID, rand.nextLong());
		this.setBlock(x + 2, y + 0, z + 15, Blocks.STONEBRICK, 0, 3);
		this.setBlock(x + 3, y + 0, z + 15, Blocks.STONEBRICK, 0, 3);
		this.setBlock(x + 4, y + 0, z + 15, Blocks.STONEBRICK, 0, 3);
		this.setBlock(x + 5, y + 0, z + 15, Blocks.STONEBRICK, 0, 3);
		this.setBlock(x + 6, y + 0, z + 15, Blocks.STONEBRICK, 0, 3);
		this.setBlock(x + 7, y + 0, z + 15, Blocks.STONEBRICK, 0, 3);
		this.setBlock(x + 8, y + 0, z + 15, Blocks.STONEBRICK, 0, 3);
		this.setBlock(x + 9, y + 0, z + 15, Blocks.STONEBRICK, 0, 3);
		this.setChest(x + 10, y + 0, z + 15, Blocks.CHEST, 4, 3, LootTableList.CHESTS_DESERT_PYRAMID, rand.nextLong());
		this.setBlock(x + 11, y + 0, z + 15, Blocks.STONEBRICK, 0, 3);
		this.setBlock(x + 0, y + 0, z + 16, Blocks.STONEBRICK, 0, 3);
		this.setBlock(x + 1, y + 0, z + 16, Blocks.STONEBRICK, 0, 3);
		this.setBlock(x + 2, y + 0, z + 16, Blocks.STONEBRICK, 0, 3);
		this.setBlock(x + 3, y + 0, z + 16, Blocks.STONEBRICK, 0, 3);
		this.setBlock(x + 4, y + 0, z + 16, Blocks.STONEBRICK, 0, 3);
		this.setBlock(x + 5, y + 0, z + 16, Blocks.STONEBRICK, 0, 3);
		this.setBlock(x + 6, y + 0, z + 16, Blocks.STONEBRICK, 0, 3);
		this.setBlock(x + 7, y + 0, z + 16, Blocks.STONEBRICK, 0, 3);
		this.setBlock(x + 8, y + 0, z + 16, Blocks.STONEBRICK, 0, 3);
		this.setBlock(x + 9, y + 0, z + 16, Blocks.STONEBRICK, 0, 3);
		this.setBlock(x + 10, y + 0, z + 16, Blocks.STONEBRICK, 0, 3);
		this.setBlock(x + 11, y + 0, z + 16, Blocks.STONEBRICK, 0, 3);
		this.setBlock(x + 0, y + 0, z + 17, Blocks.STONEBRICK, 0, 3);
		this.setBlock(x + 1, y + 0, z + 17, Blocks.STONEBRICK, 0, 3);
		this.setBlock(x + 2, y + 0, z + 17, Blocks.STONEBRICK, 0, 3);
		this.setBlock(x + 3, y + 0, z + 17, Blocks.STONEBRICK, 0, 3);
		this.setBlock(x + 4, y + 0, z + 17, Blocks.STONEBRICK, 0, 3);
		this.setBlock(x + 5, y + 0, z + 17, Blocks.STONEBRICK, 0, 3);
		this.setBlock(x + 6, y + 0, z + 17, Blocks.STONEBRICK, 0, 3);
		this.setBlock(x + 7, y + 0, z + 17, Blocks.STONEBRICK, 0, 3);
		this.setBlock(x + 8, y + 0, z + 17, Blocks.STONEBRICK, 0, 3);
		this.setBlock(x + 9, y + 0, z + 17, Blocks.STONEBRICK, 0, 3);
		this.setBlock(x + 10, y + 0, z + 17, Blocks.STONEBRICK, 0, 3);
		this.setBlock(x + 11, y + 0, z + 17, Blocks.STONEBRICK, 0, 3);
		this.setBlock(x + 0, y + 0, z + 18, Blocks.STONEBRICK, 0, 3);
		this.setBlock(x + 1, y + 0, z + 18, Blocks.STONEBRICK, 0, 3);
		this.setBlock(x + 2, y + 0, z + 18, Blocks.STONEBRICK, 0, 3);
		this.setBlock(x + 3, y + 0, z + 18, Blocks.STONEBRICK, 0, 3);
		this.setBlock(x + 4, y + 0, z + 18, Blocks.STONEBRICK, 0, 3);
		this.setBlock(x + 5, y + 0, z + 18, Blocks.STONEBRICK, 0, 3);
		this.setBlock(x + 6, y + 0, z + 18, Blocks.STONEBRICK, 0, 3);
		this.setBlock(x + 7, y + 0, z + 18, Blocks.STONEBRICK, 0, 3);
		this.setBlock(x + 8, y + 0, z + 18, Blocks.STONEBRICK, 0, 3);
		this.setBlock(x + 9, y + 0, z + 18, Blocks.STONEBRICK, 0, 3);
		this.setBlock(x + 10, y + 0, z + 18, Blocks.STONEBRICK, 0, 3);
		this.setBlock(x + 11, y + 0, z + 18, Blocks.STONEBRICK, 0, 3);
		this.setBlock(x + 0, y + 0, z + 19, Blocks.STONEBRICK, 0, 3);
		this.setBlock(x + 1, y + 0, z + 19, Blocks.STONEBRICK, 0, 3);
		this.setBlock(x + 2, y + 0, z + 19, Blocks.STONEBRICK, 0, 3);
		this.setBlock(x + 3, y + 0, z + 19, Blocks.STONEBRICK, 0, 3);
		this.setBlock(x + 4, y + 0, z + 19, Blocks.STONEBRICK, 0, 3);
		this.setBlock(x + 5, y + 0, z + 19, Blocks.STONEBRICK, 0, 3);
		this.setBlock(x + 6, y + 0, z + 19, Blocks.STONEBRICK, 0, 3);
		this.setBlock(x + 7, y + 0, z + 19, Blocks.STONEBRICK, 0, 3);
		this.setBlock(x + 8, y + 0, z + 19, Blocks.STONEBRICK, 0, 3);
		this.setBlock(x + 9, y + 0, z + 19, Blocks.STONEBRICK, 0, 3);
		this.setBlock(x + 10, y + 0, z + 19, Blocks.STONEBRICK, 0, 3);
		this.setBlock(x + 11, y + 0, z + 19, Blocks.STONEBRICK, 0, 3);
		this.setBlock(x + 0, y + 0, z + 20, Blocks.STONEBRICK, 0, 3);
		this.setBlock(x + 1, y + 0, z + 20, Blocks.STONEBRICK, 0, 3);
		this.setBlock(x + 2, y + 0, z + 20, Blocks.STONEBRICK, 0, 3);
		this.setBlock(x + 3, y + 0, z + 20, Blocks.STONEBRICK, 0, 3);
		this.setBlock(x + 4, y + 0, z + 20, Blocks.STONEBRICK, 0, 3);
		this.setBlock(x + 5, y + 0, z + 20, Blocks.STONEBRICK, 0, 3);
		this.setBlock(x + 6, y + 0, z + 20, Blocks.STONEBRICK, 0, 3);
		this.setBlock(x + 7, y + 0, z + 20, Blocks.STONEBRICK, 0, 3);
		this.setBlock(x + 8, y + 0, z + 20, Blocks.STONEBRICK, 0, 3);
		this.setBlock(x + 9, y + 0, z + 20, Blocks.STONEBRICK, 0, 3);
		this.setBlock(x + 10, y + 0, z + 20, Blocks.STONEBRICK, 0, 3);
		this.setBlock(x + 11, y + 0, z + 20, Blocks.STONEBRICK, 0, 3);
		this.setBlock(x + 0, y + 0, z + 21, Blocks.STONEBRICK, 0, 3);
		this.setBlock(x + 1, y + 0, z + 21, Blocks.STONEBRICK, 0, 3);
		this.setBlock(x + 2, y + 0, z + 21, Blocks.STONEBRICK, 0, 3);
		this.setBlock(x + 3, y + 0, z + 21, Blocks.STONEBRICK, 0, 3);
		this.setBlock(x + 4, y + 0, z + 21, Blocks.STONEBRICK, 0, 3);
		this.setBlock(x + 5, y + 0, z + 21, Blocks.STONEBRICK, 0, 3);
		this.setBlock(x + 6, y + 0, z + 21, Blocks.STONEBRICK, 0, 3);
		this.setBlock(x + 7, y + 0, z + 21, Blocks.STONEBRICK, 0, 3);
		this.setBlock(x + 8, y + 0, z + 21, Blocks.STONEBRICK, 0, 3);
		this.setBlock(x + 9, y + 0, z + 21, Blocks.STONEBRICK, 0, 3);
		this.setBlock(x + 10, y + 0, z + 21, Blocks.STONEBRICK, 0, 3);
		this.setBlock(x + 11, y + 0, z + 21, Blocks.STONEBRICK, 0, 3);
		this.setBlock(x + 0, y + 0, z + 22, Blocks.STONEBRICK, 0, 3);
		this.setBlock(x + 1, y + 0, z + 22, Blocks.STONEBRICK, 0, 3);
		this.setBlock(x + 2, y + 0, z + 22, Blocks.STONEBRICK, 0, 3);
		this.setBlock(x + 3, y + 0, z + 22, Blocks.STONEBRICK, 0, 3);
		this.setBlock(x + 4, y + 0, z + 22, Blocks.STONEBRICK, 0, 3);
		this.setBlock(x + 5, y + 0, z + 22, Blocks.STONEBRICK, 0, 3);
		this.setBlock(x + 6, y + 0, z + 22, Blocks.STONEBRICK, 0, 3);
		this.setBlock(x + 7, y + 0, z + 22, Blocks.STONEBRICK, 0, 3);
		this.setBlock(x + 8, y + 0, z + 22, Blocks.STONEBRICK, 0, 3);
		this.setBlock(x + 9, y + 0, z + 22, Blocks.STONEBRICK, 0, 3);
		this.setBlock(x + 10, y + 0, z + 22, Blocks.STONEBRICK, 0, 3);
		this.setBlock(x + 11, y + 0, z + 22, Blocks.STONEBRICK, 0, 3);
		this.setBlock(x + 0, y + 0, z + 23, Blocks.STONEBRICK, 0, 3);
		this.setBlock(x + 1, y + 0, z + 23, Blocks.STONEBRICK, 0, 3);
		this.setBlock(x + 2, y + 0, z + 23, Blocks.STONEBRICK, 0, 3);
		this.setBlock(x + 3, y + 0, z + 23, Blocks.STONEBRICK, 0, 3);
		this.setBlock(x + 4, y + 0, z + 23, Blocks.STONEBRICK, 0, 3);
		this.setBlock(x + 5, y + 0, z + 23, Blocks.STONEBRICK, 0, 3);
		this.setBlock(x + 6, y + 0, z + 23, Blocks.STONEBRICK, 0, 3);
		this.setBlock(x + 7, y + 0, z + 23, Blocks.STONEBRICK, 0, 3);
		this.setBlock(x + 8, y + 0, z + 23, Blocks.STONEBRICK, 0, 3);
		this.setBlock(x + 9, y + 0, z + 23, Blocks.STONEBRICK, 0, 3);
		this.setBlock(x + 10, y + 0, z + 23, Blocks.STONEBRICK, 0, 3);
		this.setBlock(x + 11, y + 0, z + 23, Blocks.STONEBRICK, 0, 3);
		this.setBlock(x + 0, y + 0, z + 24, Blocks.STONEBRICK, 0, 3);
		this.setBlock(x + 1, y + 0, z + 24, Blocks.STONEBRICK, 0, 3);
		this.setBlock(x + 2, y + 0, z + 24, Blocks.STONEBRICK, 0, 3);
		this.setBlock(x + 3, y + 0, z + 24, Blocks.STONEBRICK, 0, 3);
		this.setBlock(x + 4, y + 0, z + 24, Blocks.STONEBRICK, 0, 3);
		this.setBlock(x + 5, y + 0, z + 24, Blocks.STONEBRICK, 0, 3);
		this.setBlock(x + 6, y + 0, z + 24, Blocks.STONEBRICK, 0, 3);
		this.setBlock(x + 7, y + 0, z + 24, Blocks.STONEBRICK, 0, 3);
		this.setBlock(x + 8, y + 0, z + 24, Blocks.STONEBRICK, 0, 3);
		this.setBlock(x + 9, y + 0, z + 24, Blocks.STONEBRICK, 0, 3);
		this.setBlock(x + 10, y + 0, z + 24, Blocks.STONEBRICK, 0, 3);
		this.setBlock(x + 11, y + 0, z + 24, Blocks.STONEBRICK, 0, 3);
		this.setBlock(x + 0, y + 0, z + 25, Blocks.STONEBRICK, 0, 3);
		this.setBlock(x + 1, y + 0, z + 25, Blocks.STONEBRICK, 0, 3);
		this.setBlock(x + 2, y + 0, z + 25, Blocks.STONEBRICK, 0, 3);
		this.setBlock(x + 3, y + 0, z + 25, Blocks.STONEBRICK, 0, 3);
		this.setBlock(x + 4, y + 0, z + 25, Blocks.STONEBRICK, 0, 3);
		this.setBlock(x + 5, y + 0, z + 25, Blocks.STONEBRICK, 0, 3);
		this.setBlock(x + 6, y + 0, z + 25, Blocks.STONEBRICK, 0, 3);
		this.setBlock(x + 7, y + 0, z + 25, Blocks.STONEBRICK, 0, 3);
		this.setBlock(x + 8, y + 0, z + 25, Blocks.STONEBRICK, 0, 3);
		this.setBlock(x + 9, y + 0, z + 25, Blocks.STONEBRICK, 0, 3);
		this.setBlock(x + 10, y + 0, z + 25, Blocks.STONEBRICK, 0, 3);
		this.setBlock(x + 11, y + 0, z + 25, Blocks.STONEBRICK, 0, 3);
		this.setBlock(x + 0, y + 0, z + 26, Blocks.STONEBRICK, 0, 3);
		this.setBlock(x + 1, y + 0, z + 26, Blocks.STONEBRICK, 0, 3);
		this.setBlock(x + 2, y + 0, z + 26, Blocks.STONEBRICK, 0, 3);
		this.setBlock(x + 3, y + 0, z + 26, Blocks.STONEBRICK, 0, 3);
		this.setBlock(x + 4, y + 0, z + 26, Blocks.STONEBRICK, 0, 3);
		this.setBlock(x + 5, y + 0, z + 26, Blocks.STONEBRICK, 0, 3);
		this.setBlock(x + 6, y + 0, z + 26, Blocks.STONEBRICK, 0, 3);
		this.setBlock(x + 7, y + 0, z + 26, Blocks.STONEBRICK, 0, 3);
		this.setBlock(x + 8, y + 0, z + 26, Blocks.STONEBRICK, 0, 3);
		this.setBlock(x + 9, y + 0, z + 26, Blocks.STONEBRICK, 0, 3);
		this.setBlock(x + 10, y + 0, z + 26, Blocks.STONEBRICK, 0, 3);
		this.setBlock(x + 11, y + 0, z + 26, Blocks.STONEBRICK, 0, 3);
		this.setBlock(x + 0, y + 0, z + 27, Blocks.STONEBRICK, 0, 3);
		this.setBlock(x + 1, y + 0, z + 27, Blocks.STONEBRICK, 0, 3);
		this.setBlock(x + 3, y + 0, z + 27, Blocks.STONEBRICK, 0, 3);
		this.setBlock(x + 4, y + 0, z + 27, Blocks.STONEBRICK, 0, 3);
		this.setBlock(x + 5, y + 0, z + 27, Blocks.STONEBRICK, 0, 3);
		this.setBlock(x + 6, y + 0, z + 27, Blocks.STONEBRICK, 0, 3);
		this.setBlock(x + 7, y + 0, z + 27, Blocks.STONEBRICK, 0, 3);
		this.setBlock(x + 8, y + 0, z + 27, Blocks.STONEBRICK, 0, 3);
		this.setBlock(x + 10, y + 0, z + 27, Blocks.STONEBRICK, 0, 3);
		this.setBlock(x + 11, y + 0, z + 27, Blocks.STONEBRICK, 0, 3);
		this.setBlock(x + 0, y + 0, z + 28, Blocks.STONEBRICK, 0, 3);
		this.setBlock(x + 1, y + 0, z + 28, Blocks.STONEBRICK, 0, 3);
		this.setBlock(x + 2, y + 0, z + 28, Blocks.STONEBRICK, 0, 3);
		this.setBlock(x + 3, y + 0, z + 28, Blocks.STONEBRICK, 0, 3);
		this.setBlock(x + 4, y + 0, z + 28, Blocks.STONEBRICK, 0, 3);
		this.setBlock(x + 5, y + 0, z + 28, Blocks.STONEBRICK, 0, 3);
		this.setBlock(x + 6, y + 0, z + 28, Blocks.STONEBRICK, 0, 3);
		this.setBlock(x + 7, y + 0, z + 28, Blocks.STONEBRICK, 0, 3);
		this.setBlock(x + 8, y + 0, z + 28, Blocks.STONEBRICK, 0, 3);
		this.setBlock(x + 9, y + 0, z + 28, Blocks.STONEBRICK, 0, 3);
		this.setBlock(x + 10, y + 0, z + 28, Blocks.STONEBRICK, 0, 3);
		this.setBlock(x + 11, y + 0, z + 28, Blocks.STONEBRICK, 0, 3);
		this.setBlock(x + 0, y + 0, z + 29, Blocks.STONEBRICK, 0, 3);
		this.setBlock(x + 1, y + 0, z + 29, Blocks.STONEBRICK, 0, 3);
		this.setBlock(x + 2, y + 0, z + 29, Blocks.STONEBRICK, 0, 3);
		this.setBlock(x + 3, y + 0, z + 29, Blocks.STONEBRICK, 0, 3);
		this.setBlock(x + 4, y + 0, z + 29, Blocks.STONEBRICK, 0, 3);
		this.setBlock(x + 5, y + 0, z + 29, Blocks.STONEBRICK, 0, 3);
		this.setBlock(x + 6, y + 0, z + 29, Blocks.STONEBRICK, 0, 3);
		this.setBlock(x + 7, y + 0, z + 29, Blocks.STONEBRICK, 0, 3);
		this.setBlock(x + 8, y + 0, z + 29, Blocks.STONEBRICK, 0, 3);
		this.setBlock(x + 9, y + 0, z + 29, Blocks.STONEBRICK, 0, 3);
		this.setBlock(x + 10, y + 0, z + 29, Blocks.STONEBRICK, 0, 3);
		this.setBlock(x + 11, y + 0, z + 29, Blocks.STONEBRICK, 0, 3);
		this.setBlock(x + 2, y + 1, z + 0, Blocks.STONEBRICK, 0, 3);
		this.setBlock(x + 3, y + 1, z + 0, Blocks.STONEBRICK, 0, 3);
		this.setBlock(x + 4, y + 1, z + 0, Blocks.STONEBRICK, 0, 3);
		this.setBlock(x + 5, y + 1, z + 0, Blocks.STONEBRICK, 0, 3);
		this.setBlock(x + 6, y + 1, z + 0, Blocks.STONEBRICK, 0, 3);
		this.setBlock(x + 7, y + 1, z + 0, Blocks.STONEBRICK, 0, 3);
		this.setBlock(x + 8, y + 1, z + 0, Blocks.STONEBRICK, 0, 3);
		this.setBlock(x + 9, y + 1, z + 0, Blocks.STONEBRICK, 0, 3);
		this.setBlock(x + 1, y + 1, z + 1, Blocks.STONEBRICK, 0, 3);
		this.setBlock(x + 3, y + 1, z + 1, Blocks.STONE_BRICK_STAIRS, 0, 3);
		this.setBlock(x + 4, y + 1, z + 1, Blocks.STONEBRICK, 0, 3);
		this.setChest(x + 5, y + 1, z + 1, Blocks.CHEST, 3, 3, LootTableList.CHESTS_JUNGLE_TEMPLE, rand.nextLong());
		this.setChest(x + 6, y + 1, z + 1, Blocks.CHEST, 3, 3, LootTableList.CHESTS_JUNGLE_TEMPLE, rand.nextLong());
		this.setBlock(x + 7, y + 1, z + 1, Blocks.STONEBRICK, 0, 3);
		this.setBlock(x + 8, y + 1, z + 1, Blocks.STONE_BRICK_STAIRS, 1, 3);
		this.setBlock(x + 10, y + 1, z + 1, Blocks.STONEBRICK, 0, 3);
		this.setBlock(x + 0, y + 1, z + 2, Blocks.STONEBRICK, 0, 3);
		this.setBlock(x + 3, y + 1, z + 2, Blocks.STONE_BRICK_STAIRS, 0, 3);
		this.setBlock(x + 4, y + 1, z + 2, Blocks.STONEBRICK, 0, 3);
		this.setBlock(x + 5, y + 1, z + 2, Blocks.STONEBRICK, 0, 3);
		this.setBlock(x + 6, y + 1, z + 2, Blocks.STONEBRICK, 0, 3);
		this.setBlock(x + 7, y + 1, z + 2, Blocks.STONEBRICK, 0, 3);
		this.setBlock(x + 8, y + 1, z + 2, Blocks.STONE_BRICK_STAIRS, 1, 3);
		this.setBlock(x + 11, y + 1, z + 2, Blocks.STONEBRICK, 0, 3);
		this.setBlock(x + 0, y + 1, z + 3, Blocks.STONEBRICK, 0, 3);
		this.setBlock(x + 3, y + 1, z + 3, Blocks.STONE_BRICK_STAIRS, 3, 3);
		this.setBlock(x + 4, y + 1, z + 3, Blocks.STONE_BRICK_STAIRS, 3, 3);
		this.setBlock(x + 5, y + 1, z + 3, Blocks.STONEBRICK, 0, 3);
		this.setBlock(x + 6, y + 1, z + 3, Blocks.STONEBRICK, 0, 3);
		this.setBlock(x + 7, y + 1, z + 3, Blocks.STONE_BRICK_STAIRS, 3, 3);
		this.setBlock(x + 8, y + 1, z + 3, Blocks.STONE_BRICK_STAIRS, 3, 3);
		this.setBlock(x + 11, y + 1, z + 3, Blocks.STONEBRICK, 0, 3);
		this.setBlock(x + 0, y + 1, z + 4, Blocks.STONEBRICK, 0, 3);
		this.setBlock(x + 5, y + 3, z + 2, Blocks.SKULL, 0, 3);
		this.setBlock(x + 11, y + 1, z + 4, Blocks.STONEBRICK, 0, 3);
		this.setBlock(x + 0, y + 1, z + 5, Blocks.STONEBRICK, 0, 3);
		this.setBlock(x + 11, y + 1, z + 5, Blocks.STONEBRICK, 0, 3);
		this.setBlock(x + 0, y + 1, z + 6, Blocks.STONEBRICK, 0, 3);
		this.setChest(x + 1, y + 1, z + 6, Blocks.CHEST, 5, 3, LootTableList.CHESTS_STRONGHOLD_LIBRARY, rand.nextLong());
		this.setChest(x + 10, y + 1, z + 6, Blocks.CHEST, 4, 3, LootTableList.CHESTS_STRONGHOLD_LIBRARY, rand.nextLong());
		this.setBlock(x + 11, y + 1, z + 6, Blocks.STONEBRICK, 0, 3);
		this.setBlock(x + 0, y + 1, z + 7, Blocks.STONEBRICK, 0, 3);
		this.setChest(x + 1, y + 1, z + 7, Blocks.CHEST, 5, 3, LootTableList.CHESTS_STRONGHOLD_LIBRARY, rand.nextLong());
		this.setBlock(x + 3, y + 1, z + 7, Blocks.STONE_BRICK_STAIRS, 2, 3);
		this.setBlock(x + 4, y + 1, z + 7, Blocks.STONE_BRICK_STAIRS, 2, 3);
		this.setBlock(x + 7, y + 1, z + 7, Blocks.STONE_BRICK_STAIRS, 2, 3);
		this.setBlock(x + 8, y + 1, z + 7, Blocks.STONE_BRICK_STAIRS, 2, 3);
		this.setChest(x + 10, y + 1, z + 7, Blocks.CHEST, 4, 3, LootTableList.CHESTS_STRONGHOLD_LIBRARY, rand.nextLong());
		this.setBlock(x + 11, y + 1, z + 7, Blocks.STONEBRICK, 0, 3);
		this.setBlock(x + 0, y + 1, z + 8, Blocks.STONEBRICK, 0, 3);
		this.setBlock(x + 11, y + 1, z + 8, Blocks.STONEBRICK, 0, 3);
		this.setBlock(x + 0, y + 1, z + 9, Blocks.STONEBRICK, 0, 3);
		this.setBlock(x + 11, y + 1, z + 9, Blocks.STONEBRICK, 0, 3);
		this.setBlock(x + 0, y + 1, z + 10, Blocks.STONEBRICK, 0, 3);
		this.setBlock(x + 3, y + 1, z + 10, Blocks.STONE_BRICK_STAIRS, 2, 3);
		this.setBlock(x + 4, y + 1, z + 10, Blocks.STONE_BRICK_STAIRS, 2, 3);
		this.setBlock(x + 7, y + 1, z + 10, Blocks.STONE_BRICK_STAIRS, 2, 3);
		this.setBlock(x + 8, y + 1, z + 10, Blocks.STONE_BRICK_STAIRS, 2, 3);
		this.setBlock(x + 11, y + 1, z + 10, Blocks.STONEBRICK, 0, 3);
		this.setBlock(x + 0, y + 1, z + 11, Blocks.STONEBRICK, 0, 3);
		this.setBlock(x + 11, y + 1, z + 11, Blocks.STONEBRICK, 0, 3);
		this.setBlock(x + 0, y + 1, z + 12, Blocks.STONEBRICK, 0, 3);
		this.setBlock(x + 11, y + 1, z + 12, Blocks.STONEBRICK, 0, 3);
		this.setBlock(x + 0, y + 1, z + 13, Blocks.STONEBRICK, 0, 3);
		this.setBlock(x + 3, y + 1, z + 13, Blocks.STONE_BRICK_STAIRS, 2, 3);
		this.setBlock(x + 4, y + 1, z + 13, Blocks.STONE_BRICK_STAIRS, 2, 3);
		this.setBlock(x + 7, y + 1, z + 13, Blocks.STONE_BRICK_STAIRS, 2, 3);
		this.setBlock(x + 8, y + 1, z + 13, Blocks.STONE_BRICK_STAIRS, 2, 3);
		this.setBlock(x + 11, y + 1, z + 13, Blocks.STONEBRICK, 0, 3);
		this.setBlock(x + 0, y + 1, z + 14, Blocks.STONEBRICK, 0, 3);
		this.setBlock(x + 1, y + 1, z + 14, Blocks.BONE_BLOCK, 8, 3);
		this.setBlock(x + 10, y + 1, z + 14, Blocks.BONE_BLOCK, 8, 3);
		this.setBlock(x + 11, y + 1, z + 14, Blocks.STONEBRICK, 0, 3);
		this.setBlock(x + 0, y + 1, z + 15, Blocks.STONEBRICK, 0, 3);
		this.setBlock(x + 1, y + 1, z + 15, Blocks.BONE_BLOCK, 8, 3);
		this.setBlock(x + 10, y + 1, z + 15, Blocks.BONE_BLOCK, 8, 3);
		this.setBlock(x + 11, y + 1, z + 15, Blocks.STONEBRICK, 0, 3);
		this.setBlock(x + 0, y + 1, z + 16, Blocks.COBBLESTONE_WALL, 0, 3);
		this.setBlock(x + 1, y + 1, z + 16, Blocks.STONEBRICK, 0, 3);
		this.setBlock(x + 10, y + 1, z + 16, Blocks.STONEBRICK, 0, 3);
		this.setBlock(x + 11, y + 1, z + 16, Blocks.COBBLESTONE_WALL, 0, 3);
		this.setBlock(x + 0, y + 1, z + 17, Blocks.COBBLESTONE_WALL, 0, 3);
		this.setBlock(x + 2, y + 1, z + 17, Blocks.STONEBRICK, 0, 3);
		this.setBlock(x + 3, y + 1, z + 17, Blocks.STONEBRICK, 0, 3);
		this.setBlock(x + 4, y + 1, z + 17, Blocks.STONEBRICK, 0, 3);
		this.setBlock(x + 7, y + 1, z + 17, Blocks.STONEBRICK, 0, 3);
		this.setBlock(x + 8, y + 1, z + 17, Blocks.STONEBRICK, 0, 3);
		this.setBlock(x + 9, y + 1, z + 17, Blocks.STONEBRICK, 0, 3);
		this.setBlock(x + 11, y + 1, z + 17, Blocks.COBBLESTONE_WALL, 0, 3);
		this.setBlock(x + 0, y + 1, z + 18, Blocks.COBBLESTONE_WALL, 0, 3);
		this.setBlock(x + 11, y + 1, z + 18, Blocks.COBBLESTONE_WALL, 0, 3);
		this.setBlock(x + 0, y + 1, z + 19, Blocks.COBBLESTONE_WALL, 0, 3);
		this.setBlock(x + 11, y + 1, z + 19, Blocks.COBBLESTONE_WALL, 0, 3);
		this.setBlock(x + 0, y + 1, z + 20, Blocks.COBBLESTONE_WALL, 0, 3);
		this.setBlock(x + 11, y + 1, z + 20, Blocks.COBBLESTONE_WALL, 0, 3);
		this.setBlock(x + 0, y + 1, z + 21, Blocks.COBBLESTONE_WALL, 0, 3);
		this.setBlock(x + 11, y + 1, z + 21, Blocks.COBBLESTONE_WALL, 0, 3);
		this.setBlock(x + 0, y + 1, z + 22, Blocks.COBBLESTONE_WALL, 0, 3);
		this.setBlock(x + 3, y + 1, z + 22, Blocks.STONEBRICK, 0, 3);
		this.setBlock(x + 8, y + 1, z + 22, Blocks.STONEBRICK, 0, 3);
		this.setBlock(x + 11, y + 1, z + 22, Blocks.COBBLESTONE_WALL, 0, 3);
		this.setBlock(x + 0, y + 1, z + 23, Blocks.COBBLESTONE_WALL, 0, 3);
		this.setBlock(x + 11, y + 1, z + 23, Blocks.COBBLESTONE_WALL, 0, 3);
		this.setBlock(x + 0, y + 1, z + 24, Blocks.COBBLESTONE_WALL, 0, 3);
		this.setBlock(x + 11, y + 1, z + 24, Blocks.COBBLESTONE_WALL, 0, 3);
		this.setBlock(x + 0, y + 1, z + 25, Blocks.COBBLESTONE_WALL, 0, 3);
		this.setBlock(x + 11, y + 1, z + 25, Blocks.COBBLESTONE_WALL, 0, 3);
		this.setBlock(x + 0, y + 1, z + 26, Blocks.COBBLESTONE_WALL, 0, 3);
		this.setBlock(x + 11, y + 1, z + 26, Blocks.COBBLESTONE_WALL, 0, 3);
		this.setBlock(x + 0, y + 1, z + 27, Blocks.COBBLESTONE_WALL, 0, 3);
		this.setBlock(x + 2, y + 1, z + 27, Blocks.LOG, 0, 3);
		this.setBlock(x + 9, y + 1, z + 27, Blocks.LOG, 0, 3);
		this.setBlock(x + 11, y + 1, z + 27, Blocks.COBBLESTONE_WALL, 0, 3);
		this.setBlock(x + 0, y + 1, z + 28, Blocks.COBBLESTONE_WALL, 0, 3);
		this.setBlock(x + 11, y + 1, z + 28, Blocks.COBBLESTONE_WALL, 0, 3);
		this.setBlock(x + 0, y + 1, z + 29, Blocks.COBBLESTONE_WALL, 0, 3);
		this.setBlock(x + 1, y + 1, z + 29, Blocks.COBBLESTONE_WALL, 0, 3);
		this.setBlock(x + 2, y + 1, z + 29, Blocks.COBBLESTONE_WALL, 0, 3);
		this.setBlock(x + 3, y + 1, z + 29, Blocks.COBBLESTONE_WALL, 0, 3);
		this.setBlock(x + 4, y + 1, z + 29, Blocks.COBBLESTONE_WALL, 0, 3);
		this.setBlock(x + 7, y + 1, z + 29, Blocks.COBBLESTONE_WALL, 0, 3);
		this.setBlock(x + 8, y + 1, z + 29, Blocks.COBBLESTONE_WALL, 0, 3);
		this.setBlock(x + 9, y + 1, z + 29, Blocks.COBBLESTONE_WALL, 0, 3);
		this.setBlock(x + 10, y + 1, z + 29, Blocks.COBBLESTONE_WALL, 0, 3);
		this.setBlock(x + 11, y + 1, z + 29, Blocks.COBBLESTONE_WALL, 0, 3);
		this.setBlock(x + 2, y + 2, z + 0, Blocks.STONEBRICK, 0, 3);
		this.setBlock(x + 3, y + 2, z + 0, Blocks.STONEBRICK, 0, 3);
		this.setBlock(x + 4, y + 2, z + 0, Blocks.STONEBRICK, 0, 3);
		this.setBlock(x + 5, y + 2, z + 0, Blocks.STONEBRICK, 0, 3);
		this.setBlock(x + 6, y + 2, z + 0, Blocks.STONEBRICK, 0, 3);
		this.setBlock(x + 7, y + 2, z + 0, Blocks.STONEBRICK, 0, 3);
		this.setBlock(x + 8, y + 2, z + 0, Blocks.STONEBRICK, 0, 3);
		this.setBlock(x + 9, y + 2, z + 0, Blocks.STONEBRICK, 0, 3);
		this.setBlock(x + 1, y + 2, z + 1, Blocks.STONEBRICK, 0, 3);
		this.setBlock(x + 4, y + 2, z + 1, Blocks.STONE_BRICK_STAIRS, 0, 3);
		this.setBlock(x + 5, y + 2, z + 1, Blocks.STONEBRICK, 0, 3);
		this.setBlock(x + 6, y + 2, z + 1, Blocks.STONEBRICK, 0, 3);
		this.setBlock(x + 7, y + 2, z + 1, Blocks.STONE_BRICK_STAIRS, 1, 3);
		this.setBlock(x + 10, y + 2, z + 1, Blocks.STONEBRICK, 0, 3);
		this.setBlock(x + 0, y + 2, z + 2, Blocks.STONEBRICK, 0, 3);
		this.setBlock(x + 4, y + 2, z + 2, Blocks.STONE_BRICK_STAIRS, 0, 3);
		this.setBlock(x + 5, y + 2, z + 2, Blocks.STONEBRICK, 0, 3);
		this.setBlock(x + 6, y + 2, z + 2, Blocks.STONEBRICK, 0, 3);
		this.setBlock(x + 7, y + 2, z + 2, Blocks.STONE_BRICK_STAIRS, 1, 3);
		this.setBlock(x + 11, y + 2, z + 2, Blocks.STONEBRICK, 0, 3);
		this.setBlock(x + 0, y + 2, z + 3, Blocks.STONEBRICK, 0, 3);
		this.setBlock(x + 5, y + 2, z + 3, Blocks.STONEBRICK, 0, 3);
		this.setBlock(x + 6, y + 2, z + 3, Blocks.STONEBRICK, 0, 3);
		this.setBlock(x + 11, y + 2, z + 3, Blocks.STONEBRICK, 0, 3);
		this.setBlock(x + 0, y + 2, z + 4, Blocks.STONEBRICK, 0, 3);
		this.setBlock(x + 11, y + 2, z + 4, Blocks.STONEBRICK, 0, 3);
		this.setBlock(x + 0, y + 2, z + 5, Blocks.STONEBRICK, 0, 3);
		this.setBlock(x + 11, y + 2, z + 5, Blocks.STONEBRICK, 0, 3);
		this.setBlock(x + 0, y + 2, z + 6, Blocks.STONEBRICK, 0, 3);
		this.setBlock(x + 11, y + 2, z + 6, Blocks.STONEBRICK, 0, 3);
		this.setBlock(x + 0, y + 2, z + 7, Blocks.STONEBRICK, 0, 3);
		this.setBlock(x + 11, y + 2, z + 7, Blocks.STONEBRICK, 0, 3);
		this.setBlock(x + 0, y + 2, z + 8, Blocks.STONEBRICK, 0, 3);
		this.setBlock(x + 11, y + 2, z + 8, Blocks.STONEBRICK, 0, 3);
		this.setBlock(x + 0, y + 2, z + 9, Blocks.STONEBRICK, 0, 3);
		this.setBlock(x + 11, y + 2, z + 9, Blocks.STONEBRICK, 0, 3);
		this.setBlock(x + 0, y + 2, z + 10, Blocks.STONEBRICK, 0, 3);
		this.setBlock(x + 11, y + 2, z + 10, Blocks.STONEBRICK, 0, 3);
		this.setBlock(x + 0, y + 2, z + 11, Blocks.STONEBRICK, 0, 3);
		this.setBlock(x + 11, y + 2, z + 11, Blocks.STONEBRICK, 0, 3);
		this.setBlock(x + 0, y + 2, z + 12, Blocks.STONEBRICK, 0, 3);
		this.setBlock(x + 11, y + 2, z + 12, Blocks.STONEBRICK, 0, 3);
		this.setBlock(x + 0, y + 2, z + 13, Blocks.STONEBRICK, 0, 3);
		this.setBlock(x + 11, y + 2, z + 13, Blocks.STONEBRICK, 0, 3);
		this.setBlock(x + 0, y + 2, z + 14, Blocks.STONEBRICK, 0, 3);
		this.setBlock(x + 11, y + 2, z + 14, Blocks.STONEBRICK, 0, 3);
		this.setBlock(x + 0, y + 2, z + 15, Blocks.STONEBRICK, 0, 3);
		this.setBlock(x + 11, y + 2, z + 15, Blocks.STONEBRICK, 0, 3);
		this.setBlock(x + 1, y + 2, z + 16, Blocks.STONEBRICK, 0, 3);
		this.setBlock(x + 10, y + 2, z + 16, Blocks.STONEBRICK, 0, 3);
		this.setBlock(x + 2, y + 2, z + 17, Blocks.STONEBRICK, 0, 3);
		this.setBlock(x + 3, y + 2, z + 17, Blocks.STONEBRICK, 0, 3);
		this.setBlock(x + 4, y + 2, z + 17, Blocks.STONEBRICK, 0, 3);
		this.setBlock(x + 7, y + 2, z + 17, Blocks.STONEBRICK, 0, 3);
		this.setBlock(x + 8, y + 2, z + 17, Blocks.STONEBRICK, 0, 3);
		this.setBlock(x + 9, y + 2, z + 17, Blocks.STONEBRICK, 0, 3);
		this.setBlock(x + 3, y + 2, z + 22, Blocks.STONEBRICK, 0, 3);
		this.setBlock(x + 8, y + 2, z + 22, Blocks.STONEBRICK, 0, 3);
		this.setBlock(x + 2, y + 2, z + 27, Blocks.LOG, 0, 3);
		this.setBlock(x + 9, y + 2, z + 27, Blocks.LOG, 0, 3);
		this.setBlock(x + 2, y + 3, z + 0, Blocks.STONEBRICK, 0, 3);
		this.setBlock(x + 3, y + 3, z + 0, Blocks.STONEBRICK, 0, 3);
		this.setBlock(x + 4, y + 3, z + 0, Blocks.STONEBRICK, 0, 3);
		this.setBlock(x + 5, y + 3, z + 0, Blocks.STONEBRICK, 0, 3);
		this.setBlock(x + 6, y + 3, z + 0, Blocks.STONEBRICK, 0, 3);
		this.setBlock(x + 7, y + 3, z + 0, Blocks.STONEBRICK, 0, 3);
		this.setBlock(x + 8, y + 3, z + 0, Blocks.STONEBRICK, 0, 3);
		this.setBlock(x + 9, y + 3, z + 0, Blocks.STONEBRICK, 0, 3);
		this.setBlock(x + 1, y + 3, z + 1, Blocks.STONEBRICK, 0, 3);
		this.setBlock(x + 10, y + 3, z + 1, Blocks.STONEBRICK, 0, 3);
		this.setBlock(x + 0, y + 3, z + 2, Blocks.STONEBRICK, 0, 3);
		this.setBlock(x + 11, y + 3, z + 2, Blocks.STONEBRICK, 0, 3);
		this.setBlock(x + 0, y + 3, z + 3, Blocks.STAINED_GLASS, 14, 3);
		this.setBlock(x + 5, y + 3, z + 3, Blocks.STONEBRICK, 0, 3);
		this.setBlock(x + 6, y + 3, z + 3, Blocks.STONEBRICK, 0, 3);
		this.setBlock(x + 11, y + 3, z + 3, Blocks.STAINED_GLASS, 13, 3);
		this.setBlock(x + 0, y + 3, z + 4, Blocks.STAINED_GLASS, 14, 3);
		this.setBlock(x + 11, y + 3, z + 4, Blocks.STAINED_GLASS, 0, 3);
		this.setBlock(x + 0, y + 3, z + 5, Blocks.STAINED_GLASS, 0, 3);
		this.setBlock(x + 11, y + 3, z + 5, Blocks.STAINED_GLASS, 0, 3);
		this.setBlock(x + 0, y + 3, z + 6, Blocks.STAINED_GLASS, 5, 3);
		this.setBlock(x + 11, y + 3, z + 6, Blocks.STAINED_GLASS, 0, 3);
		this.setBlock(x + 0, y + 3, z + 7, Blocks.STAINED_GLASS, 5, 3);
		this.setBlock(x + 11, y + 3, z + 7, Blocks.STAINED_GLASS, 14, 3);
		this.setBlock(x + 0, y + 3, z + 8, Blocks.STONEBRICK, 0, 3);
		this.setBlock(x + 11, y + 3, z + 8, Blocks.STONEBRICK, 0, 3);
		this.setBlock(x + 0, y + 3, z + 9, Blocks.STONEBRICK, 0, 3);
		this.setBlock(x + 11, y + 3, z + 9, Blocks.STONEBRICK, 0, 3);
		this.setBlock(x + 0, y + 3, z + 10, Blocks.STAINED_GLASS, 14, 3);
		this.setBlock(x + 11, y + 3, z + 10, Blocks.STAINED_GLASS, 14, 3);
		this.setBlock(x + 0, y + 3, z + 11, Blocks.STAINED_GLASS, 14, 3);
		this.setBlock(x + 11, y + 3, z + 11, Blocks.STAINED_GLASS, 0, 3);
		this.setBlock(x + 0, y + 3, z + 12, Blocks.STAINED_GLASS, 14, 3);
		this.setBlock(x + 11, y + 3, z + 12, Blocks.STAINED_GLASS, 0, 3);
		this.setBlock(x + 0, y + 3, z + 13, Blocks.STAINED_GLASS, 14, 3);
		this.setBlock(x + 11, y + 3, z + 13, Blocks.STAINED_GLASS, 0, 3);
		this.setBlock(x + 0, y + 3, z + 14, Blocks.STAINED_GLASS, 14, 3);
		this.setBlock(x + 11, y + 3, z + 14, Blocks.STAINED_GLASS, 14, 3);
		this.setBlock(x + 0, y + 3, z + 15, Blocks.STONEBRICK, 0, 3);
		this.setBlock(x + 11, y + 3, z + 15, Blocks.STONEBRICK, 0, 3);
		this.setBlock(x + 1, y + 3, z + 16, Blocks.STONEBRICK, 0, 3);
		this.setBlock(x + 10, y + 3, z + 16, Blocks.STONEBRICK, 0, 3);
		this.setBlock(x + 2, y + 3, z + 17, Blocks.STONEBRICK, 0, 3);
		this.setBlock(x + 3, y + 3, z + 17, Blocks.STONEBRICK, 0, 3);
		this.setBlock(x + 4, y + 3, z + 17, Blocks.STONEBRICK, 0, 3);
		this.setBlock(x + 7, y + 3, z + 17, Blocks.STONEBRICK, 0, 3);
		this.setBlock(x + 8, y + 3, z + 17, Blocks.STONEBRICK, 0, 3);
		this.setBlock(x + 9, y + 3, z + 17, Blocks.STONEBRICK, 0, 3);
		this.setBlock(x + 3, y + 3, z + 22, Blocks.STONEBRICK, 0, 3);
		this.setBlock(x + 8, y + 3, z + 22, Blocks.STONEBRICK, 0, 3);
		this.setBlock(x + 1, y + 3, z + 25, Blocks.LEAVES, 0, 3);
		this.setBlock(x + 2, y + 3, z + 25, Blocks.LEAVES, 0, 3);
		this.setBlock(x + 3, y + 3, z + 25, Blocks.LEAVES, 0, 3);
		this.setBlock(x + 8, y + 3, z + 25, Blocks.LEAVES, 0, 3);
		this.setBlock(x + 9, y + 3, z + 25, Blocks.LEAVES, 0, 3);
		this.setBlock(x + 10, y + 3, z + 25, Blocks.LEAVES, 0, 3);
		this.setBlock(x + 0, y + 3, z + 26, Blocks.LEAVES, 0, 3);
		this.setBlock(x + 1, y + 3, z + 26, Blocks.LEAVES, 0, 3);
		this.setBlock(x + 2, y + 3, z + 26, Blocks.LEAVES, 0, 3);
		this.setBlock(x + 3, y + 3, z + 26, Blocks.LEAVES, 0, 3);
		this.setBlock(x + 4, y + 3, z + 26, Blocks.LEAVES, 0, 3);
		this.setBlock(x + 7, y + 3, z + 26, Blocks.LEAVES, 0, 3);
		this.setBlock(x + 8, y + 3, z + 26, Blocks.LEAVES, 0, 3);
		this.setBlock(x + 9, y + 3, z + 26, Blocks.LEAVES, 0, 3);
		this.setBlock(x + 10, y + 3, z + 26, Blocks.LEAVES, 0, 3);
		this.setBlock(x + 11, y + 3, z + 26, Blocks.LEAVES, 0, 3);
		this.setBlock(x + 0, y + 3, z + 27, Blocks.LEAVES, 0, 3);
		this.setBlock(x + 1, y + 3, z + 27, Blocks.LEAVES, 0, 3);
		this.setBlock(x + 2, y + 3, z + 27, Blocks.LOG, 0, 3);
		this.setBlock(x + 3, y + 3, z + 27, Blocks.LEAVES, 0, 3);
		this.setBlock(x + 4, y + 3, z + 27, Blocks.LEAVES, 0, 3);
		this.setBlock(x + 7, y + 3, z + 27, Blocks.LEAVES, 0, 3);
		this.setBlock(x + 8, y + 3, z + 27, Blocks.LEAVES, 0, 3);
		this.setBlock(x + 9, y + 3, z + 27, Blocks.LOG, 0, 3);
		this.setBlock(x + 10, y + 3, z + 27, Blocks.LEAVES, 0, 3);
		this.setBlock(x + 11, y + 3, z + 27, Blocks.LEAVES, 0, 3);
		this.setBlock(x + 0, y + 3, z + 28, Blocks.LEAVES, 0, 3);
		this.setBlock(x + 1, y + 3, z + 28, Blocks.LEAVES, 0, 3);
		this.setBlock(x + 2, y + 3, z + 28, Blocks.LEAVES, 0, 3);
		this.setBlock(x + 3, y + 3, z + 28, Blocks.LEAVES, 0, 3);
		this.setBlock(x + 4, y + 3, z + 28, Blocks.LEAVES, 0, 3);
		this.setBlock(x + 7, y + 3, z + 28, Blocks.LEAVES, 0, 3);
		this.setBlock(x + 8, y + 3, z + 28, Blocks.LEAVES, 0, 3);
		this.setBlock(x + 9, y + 3, z + 28, Blocks.LEAVES, 0, 3);
		this.setBlock(x + 10, y + 3, z + 28, Blocks.LEAVES, 0, 3);
		this.setBlock(x + 11, y + 3, z + 28, Blocks.LEAVES, 0, 3);
		this.setBlock(x + 1, y + 3, z + 29, Blocks.LEAVES, 0, 3);
		this.setBlock(x + 2, y + 3, z + 29, Blocks.LEAVES, 0, 3);
		this.setBlock(x + 3, y + 3, z + 29, Blocks.LEAVES, 0, 3);
		this.setBlock(x + 8, y + 3, z + 29, Blocks.LEAVES, 0, 3);
		this.setBlock(x + 9, y + 3, z + 29, Blocks.LEAVES, 0, 3);
		this.setBlock(x + 10, y + 3, z + 29, Blocks.LEAVES, 0, 3);
		this.setBlock(x + 2, y + 4, z + 0, Blocks.STONEBRICK, 0, 3);
		this.setBlock(x + 3, y + 4, z + 0, Blocks.STONEBRICK, 0, 3);
		this.setBlock(x + 4, y + 4, z + 0, Blocks.STONEBRICK, 0, 3);
		this.setBlock(x + 5, y + 4, z + 0, Blocks.STONEBRICK, 0, 3);
		this.setBlock(x + 6, y + 4, z + 0, Blocks.STONEBRICK, 0, 3);
		this.setBlock(x + 7, y + 4, z + 0, Blocks.STONEBRICK, 0, 3);
		this.setBlock(x + 8, y + 4, z + 0, Blocks.STONEBRICK, 0, 3);
		this.setBlock(x + 9, y + 4, z + 0, Blocks.STONEBRICK, 0, 3);
		this.setBlock(x + 1, y + 4, z + 1, Blocks.STONEBRICK, 0, 3);
		this.setBlock(x + 10, y + 4, z + 1, Blocks.STONEBRICK, 0, 3);
		this.setBlock(x + 0, y + 4, z + 2, Blocks.STONEBRICK, 0, 3);
		this.setBlock(x + 11, y + 4, z + 2, Blocks.STONEBRICK, 0, 3);
		this.setBlock(x + 0, y + 4, z + 3, Blocks.STAINED_GLASS, 14, 3);
		this.setBlock(x + 11, y + 4, z + 3, Blocks.STAINED_GLASS, 13, 3);
		this.setBlock(x + 0, y + 4, z + 4, Blocks.STAINED_GLASS, 14, 3);
		this.setBlock(x + 11, y + 4, z + 4, Blocks.STAINED_GLASS, 0, 3);
		this.setBlock(x + 0, y + 4, z + 5, Blocks.STAINED_GLASS, 0, 3);
		this.setBlock(x + 11, y + 4, z + 5, Blocks.STAINED_GLASS, 12, 3);
		this.setBlock(x + 0, y + 4, z + 6, Blocks.STAINED_GLASS, 5, 3);
		this.setBlock(x + 11, y + 4, z + 6, Blocks.STAINED_GLASS, 0, 3);
		this.setBlock(x + 0, y + 4, z + 7, Blocks.STAINED_GLASS, 5, 3);
		this.setBlock(x + 11, y + 4, z + 7, Blocks.STAINED_GLASS, 14, 3);
		this.setBlock(x + 0, y + 4, z + 8, Blocks.STONEBRICK, 0, 3);
		this.setBlock(x + 11, y + 4, z + 8, Blocks.STONEBRICK, 0, 3);
		this.setBlock(x + 0, y + 4, z + 9, Blocks.STONEBRICK, 0, 3);
		this.setBlock(x + 11, y + 4, z + 9, Blocks.STONEBRICK, 0, 3);
		this.setBlock(x + 0, y + 4, z + 10, Blocks.STAINED_GLASS, 0, 3);
		this.setBlock(x + 11, y + 4, z + 10, Blocks.STAINED_GLASS, 14, 3);
		this.setBlock(x + 0, y + 4, z + 11, Blocks.STAINED_GLASS, 0, 3);
		this.setBlock(x + 11, y + 4, z + 11, Blocks.STAINED_GLASS, 0, 3);
		this.setBlock(x + 0, y + 4, z + 12, Blocks.STAINED_GLASS, 0, 3);
		this.setBlock(x + 11, y + 4, z + 12, Blocks.STAINED_GLASS, 14, 3);
		this.setBlock(x + 0, y + 4, z + 13, Blocks.STAINED_GLASS, 0, 3);
		this.setBlock(x + 11, y + 4, z + 13, Blocks.STAINED_GLASS, 0, 3);
		this.setBlock(x + 0, y + 4, z + 14, Blocks.STAINED_GLASS, 0, 3);
		this.setBlock(x + 11, y + 4, z + 14, Blocks.STAINED_GLASS, 14, 3);
		this.setBlock(x + 0, y + 4, z + 15, Blocks.STONEBRICK, 0, 3);
		this.setBlock(x + 11, y + 4, z + 15, Blocks.STONEBRICK, 0, 3);
		this.setBlock(x + 1, y + 4, z + 16, Blocks.STONEBRICK, 0, 3);
		this.setBlock(x + 10, y + 4, z + 16, Blocks.STONEBRICK, 0, 3);
		this.setBlock(x + 2, y + 4, z + 17, Blocks.STONEBRICK, 0, 3);
		this.setBlock(x + 3, y + 4, z + 17, Blocks.STONEBRICK, 0, 3);
		this.setBlock(x + 4, y + 4, z + 17, Blocks.STONEBRICK, 0, 3);
		this.setBlock(x + 5, y + 4, z + 17, Blocks.STONEBRICK, 0, 3);
		this.setBlock(x + 6, y + 4, z + 17, Blocks.STONEBRICK, 0, 3);
		this.setBlock(x + 7, y + 4, z + 17, Blocks.STONEBRICK, 0, 3);
		this.setBlock(x + 8, y + 4, z + 17, Blocks.STONEBRICK, 0, 3);
		this.setBlock(x + 9, y + 4, z + 17, Blocks.STONEBRICK, 0, 3);
		this.setBlock(x + 3, y + 4, z + 22, GBlocks.stoneperch, 0, 3);
		this.setBlock(x + 8, y + 4, z + 22, GBlocks.stoneperch, 0, 3);
		this.setBlock(x + 1, y + 4, z + 25, Blocks.LEAVES, 0, 3);
		this.setBlock(x + 2, y + 4, z + 25, Blocks.LEAVES, 0, 3);
		this.setBlock(x + 3, y + 4, z + 25, Blocks.LEAVES, 0, 3);
		this.setBlock(x + 8, y + 4, z + 25, Blocks.LEAVES, 0, 3);
		this.setBlock(x + 9, y + 4, z + 25, Blocks.LEAVES, 0, 3);
		this.setBlock(x + 10, y + 4, z + 25, Blocks.LEAVES, 0, 3);
		this.setBlock(x + 0, y + 4, z + 26, Blocks.LEAVES, 0, 3);
		this.setBlock(x + 1, y + 4, z + 26, Blocks.LEAVES, 0, 3);
		this.setBlock(x + 2, y + 4, z + 26, Blocks.LEAVES, 0, 3);
		this.setBlock(x + 3, y + 4, z + 26, Blocks.LEAVES, 0, 3);
		this.setBlock(x + 4, y + 4, z + 26, Blocks.LEAVES, 0, 3);
		this.setBlock(x + 7, y + 4, z + 26, Blocks.LEAVES, 0, 3);
		this.setBlock(x + 8, y + 4, z + 26, Blocks.LEAVES, 0, 3);
		this.setBlock(x + 9, y + 4, z + 26, Blocks.LEAVES, 0, 3);
		this.setBlock(x + 10, y + 4, z + 26, Blocks.LEAVES, 0, 3);
		this.setBlock(x + 11, y + 4, z + 26, Blocks.LEAVES, 0, 3);
		this.setBlock(x + 0, y + 4, z + 27, Blocks.LEAVES, 0, 3);
		this.setBlock(x + 1, y + 4, z + 27, Blocks.LEAVES, 0, 3);
		this.setBlock(x + 2, y + 4, z + 27, Blocks.LOG, 0, 3);
		this.setBlock(x + 3, y + 4, z + 27, Blocks.LEAVES, 0, 3);
		this.setBlock(x + 4, y + 4, z + 27, Blocks.LEAVES, 0, 3);
		this.setBlock(x + 7, y + 4, z + 27, Blocks.LEAVES, 0, 3);
		this.setBlock(x + 8, y + 4, z + 27, Blocks.LEAVES, 0, 3);
		this.setBlock(x + 9, y + 4, z + 27, Blocks.LOG, 0, 3);
		this.setBlock(x + 10, y + 4, z + 27, Blocks.LEAVES, 0, 3);
		this.setBlock(x + 11, y + 4, z + 27, Blocks.LEAVES, 0, 3);
		this.setBlock(x + 0, y + 4, z + 28, Blocks.LEAVES, 0, 3);
		this.setBlock(x + 1, y + 4, z + 28, Blocks.LEAVES, 0, 3);
		this.setBlock(x + 2, y + 4, z + 28, Blocks.LEAVES, 0, 3);
		this.setBlock(x + 3, y + 4, z + 28, Blocks.LEAVES, 0, 3);
		this.setBlock(x + 4, y + 4, z + 28, Blocks.LEAVES, 0, 3);
		this.setBlock(x + 7, y + 4, z + 28, Blocks.LEAVES, 0, 3);
		this.setBlock(x + 8, y + 4, z + 28, Blocks.LEAVES, 0, 3);
		this.setBlock(x + 9, y + 4, z + 28, Blocks.LEAVES, 0, 3);
		this.setBlock(x + 10, y + 4, z + 28, Blocks.LEAVES, 0, 3);
		this.setBlock(x + 11, y + 4, z + 28, Blocks.LEAVES, 0, 3);
		this.setBlock(x + 1, y + 4, z + 29, Blocks.LEAVES, 0, 3);
		this.setBlock(x + 2, y + 4, z + 29, Blocks.LEAVES, 0, 3);
		this.setBlock(x + 3, y + 4, z + 29, Blocks.LEAVES, 0, 3);
		this.setBlock(x + 8, y + 4, z + 29, Blocks.LEAVES, 0, 3);
		this.setBlock(x + 9, y + 4, z + 29, Blocks.LEAVES, 0, 3);
		this.setBlock(x + 10, y + 4, z + 29, Blocks.LEAVES, 0, 3);
		this.setBlock(x + 1, y + 5, z + 0, Blocks.STONEBRICK, 0, 3);
		this.setBlock(x + 2, y + 5, z + 0, Blocks.STONEBRICK, 0, 3);
		this.setBlock(x + 3, y + 5, z + 0, Blocks.STONEBRICK, 0, 3);
		this.setBlock(x + 4, y + 5, z + 0, Blocks.STAINED_GLASS, 14, 3);
		this.setBlock(x + 5, y + 5, z + 0, Blocks.STAINED_GLASS, 0, 3);
		this.setBlock(x + 6, y + 5, z + 0, Blocks.STAINED_GLASS, 0, 3);
		this.setBlock(x + 7, y + 5, z + 0, Blocks.STAINED_GLASS, 14, 3);
		this.setBlock(x + 8, y + 5, z + 0, Blocks.STONEBRICK, 0, 3);
		this.setBlock(x + 9, y + 5, z + 0, Blocks.STONEBRICK, 0, 3);
		this.setBlock(x + 10, y + 5, z + 0, Blocks.STONEBRICK, 0, 3);
		this.setBlock(x + 0, y + 5, z + 1, Blocks.STONEBRICK, 0, 3);
		this.setBlock(x + 1, y + 5, z + 1, Blocks.STONEBRICK, 0, 3);
		this.setBlock(x + 10, y + 5, z + 1, Blocks.STONEBRICK, 0, 3);
		this.setBlock(x + 11, y + 5, z + 1, Blocks.STONEBRICK, 0, 3);
		this.setBlock(x + 0, y + 5, z + 2, Blocks.STONEBRICK, 0, 3);
		this.setBlock(x + 11, y + 5, z + 2, Blocks.STONEBRICK, 0, 3);
		this.setBlock(x + 0, y + 5, z + 3, Blocks.STAINED_GLASS, 14, 3);
		this.setBlock(x + 11, y + 5, z + 3, Blocks.STAINED_GLASS, 13, 3);
		this.setBlock(x + 0, y + 5, z + 4, Blocks.STAINED_GLASS, 14, 3);
		this.setBlock(x + 11, y + 5, z + 4, Blocks.STAINED_GLASS, 0, 3);
		this.setBlock(x + 0, y + 5, z + 5, Blocks.STAINED_GLASS, 0, 3);
		this.setBlock(x + 11, y + 5, z + 5, Blocks.STAINED_GLASS, 0, 3);
		this.setBlock(x + 0, y + 5, z + 6, Blocks.STAINED_GLASS, 5, 3);
		this.setBlock(x + 11, y + 5, z + 6, Blocks.STAINED_GLASS, 0, 3);
		this.setBlock(x + 0, y + 5, z + 7, Blocks.STAINED_GLASS, 5, 3);
		this.setBlock(x + 11, y + 5, z + 7, Blocks.STAINED_GLASS, 14, 3);
		this.setBlock(x + 0, y + 5, z + 8, Blocks.STONEBRICK, 0, 3);
		this.setBlock(x + 11, y + 5, z + 8, Blocks.STONEBRICK, 0, 3);
		this.setBlock(x + 0, y + 5, z + 9, Blocks.STONEBRICK, 0, 3);
		this.setBlock(x + 11, y + 5, z + 9, Blocks.STONEBRICK, 0, 3);
		this.setBlock(x + 0, y + 5, z + 10, Blocks.STAINED_GLASS, 14, 3);
		this.setBlock(x + 11, y + 5, z + 10, Blocks.STAINED_GLASS, 14, 3);
		this.setBlock(x + 0, y + 5, z + 11, Blocks.STAINED_GLASS, 14, 3);
		this.setBlock(x + 11, y + 5, z + 11, Blocks.STAINED_GLASS, 0, 3);
		this.setBlock(x + 0, y + 5, z + 12, Blocks.STAINED_GLASS, 14, 3);
		this.setBlock(x + 11, y + 5, z + 12, Blocks.STAINED_GLASS, 0, 3);
		this.setBlock(x + 0, y + 5, z + 13, Blocks.STAINED_GLASS, 11, 3);
		this.setBlock(x + 11, y + 5, z + 13, Blocks.STAINED_GLASS, 0, 3);
		this.setBlock(x + 0, y + 5, z + 14, Blocks.STAINED_GLASS, 11, 3);
		this.setBlock(x + 11, y + 5, z + 14, Blocks.STAINED_GLASS, 14, 3);
		this.setBlock(x + 0, y + 5, z + 15, Blocks.STONEBRICK, 0, 3);
		this.setBlock(x + 11, y + 5, z + 15, Blocks.STONEBRICK, 0, 3);
		this.setBlock(x + 0, y + 5, z + 16, Blocks.STONEBRICK, 0, 3);
		this.setBlock(x + 1, y + 5, z + 16, Blocks.STONEBRICK, 0, 3);
		this.setBlock(x + 10, y + 5, z + 16, Blocks.STONEBRICK, 0, 3);
		this.setBlock(x + 11, y + 5, z + 16, Blocks.STONEBRICK, 0, 3);
		this.setBlock(x + 1, y + 5, z + 17, Blocks.STONEBRICK, 0, 3);
		this.setBlock(x + 2, y + 5, z + 17, Blocks.STONEBRICK, 0, 3);
		this.setBlock(x + 3, y + 5, z + 17, Blocks.STONEBRICK, 0, 3);
		this.setBlock(x + 4, y + 5, z + 17, Blocks.STONEBRICK, 0, 3);
		this.setBlock(x + 5, y + 5, z + 17, Blocks.STONEBRICK, 0, 3);
		this.setBlock(x + 6, y + 5, z + 17, Blocks.STONEBRICK, 0, 3);
		this.setBlock(x + 7, y + 5, z + 17, Blocks.STONEBRICK, 0, 3);
		this.setBlock(x + 8, y + 5, z + 17, Blocks.STONEBRICK, 0, 3);
		this.setBlock(x + 9, y + 5, z + 17, Blocks.STONEBRICK, 0, 3);
		this.setBlock(x + 10, y + 5, z + 17, Blocks.STONEBRICK, 0, 3);
		this.setBlock(x + 4, y + 5, z + 18, Blocks.STONEBRICK, 0, 3);
		this.setBlock(x + 7, y + 5, z + 18, Blocks.STONEBRICK, 0, 3);
		this.setBlock(x + 1, y + 5, z + 26, Blocks.LEAVES, 0, 3);
		this.setBlock(x + 2, y + 5, z + 26, Blocks.LEAVES, 0, 3);
		this.setBlock(x + 3, y + 5, z + 26, Blocks.LEAVES, 0, 3);
		this.setBlock(x + 8, y + 5, z + 26, Blocks.LEAVES, 0, 3);
		this.setBlock(x + 9, y + 5, z + 26, Blocks.LEAVES, 0, 3);
		this.setBlock(x + 10, y + 5, z + 26, Blocks.LEAVES, 0, 3);
		this.setBlock(x + 1, y + 5, z + 27, Blocks.LEAVES, 0, 3);
		this.setBlock(x + 2, y + 5, z + 27, Blocks.LOG, 0, 3);
		this.setBlock(x + 3, y + 5, z + 27, Blocks.LEAVES, 0, 3);
		this.setBlock(x + 8, y + 5, z + 27, Blocks.LEAVES, 0, 3);
		this.setBlock(x + 9, y + 5, z + 27, Blocks.LOG, 0, 3);
		this.setBlock(x + 10, y + 5, z + 27, Blocks.LEAVES, 0, 3);
		this.setBlock(x + 1, y + 5, z + 28, Blocks.LEAVES, 12, 3);
		this.setBlock(x + 2, y + 5, z + 28, Blocks.LEAVES, 0, 3);
		this.setBlock(x + 3, y + 5, z + 28, Blocks.LEAVES, 4, 3);
		this.setBlock(x + 8, y + 5, z + 28, Blocks.LEAVES, 12, 3);
		this.setBlock(x + 9, y + 5, z + 28, Blocks.LEAVES, 0, 3);
		this.setBlock(x + 10, y + 5, z + 28, Blocks.LEAVES, 0, 3);
		this.setBlock(x + 1, y + 6, z + 0, GBlocks.stoneperch, 0, 3);
		this.setBlock(x + 2, y + 6, z + 0, Blocks.STONEBRICK, 0, 3);
		this.setBlock(x + 3, y + 6, z + 0, Blocks.STAINED_GLASS, 14, 3);
		this.setBlock(x + 4, y + 6, z + 0, Blocks.STAINED_GLASS, 0, 3);
		this.setBlock(x + 5, y + 6, z + 0, Blocks.STAINED_GLASS, 0, 3);
		this.setBlock(x + 6, y + 6, z + 0, Blocks.STAINED_GLASS, 0, 3);
		this.setBlock(x + 7, y + 6, z + 0, Blocks.STAINED_GLASS, 0, 3);
		this.setBlock(x + 8, y + 6, z + 0, Blocks.STAINED_GLASS, 14, 3);
		this.setBlock(x + 9, y + 6, z + 0, Blocks.STONEBRICK, 0, 3);
		this.setBlock(x + 10, y + 6, z + 0, GBlocks.stoneperch, 0, 3);
		this.setBlock(x + 0, y + 6, z + 1, GBlocks.stoneperch, 0, 3);
		this.setBlock(x + 1, y + 6, z + 1, Blocks.STONEBRICK, 0, 3);
		this.setBlock(x + 10, y + 6, z + 1, Blocks.STONEBRICK, 0, 3);
		this.setBlock(x + 11, y + 6, z + 1, GBlocks.stoneperch, 0, 3);
		this.setBlock(x + 0, y + 6, z + 2, Blocks.STONEBRICK, 0, 3);
		this.setBlock(x + 11, y + 6, z + 2, Blocks.STONEBRICK, 0, 3);
		this.setBlock(x + 0, y + 6, z + 3, Blocks.STONEBRICK, 0, 3);
		this.setBlock(x + 11, y + 6, z + 3, Blocks.STONEBRICK, 0, 3);
		this.setBlock(x + 0, y + 6, z + 4, Blocks.STONEBRICK, 0, 3);
		this.setBlock(x + 11, y + 6, z + 4, Blocks.STONEBRICK, 0, 3);
		this.setBlock(x + 0, y + 6, z + 5, Blocks.STONEBRICK, 0, 3);
		this.setBlock(x + 11, y + 6, z + 5, Blocks.STONEBRICK, 0, 3);
		this.setBlock(x + 0, y + 6, z + 6, Blocks.STONEBRICK, 0, 3);
		this.setBlock(x + 11, y + 6, z + 6, Blocks.STONEBRICK, 0, 3);
		this.setBlock(x + 0, y + 6, z + 7, Blocks.STONEBRICK, 0, 3);
		this.setBlock(x + 11, y + 6, z + 7, Blocks.STONEBRICK, 0, 3);
		this.setBlock(x + 0, y + 6, z + 8, Blocks.STONEBRICK, 0, 3);
		this.setBlock(x + 11, y + 6, z + 8, Blocks.STONEBRICK, 0, 3);
		this.setBlock(x + 0, y + 6, z + 9, Blocks.STONEBRICK, 0, 3);
		this.setBlock(x + 11, y + 6, z + 9, Blocks.STONEBRICK, 0, 3);
		this.setBlock(x + 0, y + 6, z + 10, Blocks.STONEBRICK, 0, 3);
		this.setBlock(x + 11, y + 6, z + 10, Blocks.STONEBRICK, 0, 3);
		this.setBlock(x + 0, y + 6, z + 11, Blocks.STONEBRICK, 0, 3);
		this.setBlock(x + 11, y + 6, z + 11, Blocks.STONEBRICK, 0, 3);
		this.setBlock(x + 0, y + 6, z + 12, Blocks.STONEBRICK, 0, 3);
		this.setBlock(x + 11, y + 6, z + 12, Blocks.STONEBRICK, 0, 3);
		this.setBlock(x + 0, y + 6, z + 13, Blocks.STONEBRICK, 0, 3);
		this.setBlock(x + 11, y + 6, z + 13, Blocks.STONEBRICK, 0, 3);
		this.setBlock(x + 0, y + 6, z + 14, Blocks.STONEBRICK, 0, 3);
		this.setBlock(x + 11, y + 6, z + 14, Blocks.STONEBRICK, 0, 3);
		this.setBlock(x + 0, y + 6, z + 15, Blocks.STONEBRICK, 0, 3);
		this.setBlock(x + 11, y + 6, z + 15, Blocks.STONEBRICK, 0, 3);
		this.setBlock(x + 0, y + 6, z + 16, GBlocks.stoneperch, 0, 3);
		this.setBlock(x + 1, y + 6, z + 16, Blocks.STONEBRICK, 0, 3);
		this.setBlock(x + 10, y + 6, z + 16, Blocks.STONEBRICK, 0, 3);
		this.setBlock(x + 11, y + 6, z + 16, GBlocks.stoneperch, 0, 3);
		this.setBlock(x + 1, y + 6, z + 17, GBlocks.stoneperch, 0, 3);
		this.setBlock(x + 2, y + 6, z + 17, Blocks.STONEBRICK, 0, 3);
		this.setBlock(x + 3, y + 6, z + 17, Blocks.STONEBRICK, 0, 3);
		this.setBlock(x + 4, y + 6, z + 17, Blocks.STONEBRICK, 0, 3);
		this.setBlock(x + 5, y + 6, z + 17, Blocks.STONEBRICK, 0, 3);
		this.setBlock(x + 6, y + 6, z + 17, Blocks.STONEBRICK, 0, 3);
		this.setBlock(x + 7, y + 6, z + 17, Blocks.STONEBRICK, 0, 3);
		this.setBlock(x + 8, y + 6, z + 17, Blocks.STONEBRICK, 0, 3);
		this.setBlock(x + 9, y + 6, z + 17, Blocks.STONEBRICK, 0, 3);
		this.setBlock(x + 10, y + 6, z + 17, GBlocks.stoneperch, 0, 3);
		this.setBlock(x + 4, y + 6, z + 18, GBlocks.stoneperch, 0, 3);
		this.setBlock(x + 7, y + 6, z + 18, GBlocks.stoneperch, 0, 3);
		this.setBlock(x + 2, y + 6, z + 26, Blocks.LEAVES, 0, 3);
		this.setBlock(x + 9, y + 6, z + 26, Blocks.LEAVES, 4, 3);
		this.setBlock(x + 1, y + 6, z + 27, Blocks.LEAVES, 0, 3);
		this.setBlock(x + 2, y + 6, z + 27, Blocks.LEAVES, 0, 3);
		this.setBlock(x + 3, y + 6, z + 27, Blocks.LEAVES, 0, 3);
		this.setBlock(x + 8, y + 6, z + 27, Blocks.LEAVES, 12, 3);
		this.setBlock(x + 9, y + 6, z + 27, Blocks.LEAVES, 4, 3);
		this.setBlock(x + 10, y + 6, z + 27, Blocks.LEAVES, 0, 3);
		this.setBlock(x + 2, y + 6, z + 28, Blocks.LEAVES, 0, 3);
		this.setBlock(x + 9, y + 6, z + 28, Blocks.LEAVES, 0, 3);
		this.setBlock(x + 2, y + 7, z + 0, Blocks.STONEBRICK, 0, 3);
		this.setBlock(x + 3, y + 7, z + 0, Blocks.STAINED_GLASS, 0, 3);
		this.setBlock(x + 4, y + 7, z + 0, Blocks.STAINED_GLASS, 0, 3);
		this.setBlock(x + 5, y + 7, z + 0, Blocks.STAINED_GLASS, 8, 3);
		this.setBlock(x + 6, y + 7, z + 0, Blocks.STAINED_GLASS, 8, 3);
		this.setBlock(x + 7, y + 7, z + 0, Blocks.STAINED_GLASS, 0, 3);
		this.setBlock(x + 8, y + 7, z + 0, Blocks.STAINED_GLASS, 0, 3);
		this.setBlock(x + 9, y + 7, z + 0, Blocks.STONEBRICK, 0, 3);
		this.setBlock(x + 1, y + 7, z + 1, Blocks.STONEBRICK, 0, 3);
		this.setBlock(x + 10, y + 7, z + 1, Blocks.STONEBRICK, 0, 3);
		this.setBlock(x + 0, y + 7, z + 2, Blocks.STONEBRICK, 0, 3);
		this.setBlock(x + 11, y + 7, z + 2, Blocks.STONEBRICK, 0, 3);
		this.setBlock(x + 0, y + 7, z + 3, Blocks.STONEBRICK, 0, 3);
		this.setBlock(x + 11, y + 7, z + 3, Blocks.STONEBRICK, 0, 3);
		this.setBlock(x + 0, y + 7, z + 4, Blocks.STONEBRICK, 0, 3);
		this.setBlock(x + 11, y + 7, z + 4, Blocks.STONEBRICK, 0, 3);
		this.setBlock(x + 0, y + 7, z + 5, Blocks.STONEBRICK, 0, 3);
		this.setBlock(x + 11, y + 7, z + 5, Blocks.STONEBRICK, 0, 3);
		this.setBlock(x + 0, y + 7, z + 6, Blocks.STONEBRICK, 0, 3);
		this.setBlock(x + 11, y + 7, z + 6, Blocks.STONEBRICK, 0, 3);
		this.setBlock(x + 0, y + 7, z + 7, Blocks.STONEBRICK, 0, 3);
		this.setBlock(x + 11, y + 7, z + 7, Blocks.STONEBRICK, 0, 3);
		this.setBlock(x + 0, y + 7, z + 8, Blocks.STONEBRICK, 0, 3);
		this.setBlock(x + 11, y + 7, z + 8, Blocks.STONEBRICK, 0, 3);
		this.setBlock(x + 0, y + 7, z + 9, Blocks.STONEBRICK, 0, 3);
		this.setBlock(x + 11, y + 7, z + 9, Blocks.STONEBRICK, 0, 3);
		this.setBlock(x + 0, y + 7, z + 10, Blocks.STONEBRICK, 0, 3);
		this.setBlock(x + 11, y + 7, z + 10, Blocks.STONEBRICK, 0, 3);
		this.setBlock(x + 0, y + 7, z + 11, Blocks.STONEBRICK, 0, 3);
		this.setBlock(x + 11, y + 7, z + 11, Blocks.STONEBRICK, 0, 3);
		this.setBlock(x + 0, y + 7, z + 12, Blocks.STONEBRICK, 0, 3);
		this.setBlock(x + 11, y + 7, z + 12, Blocks.STONEBRICK, 0, 3);
		this.setBlock(x + 0, y + 7, z + 13, Blocks.STONEBRICK, 0, 3);
		this.setBlock(x + 11, y + 7, z + 13, Blocks.STONEBRICK, 0, 3);
		this.setBlock(x + 0, y + 7, z + 14, Blocks.STONEBRICK, 0, 3);
		this.setBlock(x + 11, y + 7, z + 14, Blocks.STONEBRICK, 0, 3);
		this.setBlock(x + 0, y + 7, z + 15, Blocks.STONEBRICK, 0, 3);
		this.setBlock(x + 11, y + 7, z + 15, Blocks.STONEBRICK, 0, 3);
		this.setBlock(x + 1, y + 7, z + 16, Blocks.STONEBRICK, 0, 3);
		this.setBlock(x + 10, y + 7, z + 16, Blocks.STONEBRICK, 0, 3);
		this.setBlock(x + 2, y + 7, z + 17, Blocks.STONEBRICK, 0, 3);
		this.setBlock(x + 3, y + 7, z + 17, Blocks.STONEBRICK, 0, 3);
		this.setBlock(x + 4, y + 7, z + 17, Blocks.STONEBRICK, 0, 3);
		this.setBlock(x + 5, y + 7, z + 17, Blocks.STONEBRICK, 0, 3);
		this.setBlock(x + 6, y + 7, z + 17, Blocks.STONEBRICK, 0, 3);
		this.setBlock(x + 7, y + 7, z + 17, Blocks.STONEBRICK, 0, 3);
		this.setBlock(x + 8, y + 7, z + 17, Blocks.STONEBRICK, 0, 3);
		this.setBlock(x + 9, y + 7, z + 17, Blocks.STONEBRICK, 0, 3);
		this.setBlock(x + 2, y + 7, z + 27, Blocks.LEAVES, 4, 3);
		this.setBlock(x + 9, y + 7, z + 27, Blocks.LEAVES, 4, 3);
		this.setBlock(x + 2, y + 8, z + 0, Blocks.STONEBRICK, 0, 3);
		this.setBlock(x + 3, y + 8, z + 0, Blocks.STAINED_GLASS, 0, 3);
		this.setBlock(x + 4, y + 8, z + 0, Blocks.STAINED_GLASS, 8, 3);
		this.setBlock(x + 5, y + 8, z + 0, Blocks.STAINED_GLASS, 7, 3);
		this.setBlock(x + 6, y + 8, z + 0, Blocks.STAINED_GLASS, 7, 3);
		this.setBlock(x + 7, y + 8, z + 0, Blocks.STAINED_GLASS, 8, 3);
		this.setBlock(x + 8, y + 8, z + 0, Blocks.STAINED_GLASS, 0, 3);
		this.setBlock(x + 9, y + 8, z + 0, Blocks.STONEBRICK, 0, 3);
		this.setBlock(x + 1, y + 8, z + 1, Blocks.STONEBRICK, 0, 3);
		this.setBlock(x + 10, y + 8, z + 1, Blocks.STONEBRICK, 0, 3);
		this.setBlock(x + 0, y + 8, z + 2, Blocks.STONEBRICK, 0, 3);
		this.setBlock(x + 11, y + 8, z + 2, Blocks.STONEBRICK, 0, 3);
		this.setBlock(x + 0, y + 8, z + 3, Blocks.STONEBRICK, 0, 3);
		this.setBlock(x + 11, y + 8, z + 3, Blocks.STONEBRICK, 0, 3);
		this.setBlock(x + 0, y + 8, z + 4, Blocks.STONEBRICK, 0, 3);
		this.setBlock(x + 11, y + 8, z + 4, Blocks.STONEBRICK, 0, 3);
		this.setBlock(x + 0, y + 8, z + 5, Blocks.STONEBRICK, 0, 3);
		this.setBlock(x + 11, y + 8, z + 5, Blocks.STONEBRICK, 0, 3);
		this.setBlock(x + 0, y + 8, z + 6, Blocks.STONEBRICK, 0, 3);
		this.setBlock(x + 11, y + 8, z + 6, Blocks.STONEBRICK, 0, 3);
		this.setBlock(x + 0, y + 8, z + 7, Blocks.STONEBRICK, 0, 3);
		this.setBlock(x + 11, y + 8, z + 7, Blocks.STONEBRICK, 0, 3);
		this.setBlock(x + 0, y + 8, z + 8, Blocks.STONEBRICK, 0, 3);
		this.setBlock(x + 11, y + 8, z + 8, Blocks.STONEBRICK, 0, 3);
		this.setBlock(x + 0, y + 8, z + 9, Blocks.STONEBRICK, 0, 3);
		this.setBlock(x + 11, y + 8, z + 9, Blocks.STONEBRICK, 0, 3);
		this.setBlock(x + 0, y + 8, z + 10, Blocks.STONEBRICK, 0, 3);
		this.setBlock(x + 11, y + 8, z + 10, Blocks.STONEBRICK, 0, 3);
		this.setBlock(x + 0, y + 8, z + 11, Blocks.STONEBRICK, 0, 3);
		this.setBlock(x + 11, y + 8, z + 11, Blocks.STONEBRICK, 0, 3);
		this.setBlock(x + 0, y + 8, z + 12, Blocks.STONEBRICK, 0, 3);
		this.setBlock(x + 11, y + 8, z + 12, Blocks.STONEBRICK, 0, 3);
		this.setBlock(x + 0, y + 8, z + 13, Blocks.STONEBRICK, 0, 3);
		this.setBlock(x + 11, y + 8, z + 13, Blocks.STONEBRICK, 0, 3);
		this.setBlock(x + 0, y + 8, z + 14, Blocks.STONEBRICK, 0, 3);
		this.setBlock(x + 11, y + 8, z + 14, Blocks.STONEBRICK, 0, 3);
		this.setBlock(x + 0, y + 8, z + 15, Blocks.STONEBRICK, 0, 3);
		this.setBlock(x + 11, y + 8, z + 15, Blocks.STONEBRICK, 0, 3);
		this.setBlock(x + 1, y + 8, z + 16, Blocks.STONEBRICK, 0, 3);
		this.setBlock(x + 10, y + 8, z + 16, Blocks.STONEBRICK, 0, 3);
		this.setBlock(x + 2, y + 8, z + 17, Blocks.STONEBRICK, 0, 3);
		this.setBlock(x + 3, y + 8, z + 17, Blocks.STONEBRICK, 0, 3);
		this.setBlock(x + 4, y + 8, z + 17, Blocks.STAINED_GLASS, 14, 3);
		this.setBlock(x + 5, y + 8, z + 17, Blocks.STAINED_GLASS, 0, 3);
		this.setBlock(x + 6, y + 8, z + 17, Blocks.STAINED_GLASS, 0, 3);
		this.setBlock(x + 7, y + 8, z + 17, Blocks.STAINED_GLASS, 14, 3);
		this.setBlock(x + 8, y + 8, z + 17, Blocks.STONEBRICK, 0, 3);
		this.setBlock(x + 9, y + 8, z + 17, Blocks.STONEBRICK, 0, 3);
		this.setBlock(x + 2, y + 9, z + 0, Blocks.STONEBRICK, 0, 3);
		this.setBlock(x + 3, y + 9, z + 0, Blocks.STAINED_GLASS, 8, 3);
		this.setBlock(x + 4, y + 9, z + 0, Blocks.STAINED_GLASS, 7, 3);
		this.setBlock(x + 5, y + 9, z + 0, Blocks.STAINED_GLASS, 15, 3);
		this.setBlock(x + 6, y + 9, z + 0, Blocks.STAINED_GLASS, 15, 3);
		this.setBlock(x + 7, y + 9, z + 0, Blocks.STAINED_GLASS, 7, 3);
		this.setBlock(x + 8, y + 9, z + 0, Blocks.STAINED_GLASS, 8, 3);
		this.setBlock(x + 9, y + 9, z + 0, Blocks.STONEBRICK, 0, 3);
		this.setBlock(x + 1, y + 9, z + 1, Blocks.STONEBRICK, 0, 3);
		this.setBlock(x + 10, y + 9, z + 1, Blocks.STONEBRICK, 0, 3);
		this.setBlock(x + 0, y + 9, z + 2, Blocks.STONEBRICK, 0, 3);
		this.setBlock(x + 11, y + 9, z + 2, Blocks.STONEBRICK, 0, 3);
		this.setBlock(x + 0, y + 9, z + 3, Blocks.STONEBRICK, 0, 3);
		this.setBlock(x + 11, y + 9, z + 3, Blocks.STONEBRICK, 0, 3);
		this.setBlock(x + 0, y + 9, z + 4, Blocks.STONEBRICK, 0, 3);
		this.setBlock(x + 11, y + 9, z + 4, Blocks.STONEBRICK, 0, 3);
		this.setBlock(x + 0, y + 9, z + 5, Blocks.STONEBRICK, 0, 3);
		this.setBlock(x + 11, y + 9, z + 5, Blocks.STONEBRICK, 0, 3);
		this.setBlock(x + 0, y + 9, z + 6, Blocks.STONEBRICK, 0, 3);
		this.setBlock(x + 11, y + 9, z + 6, Blocks.STONEBRICK, 0, 3);
		this.setBlock(x + 0, y + 9, z + 7, Blocks.STONEBRICK, 0, 3);
		this.setBlock(x + 11, y + 9, z + 7, Blocks.STONEBRICK, 0, 3);
		this.setBlock(x + 0, y + 9, z + 8, Blocks.STONEBRICK, 0, 3);
		this.setBlock(x + 11, y + 9, z + 8, Blocks.STONEBRICK, 0, 3);
		this.setBlock(x + 0, y + 9, z + 9, Blocks.STONEBRICK, 0, 3);
		this.setBlock(x + 11, y + 9, z + 9, Blocks.STONEBRICK, 0, 3);
		this.setBlock(x + 0, y + 9, z + 10, Blocks.STONEBRICK, 0, 3);
		this.setBlock(x + 11, y + 9, z + 10, Blocks.STONEBRICK, 0, 3);
		this.setBlock(x + 0, y + 9, z + 11, Blocks.STONEBRICK, 0, 3);
		this.setBlock(x + 11, y + 9, z + 11, Blocks.STONEBRICK, 0, 3);
		this.setBlock(x + 0, y + 9, z + 12, Blocks.STONEBRICK, 0, 3);
		this.setBlock(x + 11, y + 9, z + 12, Blocks.STONEBRICK, 0, 3);
		this.setBlock(x + 0, y + 9, z + 13, Blocks.STONEBRICK, 0, 3);
		this.setBlock(x + 11, y + 9, z + 13, Blocks.STONEBRICK, 0, 3);
		this.setBlock(x + 0, y + 9, z + 14, Blocks.STONEBRICK, 0, 3);
		this.setBlock(x + 11, y + 9, z + 14, Blocks.STONEBRICK, 0, 3);
		this.setBlock(x + 0, y + 9, z + 15, Blocks.STONEBRICK, 0, 3);
		this.setBlock(x + 11, y + 9, z + 15, Blocks.STONEBRICK, 0, 3);
		this.setBlock(x + 1, y + 9, z + 16, Blocks.STONEBRICK, 0, 3);
		this.setBlock(x + 10, y + 9, z + 16, Blocks.STONEBRICK, 0, 3);
		this.setBlock(x + 2, y + 9, z + 17, Blocks.STONEBRICK, 0, 3);
		this.setBlock(x + 3, y + 9, z + 17, Blocks.STAINED_GLASS, 14, 3);
		this.setBlock(x + 4, y + 9, z + 17, Blocks.STAINED_GLASS, 15, 3);
		this.setBlock(x + 5, y + 9, z + 17, Blocks.STAINED_GLASS, 8, 3);
		this.setBlock(x + 6, y + 9, z + 17, Blocks.STAINED_GLASS, 8, 3);
		this.setBlock(x + 7, y + 9, z + 17, Blocks.STAINED_GLASS, 15, 3);
		this.setBlock(x + 8, y + 9, z + 17, Blocks.STAINED_GLASS, 14, 3);
		this.setBlock(x + 9, y + 9, z + 17, Blocks.STONEBRICK, 0, 3);
		this.setBlock(x + 2, y + 10, z + 0, Blocks.STONEBRICK, 0, 3);
		this.setBlock(x + 3, y + 10, z + 0, Blocks.STAINED_GLASS, 8, 3);
		this.setBlock(x + 4, y + 10, z + 0, Blocks.STAINED_GLASS, 7, 3);
		this.setBlock(x + 5, y + 10, z + 0, Blocks.STAINED_GLASS, 15, 3);
		this.setBlock(x + 6, y + 10, z + 0, Blocks.STAINED_GLASS, 15, 3);
		this.setBlock(x + 7, y + 10, z + 0, Blocks.STAINED_GLASS, 7, 3);
		this.setBlock(x + 8, y + 10, z + 0, Blocks.STAINED_GLASS, 8, 3);
		this.setBlock(x + 9, y + 10, z + 0, Blocks.STONEBRICK, 0, 3);
		this.setBlock(x + 1, y + 10, z + 1, Blocks.STONEBRICK, 0, 3);
		this.setBlock(x + 10, y + 10, z + 1, Blocks.STONEBRICK, 0, 3);
		this.setBlock(x + 0, y + 10, z + 2, Blocks.STONEBRICK, 0, 3);
		this.setBlock(x + 11, y + 10, z + 2, Blocks.STONEBRICK, 0, 3);
		this.setBlock(x + 0, y + 10, z + 3, Blocks.STONEBRICK, 0, 3);
		this.setBlock(x + 11, y + 10, z + 3, Blocks.STONEBRICK, 0, 3);
		this.setBlock(x + 0, y + 10, z + 4, Blocks.STONEBRICK, 0, 3);
		this.setBlock(x + 11, y + 10, z + 4, Blocks.STONEBRICK, 0, 3);
		this.setBlock(x + 0, y + 10, z + 5, Blocks.STONEBRICK, 0, 3);
		this.setBlock(x + 11, y + 10, z + 5, Blocks.STONEBRICK, 0, 3);
		this.setBlock(x + 0, y + 10, z + 6, Blocks.STONEBRICK, 0, 3);
		this.setBlock(x + 11, y + 10, z + 6, Blocks.STONEBRICK, 0, 3);
		this.setBlock(x + 0, y + 10, z + 7, Blocks.STONEBRICK, 0, 3);
		this.setBlock(x + 11, y + 10, z + 7, Blocks.STONEBRICK, 0, 3);
		this.setBlock(x + 0, y + 10, z + 8, Blocks.STONEBRICK, 0, 3);
		this.setBlock(x + 11, y + 10, z + 8, Blocks.STONEBRICK, 0, 3);
		this.setBlock(x + 0, y + 10, z + 9, Blocks.STONEBRICK, 0, 3);
		this.setBlock(x + 11, y + 10, z + 9, Blocks.STONEBRICK, 0, 3);
		this.setBlock(x + 0, y + 10, z + 10, Blocks.STONEBRICK, 0, 3);
		this.setBlock(x + 11, y + 10, z + 10, Blocks.STONEBRICK, 0, 3);
		this.setBlock(x + 0, y + 10, z + 11, Blocks.STONEBRICK, 0, 3);
		this.setBlock(x + 11, y + 10, z + 11, Blocks.STONEBRICK, 0, 3);
		this.setBlock(x + 0, y + 10, z + 12, Blocks.STONEBRICK, 0, 3);
		this.setBlock(x + 11, y + 10, z + 12, Blocks.STONEBRICK, 0, 3);
		this.setBlock(x + 0, y + 10, z + 13, Blocks.STONEBRICK, 0, 3);
		this.setBlock(x + 11, y + 10, z + 13, Blocks.STONEBRICK, 0, 3);
		this.setBlock(x + 0, y + 10, z + 14, Blocks.STONEBRICK, 0, 3);
		this.setBlock(x + 11, y + 10, z + 14, Blocks.STONEBRICK, 0, 3);
		this.setBlock(x + 0, y + 10, z + 15, Blocks.STONEBRICK, 0, 3);
		this.setBlock(x + 11, y + 10, z + 15, Blocks.STONEBRICK, 0, 3);
		this.setBlock(x + 1, y + 10, z + 16, Blocks.STONEBRICK, 0, 3);
		this.setBlock(x + 10, y + 10, z + 16, Blocks.STONEBRICK, 0, 3);
		this.setBlock(x + 2, y + 10, z + 17, Blocks.STONEBRICK, 0, 3);
		this.setBlock(x + 3, y + 10, z + 17, Blocks.STAINED_GLASS, 0, 3);
		this.setBlock(x + 4, y + 10, z + 17, Blocks.STAINED_GLASS, 8, 3);
		this.setBlock(x + 5, y + 10, z + 17, Blocks.STAINED_GLASS, 15, 3);
		this.setBlock(x + 6, y + 10, z + 17, Blocks.STAINED_GLASS, 15, 3);
		this.setBlock(x + 7, y + 10, z + 17, Blocks.STAINED_GLASS, 8, 3);
		this.setBlock(x + 8, y + 10, z + 17, Blocks.STAINED_GLASS, 0, 3);
		this.setBlock(x + 9, y + 10, z + 17, Blocks.STONEBRICK, 0, 3);
		this.setBlock(x + 2, y + 11, z + 0, Blocks.STONEBRICK, 0, 3);
		this.setBlock(x + 3, y + 11, z + 0, Blocks.STAINED_GLASS, 8, 3);
		this.setBlock(x + 4, y + 11, z + 0, Blocks.STAINED_GLASS, 7, 3);
		this.setBlock(x + 5, y + 11, z + 0, Blocks.STAINED_GLASS, 15, 3);
		this.setBlock(x + 6, y + 11, z + 0, Blocks.STAINED_GLASS, 15, 3);
		this.setBlock(x + 7, y + 11, z + 0, Blocks.STAINED_GLASS, 7, 3);
		this.setBlock(x + 8, y + 11, z + 0, Blocks.STAINED_GLASS, 8, 3);
		this.setBlock(x + 9, y + 11, z + 0, Blocks.STONEBRICK, 0, 3);
		this.setBlock(x + 1, y + 11, z + 1, Blocks.STONEBRICK, 0, 3);
		this.setBlock(x + 10, y + 11, z + 1, Blocks.STONEBRICK, 0, 3);
		this.setBlock(x + 0, y + 11, z + 2, Blocks.STONEBRICK, 0, 3);
		this.setBlock(x + 11, y + 11, z + 2, Blocks.STONEBRICK, 0, 3);
		this.setBlock(x + 0, y + 11, z + 3, Blocks.STONEBRICK, 0, 3);
		this.setBlock(x + 11, y + 11, z + 3, Blocks.STONEBRICK, 0, 3);
		this.setBlock(x + 0, y + 11, z + 4, Blocks.STONEBRICK, 0, 3);
		this.setBlock(x + 11, y + 11, z + 4, Blocks.STONEBRICK, 0, 3);
		this.setBlock(x + 0, y + 11, z + 5, Blocks.STONEBRICK, 0, 3);
		this.setBlock(x + 11, y + 11, z + 5, Blocks.STONEBRICK, 0, 3);
		this.setBlock(x + 0, y + 11, z + 6, Blocks.STONEBRICK, 0, 3);
		this.setBlock(x + 11, y + 11, z + 6, Blocks.STONEBRICK, 0, 3);
		this.setBlock(x + 0, y + 11, z + 7, Blocks.STONEBRICK, 0, 3);
		this.setBlock(x + 11, y + 11, z + 7, Blocks.STONEBRICK, 0, 3);
		this.setBlock(x + 0, y + 11, z + 8, Blocks.STONEBRICK, 0, 3);
		this.setBlock(x + 11, y + 11, z + 8, Blocks.STONEBRICK, 0, 3);
		this.setBlock(x + 0, y + 11, z + 9, Blocks.STONEBRICK, 0, 3);
		this.setBlock(x + 11, y + 11, z + 9, Blocks.STONEBRICK, 0, 3);
		this.setBlock(x + 0, y + 11, z + 10, Blocks.STONEBRICK, 0, 3);
		this.setBlock(x + 11, y + 11, z + 10, Blocks.STONEBRICK, 0, 3);
		this.setBlock(x + 0, y + 11, z + 11, Blocks.STONEBRICK, 0, 3);
		this.setBlock(x + 11, y + 11, z + 11, Blocks.STONEBRICK, 0, 3);
		this.setBlock(x + 0, y + 11, z + 12, Blocks.STONEBRICK, 0, 3);
		this.setBlock(x + 11, y + 11, z + 12, Blocks.STONEBRICK, 0, 3);
		this.setBlock(x + 0, y + 11, z + 13, Blocks.STONEBRICK, 0, 3);
		this.setBlock(x + 11, y + 11, z + 13, Blocks.STONEBRICK, 0, 3);
		this.setBlock(x + 0, y + 11, z + 14, Blocks.STONEBRICK, 0, 3);
		this.setBlock(x + 11, y + 11, z + 14, Blocks.STONEBRICK, 0, 3);
		this.setBlock(x + 0, y + 11, z + 15, Blocks.STONEBRICK, 0, 3);
		this.setBlock(x + 11, y + 11, z + 15, Blocks.STONEBRICK, 0, 3);
		this.setBlock(x + 1, y + 11, z + 16, Blocks.STONEBRICK, 0, 3);
		this.setBlock(x + 10, y + 11, z + 16, Blocks.STONEBRICK, 0, 3);
		this.setBlock(x + 2, y + 11, z + 17, Blocks.STONEBRICK, 0, 3);
		this.setBlock(x + 3, y + 11, z + 17, Blocks.STAINED_GLASS, 0, 3);
		this.setBlock(x + 4, y + 11, z + 17, Blocks.STAINED_GLASS, 8, 3);
		this.setBlock(x + 5, y + 11, z + 17, Blocks.STAINED_GLASS, 15, 3);
		this.setBlock(x + 6, y + 11, z + 17, Blocks.STAINED_GLASS, 15, 3);
		this.setBlock(x + 7, y + 11, z + 17, Blocks.STAINED_GLASS, 8, 3);
		this.setBlock(x + 8, y + 11, z + 17, Blocks.STAINED_GLASS, 0, 3);
		this.setBlock(x + 9, y + 11, z + 17, Blocks.STONEBRICK, 0, 3);
		this.setBlock(x + 2, y + 12, z + 0, Blocks.STONEBRICK, 0, 3);
		this.setBlock(x + 3, y + 12, z + 0, Blocks.STAINED_GLASS, 0, 3);
		this.setBlock(x + 4, y + 12, z + 0, Blocks.STAINED_GLASS, 8, 3);
		this.setBlock(x + 5, y + 12, z + 0, Blocks.STAINED_GLASS, 7, 3);
		this.setBlock(x + 6, y + 12, z + 0, Blocks.STAINED_GLASS, 7, 3);
		this.setBlock(x + 7, y + 12, z + 0, Blocks.STAINED_GLASS, 8, 3);
		this.setBlock(x + 8, y + 12, z + 0, Blocks.STAINED_GLASS, 0, 3);
		this.setBlock(x + 9, y + 12, z + 0, Blocks.STONEBRICK, 0, 3);
		this.setBlock(x + 1, y + 12, z + 1, Blocks.STONEBRICK, 0, 3);
		this.setBlock(x + 10, y + 12, z + 1, Blocks.STONEBRICK, 0, 3);
		this.setBlock(x + 0, y + 12, z + 2, Blocks.STONEBRICK, 0, 3);
		this.setBlock(x + 11, y + 12, z + 2, Blocks.STONEBRICK, 0, 3);
		this.setBlock(x + 0, y + 12, z + 3, Blocks.STONEBRICK, 0, 3);
		this.setBlock(x + 11, y + 12, z + 3, Blocks.STONEBRICK, 0, 3);
		this.setBlock(x + 0, y + 12, z + 4, Blocks.STONEBRICK, 0, 3);
		this.setBlock(x + 11, y + 12, z + 4, Blocks.STONEBRICK, 0, 3);
		this.setBlock(x + 0, y + 12, z + 5, Blocks.STONEBRICK, 0, 3);
		this.setBlock(x + 11, y + 12, z + 5, Blocks.STONEBRICK, 0, 3);
		this.setBlock(x + 0, y + 12, z + 6, Blocks.STONEBRICK, 0, 3);
		this.setBlock(x + 11, y + 12, z + 6, Blocks.STONEBRICK, 0, 3);
		this.setBlock(x + 0, y + 12, z + 7, Blocks.STONEBRICK, 0, 3);
		this.setBlock(x + 11, y + 12, z + 7, Blocks.STONEBRICK, 0, 3);
		this.setBlock(x + 0, y + 12, z + 8, Blocks.STONEBRICK, 0, 3);
		this.setBlock(x + 11, y + 12, z + 8, Blocks.STONEBRICK, 0, 3);
		this.setBlock(x + 0, y + 12, z + 9, Blocks.STONEBRICK, 0, 3);
		this.setBlock(x + 11, y + 12, z + 9, Blocks.STONEBRICK, 0, 3);
		this.setBlock(x + 0, y + 12, z + 10, Blocks.STONEBRICK, 0, 3);
		this.setBlock(x + 11, y + 12, z + 10, Blocks.STONEBRICK, 0, 3);
		this.setBlock(x + 0, y + 12, z + 11, Blocks.STONEBRICK, 0, 3);
		this.setBlock(x + 11, y + 12, z + 11, Blocks.STONEBRICK, 0, 3);
		this.setBlock(x + 0, y + 12, z + 12, Blocks.STONEBRICK, 0, 3);
		this.setBlock(x + 11, y + 12, z + 12, Blocks.STONEBRICK, 0, 3);
		this.setBlock(x + 0, y + 12, z + 13, Blocks.STONEBRICK, 0, 3);
		this.setBlock(x + 11, y + 12, z + 13, Blocks.STONEBRICK, 0, 3);
		this.setBlock(x + 0, y + 12, z + 14, Blocks.STONEBRICK, 0, 3);
		this.setBlock(x + 11, y + 12, z + 14, Blocks.STONEBRICK, 0, 3);
		this.setBlock(x + 0, y + 12, z + 15, Blocks.STONEBRICK, 0, 3);
		this.setBlock(x + 11, y + 12, z + 15, Blocks.STONEBRICK, 0, 3);
		this.setBlock(x + 1, y + 12, z + 16, Blocks.STONEBRICK, 0, 3);
		this.setBlock(x + 10, y + 12, z + 16, Blocks.STONEBRICK, 0, 3);
		this.setBlock(x + 2, y + 12, z + 17, Blocks.STONEBRICK, 0, 3);
		this.setBlock(x + 3, y + 12, z + 17, Blocks.STAINED_GLASS, 14, 3);
		this.setBlock(x + 4, y + 12, z + 17, Blocks.STAINED_GLASS, 15, 3);
		this.setBlock(x + 5, y + 12, z + 17, Blocks.STAINED_GLASS, 8, 3);
		this.setBlock(x + 6, y + 12, z + 17, Blocks.STAINED_GLASS, 8, 3);
		this.setBlock(x + 7, y + 12, z + 17, Blocks.STAINED_GLASS, 15, 3);
		this.setBlock(x + 8, y + 12, z + 17, Blocks.STAINED_GLASS, 14, 3);
		this.setBlock(x + 9, y + 12, z + 17, Blocks.STONEBRICK, 0, 3);
		this.setBlock(x + 2, y + 13, z + 0, Blocks.STONEBRICK, 0, 3);
		this.setBlock(x + 3, y + 13, z + 0, Blocks.STAINED_GLASS, 0, 3);
		this.setBlock(x + 4, y + 13, z + 0, Blocks.STAINED_GLASS, 0, 3);
		this.setBlock(x + 5, y + 13, z + 0, Blocks.STAINED_GLASS, 8, 3);
		this.setBlock(x + 6, y + 13, z + 0, Blocks.STAINED_GLASS, 8, 3);
		this.setBlock(x + 7, y + 13, z + 0, Blocks.STAINED_GLASS, 0, 3);
		this.setBlock(x + 8, y + 13, z + 0, Blocks.STAINED_GLASS, 0, 3);
		this.setBlock(x + 9, y + 13, z + 0, Blocks.STONEBRICK, 0, 3);
		this.setBlock(x + 1, y + 13, z + 1, Blocks.STONEBRICK, 0, 3);
		this.setBlock(x + 10, y + 13, z + 1, Blocks.STONEBRICK, 0, 3);
		this.setBlock(x + 0, y + 13, z + 2, Blocks.STONEBRICK, 0, 3);
		this.setBlock(x + 11, y + 13, z + 2, Blocks.STONEBRICK, 0, 3);
		this.setBlock(x + 0, y + 13, z + 3, Blocks.STONEBRICK, 0, 3);
		this.setBlock(x + 11, y + 13, z + 3, Blocks.STONEBRICK, 0, 3);
		this.setBlock(x + 0, y + 13, z + 4, Blocks.STONEBRICK, 0, 3);
		this.setBlock(x + 11, y + 13, z + 4, Blocks.STONEBRICK, 0, 3);
		this.setBlock(x + 0, y + 13, z + 5, Blocks.STONEBRICK, 0, 3);
		this.setBlock(x + 11, y + 13, z + 5, Blocks.STONEBRICK, 0, 3);
		this.setBlock(x + 0, y + 13, z + 6, Blocks.STONEBRICK, 0, 3);
		this.setBlock(x + 11, y + 13, z + 6, Blocks.STONEBRICK, 0, 3);
		this.setBlock(x + 0, y + 13, z + 7, Blocks.STONEBRICK, 0, 3);
		this.setBlock(x + 11, y + 13, z + 7, Blocks.STONEBRICK, 0, 3);
		this.setBlock(x + 0, y + 13, z + 8, Blocks.STONEBRICK, 0, 3);
		this.setBlock(x + 11, y + 13, z + 8, Blocks.STONEBRICK, 0, 3);
		this.setBlock(x + 0, y + 13, z + 9, Blocks.STONEBRICK, 0, 3);
		this.setBlock(x + 11, y + 13, z + 9, Blocks.STONEBRICK, 0, 3);
		this.setBlock(x + 0, y + 13, z + 10, Blocks.STONEBRICK, 0, 3);
		this.setBlock(x + 11, y + 13, z + 10, Blocks.STONEBRICK, 0, 3);
		this.setBlock(x + 0, y + 13, z + 11, Blocks.STONEBRICK, 0, 3);
		this.setBlock(x + 11, y + 13, z + 11, Blocks.STONEBRICK, 0, 3);
		this.setBlock(x + 0, y + 13, z + 12, Blocks.STONEBRICK, 0, 3);
		this.setBlock(x + 11, y + 13, z + 12, Blocks.STONEBRICK, 0, 3);
		this.setBlock(x + 0, y + 13, z + 13, Blocks.STONEBRICK, 0, 3);
		this.setBlock(x + 11, y + 13, z + 13, Blocks.STONEBRICK, 0, 3);
		this.setBlock(x + 0, y + 13, z + 14, Blocks.STONEBRICK, 0, 3);
		this.setBlock(x + 11, y + 13, z + 14, Blocks.STONEBRICK, 0, 3);
		this.setBlock(x + 0, y + 13, z + 15, Blocks.STONEBRICK, 0, 3);
		this.setBlock(x + 11, y + 13, z + 15, Blocks.STONEBRICK, 0, 3);
		this.setBlock(x + 1, y + 13, z + 16, Blocks.STONEBRICK, 0, 3);
		this.setBlock(x + 10, y + 13, z + 16, Blocks.STONEBRICK, 0, 3);
		this.setBlock(x + 2, y + 13, z + 17, Blocks.STONEBRICK, 0, 3);
		this.setBlock(x + 3, y + 13, z + 17, Blocks.STONEBRICK, 0, 3);
		this.setBlock(x + 4, y + 13, z + 17, Blocks.STAINED_GLASS, 14, 3);
		this.setBlock(x + 5, y + 13, z + 17, Blocks.STAINED_GLASS, 0, 3);
		this.setBlock(x + 6, y + 13, z + 17, Blocks.STAINED_GLASS, 0, 3);
		this.setBlock(x + 7, y + 13, z + 17, Blocks.STAINED_GLASS, 14, 3);
		this.setBlock(x + 8, y + 13, z + 17, Blocks.STONEBRICK, 0, 3);
		this.setBlock(x + 9, y + 13, z + 17, Blocks.STONEBRICK, 0, 3);
		this.setBlock(x + 2, y + 14, z + 0, Blocks.STONEBRICK, 0, 3);
		this.setBlock(x + 3, y + 14, z + 0, Blocks.STAINED_GLASS, 14, 3);
		this.setBlock(x + 4, y + 14, z + 0, Blocks.STAINED_GLASS, 0, 3);
		this.setBlock(x + 5, y + 14, z + 0, Blocks.STAINED_GLASS, 0, 3);
		this.setBlock(x + 6, y + 14, z + 0, Blocks.STAINED_GLASS, 0, 3);
		this.setBlock(x + 7, y + 14, z + 0, Blocks.STAINED_GLASS, 0, 3);
		this.setBlock(x + 8, y + 14, z + 0, Blocks.STAINED_GLASS, 14, 3);
		this.setBlock(x + 9, y + 14, z + 0, Blocks.STONEBRICK, 0, 3);
		this.setBlock(x + 1, y + 14, z + 1, Blocks.STONEBRICK, 0, 3);
		this.setBlock(x + 10, y + 14, z + 1, Blocks.STONEBRICK, 0, 3);
		this.setBlock(x + 0, y + 14, z + 2, Blocks.STONEBRICK, 0, 3);
		this.setBlock(x + 11, y + 14, z + 2, Blocks.STONEBRICK, 0, 3);
		this.setBlock(x + 0, y + 14, z + 3, Blocks.STONEBRICK, 0, 3);
		this.setBlock(x + 11, y + 14, z + 3, Blocks.STONEBRICK, 0, 3);
		this.setBlock(x + 0, y + 14, z + 4, Blocks.STONEBRICK, 0, 3);
		this.setBlock(x + 11, y + 14, z + 4, Blocks.STONEBRICK, 0, 3);
		this.setBlock(x + 0, y + 14, z + 5, Blocks.STONEBRICK, 0, 3);
		this.setBlock(x + 11, y + 14, z + 5, Blocks.STONEBRICK, 0, 3);
		this.setBlock(x + 0, y + 14, z + 6, Blocks.STONEBRICK, 0, 3);
		this.setBlock(x + 11, y + 14, z + 6, Blocks.STONEBRICK, 0, 3);
		this.setBlock(x + 0, y + 14, z + 7, Blocks.STONEBRICK, 0, 3);
		this.setBlock(x + 11, y + 14, z + 7, Blocks.STONEBRICK, 0, 3);
		this.setBlock(x + 0, y + 14, z + 8, Blocks.STONEBRICK, 0, 3);
		this.setBlock(x + 11, y + 14, z + 8, Blocks.STONEBRICK, 0, 3);
		this.setBlock(x + 0, y + 14, z + 9, Blocks.STONEBRICK, 0, 3);
		this.setBlock(x + 11, y + 14, z + 9, Blocks.STONEBRICK, 0, 3);
		this.setBlock(x + 0, y + 14, z + 10, Blocks.STONEBRICK, 0, 3);
		this.setBlock(x + 11, y + 14, z + 10, Blocks.STONEBRICK, 0, 3);
		this.setBlock(x + 0, y + 14, z + 11, Blocks.STONEBRICK, 0, 3);
		this.setBlock(x + 11, y + 14, z + 11, Blocks.STONEBRICK, 0, 3);
		this.setBlock(x + 0, y + 14, z + 12, Blocks.STONEBRICK, 0, 3);
		this.setBlock(x + 11, y + 14, z + 12, Blocks.STONEBRICK, 0, 3);
		this.setBlock(x + 0, y + 14, z + 13, Blocks.STONEBRICK, 0, 3);
		this.setBlock(x + 11, y + 14, z + 13, Blocks.STONEBRICK, 0, 3);
		this.setBlock(x + 0, y + 14, z + 14, Blocks.STONEBRICK, 0, 3);
		this.setBlock(x + 11, y + 14, z + 14, Blocks.STONEBRICK, 0, 3);
		this.setBlock(x + 0, y + 14, z + 15, Blocks.STONEBRICK, 0, 3);
		this.setBlock(x + 11, y + 14, z + 15, Blocks.STONEBRICK, 0, 3);
		this.setBlock(x + 1, y + 14, z + 16, Blocks.STONEBRICK, 0, 3);
		this.setBlock(x + 10, y + 14, z + 16, Blocks.STONEBRICK, 0, 3);
		this.setBlock(x + 2, y + 14, z + 17, Blocks.STONEBRICK, 0, 3);
		this.setBlock(x + 3, y + 14, z + 17, Blocks.STONEBRICK, 0, 3);
		this.setBlock(x + 4, y + 14, z + 17, Blocks.STONEBRICK, 0, 3);
		this.setBlock(x + 5, y + 14, z + 17, Blocks.STONEBRICK, 0, 3);
		this.setBlock(x + 6, y + 14, z + 17, Blocks.STONEBRICK, 0, 3);
		this.setBlock(x + 7, y + 14, z + 17, Blocks.STONEBRICK, 0, 3);
		this.setBlock(x + 8, y + 14, z + 17, Blocks.STONEBRICK, 0, 3);
		this.setBlock(x + 9, y + 14, z + 17, Blocks.STONEBRICK, 0, 3);
		this.setBlock(x + 5, y + 14, z + 18, Blocks.STONEBRICK, 0, 3);
		this.setBlock(x + 6, y + 14, z + 18, Blocks.STONEBRICK, 0, 3);
		this.setBlock(x + 2, y + 15, z + 0, Blocks.STONEBRICK, 0, 3);
		this.setBlock(x + 3, y + 15, z + 0, Blocks.STONEBRICK, 0, 3);
		this.setBlock(x + 4, y + 15, z + 0, Blocks.STAINED_GLASS, 14, 3);
		this.setBlock(x + 5, y + 15, z + 0, Blocks.STAINED_GLASS, 0, 3);
		this.setBlock(x + 6, y + 15, z + 0, Blocks.STAINED_GLASS, 0, 3);
		this.setBlock(x + 7, y + 15, z + 0, Blocks.STAINED_GLASS, 14, 3);
		this.setBlock(x + 8, y + 15, z + 0, Blocks.STONEBRICK, 0, 3);
		this.setBlock(x + 9, y + 15, z + 0, Blocks.STONEBRICK, 0, 3);
		this.setBlock(x + 1, y + 15, z + 1, Blocks.STONEBRICK, 0, 3);
		this.setBlock(x + 10, y + 15, z + 1, Blocks.STONEBRICK, 0, 3);
		this.setBlock(x + 0, y + 15, z + 2, Blocks.STONEBRICK, 0, 3);
		this.setBlock(x + 11, y + 15, z + 2, Blocks.STONEBRICK, 0, 3);
		this.setBlock(x + 0, y + 15, z + 3, Blocks.STONEBRICK, 0, 3);
		this.setBlock(x + 11, y + 15, z + 3, Blocks.STONEBRICK, 0, 3);
		this.setBlock(x + 0, y + 15, z + 4, Blocks.STONEBRICK, 0, 3);
		this.setBlock(x + 11, y + 15, z + 4, Blocks.STONEBRICK, 0, 3);
		this.setBlock(x + 0, y + 15, z + 5, Blocks.STONEBRICK, 0, 3);
		this.setBlock(x + 11, y + 15, z + 5, Blocks.STONEBRICK, 0, 3);
		this.setBlock(x + 0, y + 15, z + 6, Blocks.STONEBRICK, 0, 3);
		this.setBlock(x + 11, y + 15, z + 6, Blocks.STONEBRICK, 0, 3);
		this.setBlock(x + 0, y + 15, z + 7, Blocks.STONEBRICK, 0, 3);
		this.setBlock(x + 11, y + 15, z + 7, Blocks.STONEBRICK, 0, 3);
		this.setBlock(x + 0, y + 15, z + 8, Blocks.STONEBRICK, 0, 3);
		this.setBlock(x + 11, y + 15, z + 8, Blocks.STONEBRICK, 0, 3);
		this.setBlock(x + 0, y + 15, z + 9, Blocks.STONEBRICK, 0, 3);
		this.setBlock(x + 11, y + 15, z + 9, Blocks.STONEBRICK, 0, 3);
		this.setBlock(x + 0, y + 15, z + 10, Blocks.STONEBRICK, 0, 3);
		this.setBlock(x + 11, y + 15, z + 10, Blocks.STONEBRICK, 0, 3);
		this.setBlock(x + 0, y + 15, z + 11, Blocks.STONEBRICK, 0, 3);
		this.setBlock(x + 11, y + 15, z + 11, Blocks.STONEBRICK, 0, 3);
		this.setBlock(x + 0, y + 15, z + 12, Blocks.STONEBRICK, 0, 3);
		this.setBlock(x + 11, y + 15, z + 12, Blocks.STONEBRICK, 0, 3);
		this.setBlock(x + 0, y + 15, z + 13, Blocks.STONEBRICK, 0, 3);
		this.setBlock(x + 11, y + 15, z + 13, Blocks.STONEBRICK, 0, 3);
		this.setBlock(x + 0, y + 15, z + 14, Blocks.STONEBRICK, 0, 3);
		this.setBlock(x + 11, y + 15, z + 14, Blocks.STONEBRICK, 0, 3);
		this.setBlock(x + 0, y + 15, z + 15, Blocks.STONEBRICK, 0, 3);
		this.setBlock(x + 11, y + 15, z + 15, Blocks.STONEBRICK, 0, 3);
		this.setBlock(x + 1, y + 15, z + 16, Blocks.STONEBRICK, 0, 3);
		this.setBlock(x + 10, y + 15, z + 16, Blocks.STONEBRICK, 0, 3);
		this.setBlock(x + 2, y + 15, z + 17, Blocks.STONEBRICK, 0, 3);
		this.setBlock(x + 3, y + 15, z + 17, Blocks.STONEBRICK, 0, 3);
		this.setBlock(x + 4, y + 15, z + 17, Blocks.STONEBRICK, 0, 3);
		this.setBlock(x + 5, y + 15, z + 17, Blocks.STONEBRICK, 0, 3);
		this.setBlock(x + 6, y + 15, z + 17, Blocks.STONEBRICK, 0, 3);
		this.setBlock(x + 7, y + 15, z + 17, Blocks.STONEBRICK, 0, 3);
		this.setBlock(x + 8, y + 15, z + 17, Blocks.STONEBRICK, 0, 3);
		this.setBlock(x + 9, y + 15, z + 17, Blocks.STONEBRICK, 0, 3);
		this.setBlock(x + 5, y + 15, z + 18, Blocks.STONEBRICK, 0, 3);
		this.setBlock(x + 6, y + 15, z + 18, Blocks.STONEBRICK, 0, 3);
		this.setBlock(x + 2, y + 16, z + 0, Blocks.STONEBRICK, 0, 3);
		this.setBlock(x + 3, y + 16, z + 0, Blocks.STONEBRICK, 0, 3);
		this.setBlock(x + 4, y + 16, z + 0, Blocks.STONEBRICK, 0, 3);
		this.setBlock(x + 5, y + 16, z + 0, Blocks.STONEBRICK, 0, 3);
		this.setBlock(x + 6, y + 16, z + 0, Blocks.STONEBRICK, 0, 3);
		this.setBlock(x + 7, y + 16, z + 0, Blocks.STONEBRICK, 0, 3);
		this.setBlock(x + 8, y + 16, z + 0, Blocks.STONEBRICK, 0, 3);
		this.setBlock(x + 9, y + 16, z + 0, Blocks.STONEBRICK, 0, 3);
		this.setBlock(x + 1, y + 16, z + 1, Blocks.STONEBRICK, 0, 3);
		this.setBlock(x + 2, y + 16, z + 1, Blocks.STONEBRICK, 0, 3);
		this.setBlock(x + 9, y + 16, z + 1, Blocks.STONEBRICK, 0, 3);
		this.setBlock(x + 10, y + 16, z + 1, Blocks.STONEBRICK, 0, 3);
		this.setBlock(x + 0, y + 16, z + 2, Blocks.STONEBRICK, 0, 3);
		this.setBlock(x + 1, y + 16, z + 2, Blocks.STONEBRICK, 0, 3);
		this.setBlock(x + 10, y + 16, z + 2, Blocks.STONEBRICK, 0, 3);
		this.setBlock(x + 11, y + 16, z + 2, Blocks.STONEBRICK, 0, 3);
		this.setBlock(x + 0, y + 16, z + 3, Blocks.STONEBRICK, 0, 3);
		this.setBlock(x + 11, y + 16, z + 3, Blocks.STONEBRICK, 0, 3);
		this.setBlock(x + 0, y + 16, z + 4, Blocks.STONEBRICK, 0, 3);
		this.setBlock(x + 11, y + 16, z + 4, Blocks.STONEBRICK, 0, 3);
		this.setBlock(x + 0, y + 16, z + 5, Blocks.STONEBRICK, 0, 3);
		this.setBlock(x + 11, y + 16, z + 5, Blocks.STONEBRICK, 0, 3);
		this.setBlock(x + 0, y + 16, z + 6, Blocks.STONEBRICK, 0, 3);
		this.setBlock(x + 11, y + 16, z + 6, Blocks.STONEBRICK, 0, 3);
		this.setBlock(x + 0, y + 16, z + 7, Blocks.STONEBRICK, 0, 3);
		this.setBlock(x + 11, y + 16, z + 7, Blocks.STONEBRICK, 0, 3);
		this.setBlock(x + 0, y + 16, z + 8, Blocks.STONEBRICK, 0, 3);
		this.setBlock(x + 11, y + 16, z + 8, Blocks.STONEBRICK, 0, 3);
		this.setBlock(x + 0, y + 16, z + 9, Blocks.STONEBRICK, 0, 3);
		this.setBlock(x + 11, y + 16, z + 9, Blocks.STONEBRICK, 0, 3);
		this.setBlock(x + 0, y + 16, z + 10, Blocks.STONEBRICK, 0, 3);
		this.setBlock(x + 11, y + 16, z + 10, Blocks.STONEBRICK, 0, 3);
		this.setBlock(x + 0, y + 16, z + 11, Blocks.STONEBRICK, 0, 3);
		this.setBlock(x + 11, y + 16, z + 11, Blocks.STONEBRICK, 0, 3);
		this.setBlock(x + 0, y + 16, z + 12, Blocks.STONEBRICK, 0, 3);
		this.setBlock(x + 11, y + 16, z + 12, Blocks.STONEBRICK, 0, 3);
		this.setBlock(x + 0, y + 16, z + 13, Blocks.STONEBRICK, 0, 3);
		this.setBlock(x + 11, y + 16, z + 13, Blocks.STONEBRICK, 0, 3);
		this.setBlock(x + 0, y + 16, z + 14, Blocks.STONEBRICK, 0, 3);
		this.setBlock(x + 11, y + 16, z + 14, Blocks.STONEBRICK, 0, 3);
		this.setBlock(x + 0, y + 16, z + 15, Blocks.STONEBRICK, 0, 3);
		this.setBlock(x + 11, y + 16, z + 15, Blocks.STONEBRICK, 0, 3);
		this.setBlock(x + 1, y + 16, z + 16, Blocks.STONEBRICK, 0, 3);
		this.setBlock(x + 10, y + 16, z + 16, Blocks.STONEBRICK, 0, 3);
		this.setBlock(x + 2, y + 16, z + 17, Blocks.STONEBRICK, 0, 3);
		this.setBlock(x + 3, y + 16, z + 17, Blocks.STONEBRICK, 0, 3);
		this.setBlock(x + 4, y + 16, z + 17, Blocks.CONCRETE, 7, 3);
		this.setBlock(x + 5, y + 16, z + 17, Blocks.STONEBRICK, 0, 3);
		this.setBlock(x + 6, y + 16, z + 17, Blocks.STONEBRICK, 0, 3);
		this.setBlock(x + 7, y + 16, z + 17, Blocks.CONCRETE, 7, 3);
		this.setBlock(x + 8, y + 16, z + 17, Blocks.STONEBRICK, 0, 3);
		this.setBlock(x + 9, y + 16, z + 17, Blocks.STONEBRICK, 0, 3);
		this.setBlock(x + 5, y + 16, z + 18, Blocks.STONEBRICK, 0, 3);
		this.setBlock(x + 6, y + 16, z + 18, Blocks.STONEBRICK, 0, 3);
		this.setBlock(x + 4, y + 17, z + 0, GBlocks.stoneperch, 0, 3);
		this.setBlock(x + 7, y + 17, z + 0, GBlocks.stoneperch, 0, 3);
		this.setBlock(x + 1, y + 17, z + 1, GBlocks.stoneperch, 0, 3);
		this.setBlock(x + 2, y + 17, z + 1, Blocks.STONEBRICK, 0, 3);
		this.setBlock(x + 3, y + 17, z + 1, Blocks.STONEBRICK, 0, 3);
		this.setBlock(x + 4, y + 17, z + 1, Blocks.STONEBRICK, 0, 3);
		this.setBlock(x + 5, y + 17, z + 1, Blocks.STONEBRICK, 0, 3);
		this.setBlock(x + 6, y + 17, z + 1, Blocks.STONEBRICK, 0, 3);
		this.setBlock(x + 7, y + 17, z + 1, Blocks.STONEBRICK, 0, 3);
		this.setBlock(x + 8, y + 17, z + 1, Blocks.STONEBRICK, 0, 3);
		this.setBlock(x + 9, y + 17, z + 1, Blocks.STONEBRICK, 0, 3);
		this.setBlock(x + 10, y + 17, z + 1, GBlocks.stoneperch, 0, 3);
		this.setBlock(x + 1, y + 17, z + 2, Blocks.STONEBRICK, 0, 3);
		this.setBlock(x + 2, y + 17, z + 2, Blocks.CONCRETE, 15, 3);
		this.setBlock(x + 3, y + 17, z + 2, Blocks.CONCRETE, 15, 3);
		this.setBlock(x + 4, y + 17, z + 2, Blocks.CONCRETE, 15, 3);
		this.setBlock(x + 5, y + 17, z + 2, Blocks.CONCRETE, 15, 3);
		this.setBlock(x + 6, y + 17, z + 2, Blocks.CONCRETE, 15, 3);
		this.setBlock(x + 7, y + 17, z + 2, Blocks.CONCRETE, 15, 3);
		this.setBlock(x + 8, y + 17, z + 2, Blocks.CONCRETE, 15, 3);
		this.setBlock(x + 9, y + 17, z + 2, Blocks.CONCRETE, 15, 3);
		this.setBlock(x + 10, y + 17, z + 2, Blocks.STONEBRICK, 0, 3);
		this.setBlock(x + 1, y + 17, z + 3, Blocks.STONEBRICK, 0, 3);
		this.setBlock(x + 2, y + 17, z + 3, Blocks.CONCRETE, 15, 3);
		this.setBlock(x + 3, y + 17, z + 3, Blocks.CONCRETE, 15, 3);
		this.setBlock(x + 4, y + 17, z + 3, Blocks.CONCRETE, 15, 3);
		this.setBlock(x + 5, y + 17, z + 3, Blocks.CONCRETE, 15, 3);
		this.setBlock(x + 6, y + 17, z + 3, Blocks.CONCRETE, 15, 3);
		this.setBlock(x + 7, y + 17, z + 3, Blocks.CONCRETE, 15, 3);
		this.setBlock(x + 8, y + 17, z + 3, Blocks.CONCRETE, 15, 3);
		this.setBlock(x + 9, y + 17, z + 3, Blocks.CONCRETE, 15, 3);
		this.setBlock(x + 10, y + 17, z + 3, Blocks.STONEBRICK, 0, 3);
		this.setBlock(x + 0, y + 17, z + 4, GBlocks.stoneperch, 0, 3);
		this.setBlock(x + 1, y + 17, z + 4, Blocks.STONEBRICK, 0, 3);
		this.setBlock(x + 2, y + 17, z + 4, Blocks.CONCRETE, 1, 3);
		this.setBlock(x + 3, y + 17, z + 4, Blocks.CONCRETE, 15, 3);
		this.setBlock(x + 4, y + 17, z + 4, Blocks.CONCRETE, 15, 3);
		this.setBlock(x + 5, y + 17, z + 4, Blocks.CONCRETE, 15, 3);
		this.setBlock(x + 6, y + 17, z + 4, Blocks.CONCRETE, 15, 3);
		this.setBlock(x + 7, y + 17, z + 4, Blocks.CONCRETE, 15, 3);
		this.setBlock(x + 8, y + 17, z + 4, Blocks.CONCRETE, 15, 3);
		this.setBlock(x + 9, y + 17, z + 4, Blocks.CONCRETE, 1, 3);
		this.setBlock(x + 10, y + 17, z + 4, Blocks.STONEBRICK, 0, 3);
		this.setBlock(x + 11, y + 17, z + 4, GBlocks.stoneperch, 0, 3);
		this.setBlock(x + 1, y + 17, z + 5, Blocks.STONEBRICK, 0, 3);
		this.setBlock(x + 2, y + 17, z + 5, Blocks.CONCRETE, 15, 3);
		this.setBlock(x + 3, y + 17, z + 5, Blocks.CONCRETE, 1, 3);
		this.setBlock(x + 4, y + 17, z + 5, Blocks.CONCRETE, 15, 3);
		this.setBlock(x + 5, y + 17, z + 5, Blocks.CONCRETE, 15, 3);
		this.setBlock(x + 6, y + 17, z + 5, Blocks.CONCRETE, 15, 3);
		this.setBlock(x + 7, y + 17, z + 5, Blocks.CONCRETE, 15, 3);
		this.setBlock(x + 8, y + 17, z + 5, Blocks.CONCRETE, 1, 3);
		this.setBlock(x + 9, y + 17, z + 5, Blocks.CONCRETE, 15, 3);
		this.setBlock(x + 10, y + 17, z + 5, Blocks.STONEBRICK, 0, 3);
		this.setBlock(x + 1, y + 17, z + 6, Blocks.STONEBRICK, 0, 3);
		this.setBlock(x + 2, y + 17, z + 6, Blocks.CONCRETE, 15, 3);
		this.setBlock(x + 3, y + 17, z + 6, Blocks.CONCRETE, 1, 3);
		this.setBlock(x + 4, y + 17, z + 6, Blocks.CONCRETE, 4, 3);
		this.setBlock(x + 5, y + 17, z + 6, Blocks.CONCRETE, 15, 3);
		this.setBlock(x + 6, y + 17, z + 6, Blocks.CONCRETE, 15, 3);
		this.setBlock(x + 7, y + 17, z + 6, Blocks.CONCRETE, 4, 3);
		this.setBlock(x + 8, y + 17, z + 6, Blocks.CONCRETE, 1, 3);
		this.setBlock(x + 9, y + 17, z + 6, Blocks.CONCRETE, 15, 3);
		this.setBlock(x + 10, y + 17, z + 6, Blocks.STONEBRICK, 0, 3);
		this.setBlock(x + 0, y + 17, z + 7, GBlocks.stoneperch, 0, 3);
		this.setBlock(x + 1, y + 17, z + 7, Blocks.STONEBRICK, 0, 3);
		this.setBlock(x + 2, y + 17, z + 7, Blocks.CONCRETE, 15, 3);
		this.setBlock(x + 3, y + 17, z + 7, Blocks.CONCRETE, 15, 3);
		this.setBlock(x + 4, y + 17, z + 7, Blocks.CONCRETE, 1, 3);
		this.setBlock(x + 5, y + 17, z + 7, Blocks.CONCRETE, 15, 3);
		this.setBlock(x + 6, y + 17, z + 7, Blocks.CONCRETE, 15, 3);
		this.setBlock(x + 7, y + 17, z + 7, Blocks.CONCRETE, 1, 3);
		this.setBlock(x + 8, y + 17, z + 7, Blocks.CONCRETE, 15, 3);
		this.setBlock(x + 9, y + 17, z + 7, Blocks.CONCRETE, 15, 3);
		this.setBlock(x + 10, y + 17, z + 7, Blocks.STONEBRICK, 0, 3);
		this.setBlock(x + 11, y + 17, z + 7, GBlocks.stoneperch, 0, 3);
		this.setBlock(x + 1, y + 17, z + 8, Blocks.STONEBRICK, 0, 3);
		this.setBlock(x + 2, y + 17, z + 8, Blocks.CONCRETE, 15, 3);
		this.setBlock(x + 3, y + 17, z + 8, Blocks.CONCRETE, 1, 3);
		this.setBlock(x + 4, y + 17, z + 8, Blocks.CONCRETE, 15, 3);
		this.setBlock(x + 5, y + 17, z + 8, Blocks.CONCRETE, 15, 3);
		this.setBlock(x + 6, y + 17, z + 8, Blocks.CONCRETE, 15, 3);
		this.setBlock(x + 7, y + 17, z + 8, Blocks.CONCRETE, 15, 3);
		this.setBlock(x + 8, y + 17, z + 8, Blocks.CONCRETE, 1, 3);
		this.setBlock(x + 9, y + 17, z + 8, Blocks.CONCRETE, 15, 3);
		this.setBlock(x + 10, y + 17, z + 8, Blocks.STONEBRICK, 0, 3);
		this.setBlock(x + 1, y + 17, z + 9, Blocks.STONEBRICK, 0, 3);
		this.setBlock(x + 2, y + 17, z + 9, Blocks.CONCRETE, 15, 3);
		this.setBlock(x + 3, y + 17, z + 9, Blocks.CONCRETE, 15, 3);
		this.setBlock(x + 4, y + 17, z + 9, Blocks.CONCRETE, 15, 3);
		this.setBlock(x + 5, y + 17, z + 9, Blocks.CONCRETE, 15, 3);
		this.setBlock(x + 6, y + 17, z + 9, Blocks.CONCRETE, 15, 3);
		this.setBlock(x + 7, y + 17, z + 9, Blocks.CONCRETE, 15, 3);
		this.setBlock(x + 8, y + 17, z + 9, Blocks.CONCRETE, 15, 3);
		this.setBlock(x + 9, y + 17, z + 9, Blocks.CONCRETE, 15, 3);
		this.setBlock(x + 10, y + 17, z + 9, Blocks.STONEBRICK, 0, 3);
		this.setBlock(x + 0, y + 17, z + 10, GBlocks.stoneperch, 0, 3);
		this.setBlock(x + 1, y + 17, z + 10, Blocks.STONEBRICK, 0, 3);
		this.setBlock(x + 2, y + 17, z + 10, Blocks.STONEBRICK, 0, 3);
		this.setBlock(x + 3, y + 17, z + 10, Blocks.STONEBRICK, 0, 3);
		this.setBlock(x + 4, y + 17, z + 10, Blocks.STONEBRICK, 0, 3);
		this.setBlock(x + 5, y + 17, z + 10, Blocks.STONEBRICK, 0, 3);
		this.setBlock(x + 6, y + 17, z + 10, Blocks.STONEBRICK, 0, 3);
		this.setBlock(x + 7, y + 17, z + 10, Blocks.STONEBRICK, 0, 3);
		this.setBlock(x + 8, y + 17, z + 10, Blocks.STONEBRICK, 0, 3);
		this.setBlock(x + 9, y + 17, z + 10, Blocks.STONEBRICK, 0, 3);
		this.setBlock(x + 10, y + 17, z + 10, Blocks.STONEBRICK, 0, 3);
		this.setBlock(x + 11, y + 17, z + 10, GBlocks.stoneperch, 0, 3);
