package net.endermanofdoom.necromancer;

import java.util.Random;
import net.minecraft.block.Block;
import net.minecraft.init.Biomes;
import net.minecraft.init.Blocks;
import net.minecraft.tileentity.TileEntity;
import net.minecraft.tileentity.TileEntityChest;
import net.minecraft.tileentity.TileEntityMobSpawner;
import net.minecraft.util.ResourceLocation;
import net.minecraft.util.math.BlockPos;
import net.minecraft.world.World;
import net.minecraft.world.gen.feature.WorldGenerator;
import net.minecraft.world.storage.loot.LootTableList;
import net.endermanofdoom.necromancer.entity.boss.EntityNecromancer;

public class WorldGenNecromancerTower extends WorldGenerator
{
	World world;
	
	public boolean generate(World world, Random rand, BlockPos pos)
	{
		this.world = world;
		
	    return generate_r0(world, rand, pos.getX(), pos.getY(), pos.getZ());
	}

	public boolean generate_r0(World world, Random rand, int x, int y, int z)
	{
		BlockPos pos = new BlockPos(x, y, z);
		
		y = world.getTopSolidOrLiquidBlock(pos).getY();
		
		x -= 5;
		z -= 5;
		
		if (world.getClosestPlayer(x, y, z, 100D, false) != null || world.getBlockState(pos).getMaterial().isLiquid() || world.getBiome(pos) == Biomes.OCEAN || world.getBiome(pos) == Biomes.DEEP_OCEAN || world.getBiome(pos) == Biomes.FROZEN_OCEAN || world.getBiome(pos) == Biomes.RIVER || world.getBiome(pos) == Biomes.FROZEN_RIVER)
			return false;
		--y;

		this.setBlock(x + 2, y + 0, z + 0, Blocks.STONEBRICK, 0, 3);
		this.setBlock(x + 3, y + 0, z + 0, Blocks.STONEBRICK, 0, 3);
		this.setBlock(x + 4, y + 0, z + 0, Blocks.STONEBRICK, 0, 3);
		this.setBlock(x + 5, y + 0, z + 0, Blocks.STONEBRICK, 0, 3);
		this.setBlock(x + 6, y + 0, z + 0, Blocks.STONEBRICK, 0, 3);
		this.setBlock(x + 7, y + 0, z + 0, Blocks.STONEBRICK, 0, 3);
		this.setBlock(x + 8, y + 0, z + 0, Blocks.STONEBRICK, 0, 3);
		this.setBlock(x + 1, y + 0, z + 1, Blocks.STONEBRICK, 0, 3);
		this.setBlock(x + 2, y + 0, z + 1, Blocks.STONEBRICK, 0, 3);
		this.setBlock(x + 3, y + 0, z + 1, Blocks.STONEBRICK, 0, 3);
		this.setBlock(x + 4, y + 0, z + 1, Blocks.STONEBRICK, 0, 3);
		this.setBlock(x + 5, y + 0, z + 1, Blocks.STONEBRICK, 0, 3);
		this.setBlock(x + 6, y + 0, z + 1, Blocks.STONEBRICK, 0, 3);
		this.setBlock(x + 7, y + 0, z + 1, Blocks.STONEBRICK, 0, 3);
		this.setBlock(x + 8, y + 0, z + 1, Blocks.STONEBRICK, 0, 3);
		this.setBlock(x + 9, y + 0, z + 1, Blocks.STONEBRICK, 0, 3);
		this.setBlock(x + 0, y + 0, z + 2, Blocks.STONEBRICK, 0, 3);
		this.setBlock(x + 1, y + 0, z + 2, Blocks.STONEBRICK, 0, 3);
		this.setBlock(x + 2, y + 0, z + 2, Blocks.STONEBRICK, 0, 3);
		this.setBlock(x + 3, y + 0, z + 2, Blocks.STONEBRICK, 0, 3);
		this.setBlock(x + 4, y + 0, z + 2, Blocks.STONEBRICK, 0, 3);
		this.setBlock(x + 5, y + 0, z + 2, Blocks.STONEBRICK, 0, 3);
		this.setBlock(x + 6, y + 0, z + 2, Blocks.STONEBRICK, 0, 3);
		this.setBlock(x + 7, y + 0, z + 2, Blocks.STONEBRICK, 0, 3);
		this.setBlock(x + 8, y + 0, z + 2, Blocks.STONEBRICK, 0, 3);
		this.setBlock(x + 9, y + 0, z + 2, Blocks.STONEBRICK, 0, 3);
		this.setBlock(x + 10, y + 0, z + 2, Blocks.STONEBRICK, 0, 3);
		this.setBlock(x + 0, y + 0, z + 3, Blocks.STONEBRICK, 0, 3);
		this.setBlock(x + 1, y + 0, z + 3, Blocks.STONEBRICK, 0, 3);
		this.setBlock(x + 2, y + 0, z + 3, Blocks.STONEBRICK, 0, 3);
		this.setBlock(x + 3, y + 0, z + 3, Blocks.STONEBRICK, 0, 3);
		this.setBlock(x + 4, y + 0, z + 3, Blocks.STONEBRICK, 0, 3);
		this.setBlock(x + 5, y + 0, z + 3, Blocks.STONEBRICK, 0, 3);
		this.setBlock(x + 6, y + 0, z + 3, Blocks.STONEBRICK, 0, 3);
		this.setBlock(x + 7, y + 0, z + 3, Blocks.STONEBRICK, 0, 3);
		this.setBlock(x + 8, y + 0, z + 3, Blocks.STONEBRICK, 0, 3);
		this.setBlock(x + 9, y + 0, z + 3, Blocks.STONEBRICK, 0, 3);
		this.setBlock(x + 10, y + 0, z + 3, Blocks.STONEBRICK, 0, 3);
		this.setBlock(x + 0, y + 0, z + 4, Blocks.STONEBRICK, 0, 3);
		this.setBlock(x + 1, y + 0, z + 4, Blocks.STONEBRICK, 0, 3);
		this.setBlock(x + 2, y + 0, z + 4, Blocks.STONEBRICK, 0, 3);
		this.setBlock(x + 3, y + 0, z + 4, Blocks.STONEBRICK, 0, 3);
		this.setBlock(x + 4, y + 0, z + 4, Blocks.STONEBRICK, 0, 3);
		this.setBlock(x + 5, y + 0, z + 4, Blocks.STONEBRICK, 0, 3);
		this.setBlock(x + 6, y + 0, z + 4, Blocks.STONEBRICK, 0, 3);
		this.setBlock(x + 7, y + 0, z + 4, Blocks.STONEBRICK, 0, 3);
		this.setBlock(x + 8, y + 0, z + 4, Blocks.STONEBRICK, 0, 3);
		this.setBlock(x + 9, y + 0, z + 4, Blocks.STONEBRICK, 0, 3);
		this.setBlock(x + 10, y + 0, z + 4, Blocks.STONEBRICK, 0, 3);
		this.setBlock(x + 0, y + 0, z + 5, Blocks.STONEBRICK, 0, 3);
		this.setBlock(x + 1, y + 0, z + 5, Blocks.STONEBRICK, 0, 3);
		this.setBlock(x + 2, y + 0, z + 5, Blocks.STONEBRICK, 0, 3);
		this.setBlock(x + 3, y + 0, z + 5, Blocks.STONEBRICK, 0, 3);
		this.setBlock(x + 4, y + 0, z + 5, Blocks.STONEBRICK, 0, 3);
		this.setBlock(x + 5, y + 0, z + 5, Blocks.STONEBRICK, 0, 3);
		this.setBlock(x + 6, y + 0, z + 5, Blocks.STONEBRICK, 0, 3);
		this.setBlock(x + 7, y + 0, z + 5, Blocks.STONEBRICK, 0, 3);
		this.setBlock(x + 8, y + 0, z + 5, Blocks.STONEBRICK, 0, 3);
		this.setBlock(x + 9, y + 0, z + 5, Blocks.STONEBRICK, 0, 3);
		this.setBlock(x + 10, y + 0, z + 5, Blocks.STONEBRICK, 0, 3);
		this.setBlock(x + 0, y + 0, z + 6, Blocks.STONEBRICK, 0, 3);
		this.setBlock(x + 1, y + 0, z + 6, Blocks.STONEBRICK, 0, 3);
		this.setBlock(x + 2, y + 0, z + 6, Blocks.STONEBRICK, 0, 3);
		this.setBlock(x + 3, y + 0, z + 6, Blocks.STONEBRICK, 0, 3);
		this.setBlock(x + 4, y + 0, z + 6, Blocks.STONEBRICK, 0, 3);
		this.setBlock(x + 5, y + 0, z + 6, Blocks.STONEBRICK, 0, 3);
		this.setBlock(x + 6, y + 0, z + 6, Blocks.STONEBRICK, 0, 3);
		this.setBlock(x + 7, y + 0, z + 6, Blocks.STONEBRICK, 0, 3);
		this.setBlock(x + 8, y + 0, z + 6, Blocks.STONEBRICK, 0, 3);
		this.setBlock(x + 9, y + 0, z + 6, Blocks.STONEBRICK, 0, 3);
		this.setBlock(x + 10, y + 0, z + 6, Blocks.STONEBRICK, 0, 3);
		this.setBlock(x + 0, y + 0, z + 7, Blocks.STONEBRICK, 0, 3);
		this.setBlock(x + 1, y + 0, z + 7, Blocks.STONEBRICK, 0, 3);
		this.setBlock(x + 2, y + 0, z + 7, Blocks.STONEBRICK, 0, 3);
		this.setBlock(x + 3, y + 0, z + 7, Blocks.STONEBRICK, 0, 3);
		this.setBlock(x + 4, y + 0, z + 7, Blocks.STONEBRICK, 0, 3);
		this.setBlock(x + 5, y + 0, z + 7, Blocks.STONEBRICK, 0, 3);
		this.setBlock(x + 6, y + 0, z + 7, Blocks.STONEBRICK, 0, 3);
		this.setBlock(x + 7, y + 0, z + 7, Blocks.STONEBRICK, 0, 3);
		this.setBlock(x + 8, y + 0, z + 7, Blocks.STONEBRICK, 0, 3);
		this.setBlock(x + 9, y + 0, z + 7, Blocks.STONEBRICK, 0, 3);
		this.setBlock(x + 10, y + 0, z + 7, Blocks.STONEBRICK, 0, 3);
		this.setBlock(x + 0, y + 0, z + 8, Blocks.STONEBRICK, 0, 3);
		this.setBlock(x + 1, y + 0, z + 8, Blocks.STONEBRICK, 0, 3);
		this.setBlock(x + 2, y + 0, z + 8, Blocks.STONEBRICK, 0, 3);
		this.setBlock(x + 3, y + 0, z + 8, Blocks.STONEBRICK, 0, 3);
		this.setBlock(x + 4, y + 0, z + 8, Blocks.STONEBRICK, 0, 3);
		this.setBlock(x + 5, y + 0, z + 8, Blocks.STONEBRICK, 0, 3);
		this.setBlock(x + 6, y + 0, z + 8, Blocks.STONEBRICK, 0, 3);
		this.setBlock(x + 7, y + 0, z + 8, Blocks.STONEBRICK, 0, 3);
		this.setBlock(x + 8, y + 0, z + 8, Blocks.STONEBRICK, 0, 3);
		this.setBlock(x + 9, y + 0, z + 8, Blocks.STONEBRICK, 0, 3);
		this.setBlock(x + 10, y + 0, z + 8, Blocks.STONEBRICK, 0, 3);
		this.setBlock(x + 1, y + 0, z + 9, Blocks.STONEBRICK, 0, 3);
		this.setBlock(x + 2, y + 0, z + 9, Blocks.STONEBRICK, 0, 3);
		this.setBlock(x + 3, y + 0, z + 9, Blocks.STONEBRICK, 0, 3);
		this.setBlock(x + 4, y + 0, z + 9, Blocks.STONEBRICK, 0, 3);
		this.setBlock(x + 5, y + 0, z + 9, Blocks.STONEBRICK, 0, 3);
		this.setBlock(x + 6, y + 0, z + 9, Blocks.STONEBRICK, 0, 3);
		this.setBlock(x + 7, y + 0, z + 9, Blocks.STONEBRICK, 0, 3);
		this.setBlock(x + 8, y + 0, z + 9, Blocks.STONEBRICK, 0, 3);
		this.setBlock(x + 9, y + 0, z + 9, Blocks.STONEBRICK, 0, 3);
		this.setBlock(x + 2, y + 0, z + 10, Blocks.STONEBRICK, 0, 3);
		this.setBlock(x + 3, y + 0, z + 10, Blocks.STONEBRICK, 0, 3);
		this.setBlock(x + 4, y + 0, z + 10, Blocks.STONEBRICK, 0, 3);
		this.setBlock(x + 5, y + 0, z + 10, Blocks.STONEBRICK, 0, 3);
		this.setBlock(x + 6, y + 0, z + 10, Blocks.STONEBRICK, 0, 3);
		this.setBlock(x + 7, y + 0, z + 10, Blocks.STONEBRICK, 0, 3);
		this.setBlock(x + 8, y + 0, z + 10, Blocks.STONEBRICK, 0, 3);
		this.setBlock(x + 2, y + 1, z + 0, Blocks.STONEBRICK, 0, 3);
		this.setBlock(x + 3, y + 1, z + 0, Blocks.STONEBRICK, 0, 3);
		this.setBlock(x + 4, y + 1, z + 0, Blocks.STONEBRICK, 0, 3);
		this.setBlock(x + 5, y + 1, z + 0, Blocks.STONEBRICK, 0, 3);
		this.setBlock(x + 6, y + 1, z + 0, Blocks.STONEBRICK, 0, 3);
		this.setBlock(x + 7, y + 1, z + 0, Blocks.STONEBRICK, 0, 3);
		this.setBlock(x + 8, y + 1, z + 0, Blocks.STONEBRICK, 0, 3);
		this.setBlock(x + 1, y + 1, z + 1, Blocks.STONEBRICK, 0, 3);
		this.setBlock(x + 2, y + 1, z + 1, Blocks.STONEBRICK, 0, 3);
		this.setBlock(x + 3, y + 1, z + 1, Blocks.STONEBRICK, 0, 3);
		this.setBlock(x + 4, y + 1, z + 1, Blocks.MOB_SPAWNER, 0, 3);
		this.setBlock(x + 5, y + 1, z + 1, Blocks.STONEBRICK, 0, 3);
		this.setBlock(x + 6, y + 1, z + 1, Blocks.STONE_BRICK_STAIRS, 1, 3);
		this.setBlock(x + 7, y + 1, z + 1, Blocks.AIR, 0, 3);
		this.setBlock(x + 8, y + 1, z + 1, Blocks.AIR, 0, 3);
		this.setBlock(x + 9, y + 1, z + 1, Blocks.STONEBRICK, 0, 3);
		this.setBlock(x + 0, y + 1, z + 2, Blocks.STONEBRICK, 0, 3);
		this.setBlock(x + 1, y + 1, z + 2, Blocks.STONEBRICK, 0, 3);
		this.setBlock(x + 2, y + 1, z + 2, Blocks.STONEBRICK, 0, 3);
		this.setBlock(x + 3, y + 1, z + 2, Blocks.STONEBRICK, 0, 3);
		this.setBlock(x + 4, y + 1, z + 2, Blocks.STONEBRICK, 0, 3);
		this.setBlock(x + 5, y + 1, z + 2, Blocks.STONEBRICK, 0, 3);
		this.setBlock(x + 6, y + 1, z + 2, Blocks.STONE_BRICK_STAIRS, 1, 3);
		this.setBlock(x + 7, y + 1, z + 2, Blocks.AIR, 0, 3);
		this.setBlock(x + 8, y + 1, z + 2, Blocks.AIR, 0, 3);
		this.setBlock(x + 9, y + 1, z + 2, Blocks.AIR, 0, 3);
		this.setBlock(x + 10, y + 1, z + 2, Blocks.STONEBRICK, 0, 3);
		this.setBlock(x + 0, y + 1, z + 3, Blocks.STONEBRICK, 0, 3);
		this.setBlock(x + 1, y + 1, z + 3, Blocks.CRAFTING_TABLE, 0, 3);
		this.setBlock(x + 2, y + 1, z + 3, Blocks.AIR, 0, 3);
		this.setBlock(x + 3, y + 1, z + 3, Blocks.AIR, 0, 3);
		this.setBlock(x + 4, y + 1, z + 3, Blocks.AIR, 0, 3);
		this.setBlock(x + 5, y + 1, z + 3, Blocks.AIR, 0, 3);
		this.setBlock(x + 6, y + 1, z + 3, Blocks.AIR, 0, 3);
		this.setBlock(x + 7, y + 1, z + 3, Blocks.AIR, 0, 3);
		this.setBlock(x + 8, y + 1, z + 3, Blocks.AIR, 0, 3);
		this.setBlock(x + 9, y + 1, z + 3, Blocks.AIR, 0, 3);
		this.setBlock(x + 10, y + 1, z + 3, Blocks.STONEBRICK, 0, 3);
		this.setBlock(x + 0, y + 1, z + 4, Blocks.STONEBRICK, 0, 3);
		this.setBlock(x + 1, y + 1, z + 4, Blocks.COBBLESTONE_WALL, 1, 3);
		this.setBlock(x + 2, y + 1, z + 4, Blocks.AIR, 0, 3);
		this.setBlock(x + 3, y + 1, z + 4, Blocks.AIR, 0, 3);
		this.setBlock(x + 4, y + 1, z + 4, Blocks.AIR, 0, 3);
		this.setBlock(x + 5, y + 1, z + 4, Blocks.AIR, 0, 3);
		this.setBlock(x + 6, y + 1, z + 4, Blocks.AIR, 0, 3);
		this.setBlock(x + 7, y + 1, z + 4, Blocks.AIR, 0, 3);
		this.setBlock(x + 8, y + 1, z + 4, Blocks.AIR, 0, 3);
		this.setBlock(x + 9, y + 1, z + 4, Blocks.AIR, 0, 3);
		this.setBlock(x + 10, y + 1, z + 4, Blocks.STONEBRICK, 0, 3);
		this.setBlock(x + 0, y + 1, z + 5, Blocks.STONEBRICK, 0, 3);
		this.setBlock(x + 1, y + 1, z + 5, Blocks.COBBLESTONE_WALL, 1, 3);
		this.setBlock(x + 2, y + 1, z + 5, Blocks.AIR, 0, 3);
		this.setBlock(x + 3, y + 1, z + 5, Blocks.AIR, 0, 3);
		this.setBlock(x + 4, y + 1, z + 5, Blocks.AIR, 0, 3);
		this.setBlock(x + 5, y + 1, z + 5, Blocks.AIR, 0, 3);
		this.setBlock(x + 6, y + 1, z + 5, Blocks.AIR, 0, 3);
		this.setBlock(x + 7, y + 1, z + 5, Blocks.AIR, 0, 3);
		this.setBlock(x + 8, y + 1, z + 5, Blocks.AIR, 0, 3);
		this.setBlock(x + 9, y + 1, z + 5, Blocks.AIR, 0, 3);
		this.setBlock(x + 10, y + 1, z + 5, Blocks.STONEBRICK, 0, 3);
		this.setBlock(x + 0, y + 1, z + 6, Blocks.STONEBRICK, 0, 3);
		this.setBlock(x + 1, y + 1, z + 6, Blocks.COBBLESTONE_WALL, 1, 3);
		this.setBlock(x + 2, y + 1, z + 6, Blocks.AIR, 0, 3);
		this.setBlock(x + 3, y + 1, z + 6, Blocks.AIR, 0, 3);
		this.setBlock(x + 4, y + 1, z + 6, Blocks.AIR, 0, 3);
		this.setBlock(x + 5, y + 1, z + 6, Blocks.AIR, 0, 3);
		this.setBlock(x + 6, y + 1, z + 6, Blocks.AIR, 0, 3);
		this.setBlock(x + 7, y + 1, z + 6, Blocks.AIR, 0, 3);
		this.setBlock(x + 8, y + 1, z + 6, Blocks.AIR, 0, 3);
		this.setBlock(x + 9, y + 1, z + 6, Blocks.AIR, 0, 3);
		this.setBlock(x + 10, y + 1, z + 6, Blocks.STONEBRICK, 0, 3);
		this.setBlock(x + 0, y + 1, z + 7, Blocks.STONEBRICK, 0, 3);
		this.setBlock(x + 1, y + 1, z + 7, Blocks.CHEST, 5, 3);
		this.setBlock(x + 2, y + 1, z + 7, Blocks.AIR, 0, 3);
		this.setBlock(x + 3, y + 1, z + 7, Blocks.AIR, 0, 3);
		this.setBlock(x + 4, y + 1, z + 7, Blocks.AIR, 0, 3);
		this.setBlock(x + 5, y + 1, z + 7, Blocks.AIR, 0, 3);
		this.setBlock(x + 6, y + 1, z + 7, Blocks.AIR, 0, 3);
		this.setBlock(x + 7, y + 1, z + 7, Blocks.AIR, 0, 3);
		this.setBlock(x + 8, y + 1, z + 7, Blocks.AIR, 0, 3);
		this.setBlock(x + 9, y + 1, z + 7, Blocks.AIR, 0, 3);
		this.setBlock(x + 10, y + 1, z + 7, Blocks.STONEBRICK, 0, 3);
		this.setBlock(x + 0, y + 1, z + 8, Blocks.STONEBRICK, 0, 3);
		this.setBlock(x + 1, y + 1, z + 8, Blocks.AIR, 0, 3);
		this.setBlock(x + 2, y + 1, z + 8, Blocks.AIR, 0, 3);
		this.setBlock(x + 3, y + 1, z + 8, Blocks.AIR, 0, 3);
		this.setBlock(x + 4, y + 1, z + 8, Blocks.AIR, 0, 3);
		this.setBlock(x + 5, y + 1, z + 8, Blocks.AIR, 0, 3);
		this.setBlock(x + 6, y + 1, z + 8, Blocks.AIR, 0, 3);
		this.setBlock(x + 7, y + 1, z + 8, Blocks.AIR, 0, 3);
		this.setBlock(x + 8, y + 1, z + 8, Blocks.AIR, 0, 3);
		this.setBlock(x + 9, y + 1, z + 8, Blocks.AIR, 0, 3);
		this.setBlock(x + 10, y + 1, z + 8, Blocks.STONEBRICK, 0, 3);
		this.setBlock(x + 1, y + 1, z + 9, Blocks.STONEBRICK, 0, 3);
		this.setBlock(x + 2, y + 1, z + 9, Blocks.AIR, 0, 3);
		this.setBlock(x + 3, y + 1, z + 9, Blocks.AIR, 0, 3);
		this.setBlock(x + 4, y + 1, z + 9, Blocks.AIR, 0, 3);
		this.setBlock(x + 5, y + 1, z + 9, Blocks.AIR, 0, 3);
		this.setBlock(x + 6, y + 1, z + 9, Blocks.AIR, 0, 3);
		this.setBlock(x + 7, y + 1, z + 9, Blocks.AIR, 0, 3);
		this.setBlock(x + 8, y + 1, z + 9, Blocks.CHEST, 2, 3);
		this.setBlock(x + 9, y + 1, z + 9, Blocks.STONEBRICK, 0, 3);
		this.setBlock(x + 2, y + 1, z + 10, Blocks.STONEBRICK, 0, 3);
		this.setBlock(x + 3, y + 1, z + 10, Blocks.STONEBRICK, 0, 3);
		this.setBlock(x + 4, y + 1, z + 10, Blocks.STONEBRICK, 0, 3);
		this.setBlock(x + 5, y + 1, z + 10, Blocks.AIR, 0, 3);
		this.setBlock(x + 6, y + 1, z + 10, Blocks.STONEBRICK, 0, 3);
		this.setBlock(x + 7, y + 1, z + 10, Blocks.STONEBRICK, 0, 3);
		this.setBlock(x + 8, y + 1, z + 10, Blocks.STONEBRICK, 0, 3);
		this.setBlock(x + 2, y + 2, z + 0, Blocks.STONEBRICK, 0, 3);
		this.setBlock(x + 3, y + 2, z + 0, Blocks.STONEBRICK, 0, 3);
		this.setBlock(x + 4, y + 2, z + 0, Blocks.STONEBRICK, 0, 3);
		this.setBlock(x + 5, y + 2, z + 0, Blocks.STONEBRICK, 0, 3);
		this.setBlock(x + 6, y + 2, z + 0, Blocks.STONEBRICK, 0, 3);
		this.setBlock(x + 7, y + 2, z + 0, Blocks.STONEBRICK, 0, 3);
		this.setBlock(x + 8, y + 2, z + 0, Blocks.STONEBRICK, 0, 3);
		this.setBlock(x + 1, y + 2, z + 1, Blocks.STONEBRICK, 0, 3);
		this.setBlock(x + 2, y + 2, z + 1, Blocks.STONEBRICK, 0, 3);
		this.setBlock(x + 3, y + 2, z + 1, Blocks.STONEBRICK, 0, 3);
		this.setBlock(x + 4, y + 2, z + 1, Blocks.STONEBRICK, 0, 3);
		this.setBlock(x + 5, y + 2, z + 1, Blocks.STONE_BRICK_STAIRS, 1, 3);
		this.setBlock(x + 6, y + 2, z + 1, Blocks.AIR, 0, 3);
		this.setBlock(x + 7, y + 2, z + 1, Blocks.AIR, 0, 3);
		this.setBlock(x + 8, y + 2, z + 1, Blocks.AIR, 0, 3);
		this.setBlock(x + 9, y + 2, z + 1, Blocks.STONEBRICK, 0, 3);
		this.setBlock(x + 0, y + 2, z + 2, Blocks.STONEBRICK, 0, 3);
		this.setBlock(x + 1, y + 2, z + 2, Blocks.STONEBRICK, 0, 3);
		this.setBlock(x + 2, y + 2, z + 2, Blocks.STONEBRICK, 0, 3);
		this.setBlock(x + 3, y + 2, z + 2, Blocks.STONEBRICK, 0, 3);
		this.setBlock(x + 4, y + 2, z + 2, Blocks.STONEBRICK, 0, 3);
		this.setBlock(x + 5, y + 2, z + 2, Blocks.STONE_BRICK_STAIRS, 1, 3);
		this.setBlock(x + 6, y + 2, z + 2, Blocks.AIR, 0, 3);
		this.setBlock(x + 7, y + 2, z + 2, Blocks.AIR, 0, 3);
		this.setBlock(x + 8, y + 2, z + 2, Blocks.AIR, 0, 3);
		this.setBlock(x + 9, y + 2, z + 2, Blocks.AIR, 0, 3);
		this.setBlock(x + 10, y + 2, z + 2, Blocks.STONEBRICK, 0, 3);
		this.setBlock(x + 0, y + 2, z + 3, Blocks.STONEBRICK, 0, 3);
		this.setBlock(x + 1, y + 2, z + 3, Blocks.AIR, 0, 3);
		this.setBlock(x + 2, y + 2, z + 3, Blocks.AIR, 0, 3);
		this.setBlock(x + 3, y + 2, z + 3, Blocks.AIR, 0, 3);
		this.setBlock(x + 4, y + 2, z + 3, Blocks.AIR, 0, 3);
		this.setBlock(x + 5, y + 2, z + 3, Blocks.AIR, 0, 3);
		this.setBlock(x + 6, y + 2, z + 3, Blocks.AIR, 0, 3);
		this.setBlock(x + 7, y + 2, z + 3, Blocks.AIR, 0, 3);
		this.setBlock(x + 8, y + 2, z + 3, Blocks.AIR, 0, 3);
		this.setBlock(x + 9, y + 2, z + 3, Blocks.AIR, 0, 3);
		this.setBlock(x + 10, y + 2, z + 3, Blocks.STONEBRICK, 0, 3);
		this.setBlock(x + 0, y + 2, z + 4, Blocks.STONEBRICK, 0, 3);
		this.setBlock(x + 1, y + 2, z + 4, Blocks.CARPET, 15, 3);
		this.setBlock(x + 2, y + 2, z + 4, Blocks.AIR, 0, 3);
		this.setBlock(x + 3, y + 2, z + 4, Blocks.AIR, 0, 3);
		this.setBlock(x + 4, y + 2, z + 4, Blocks.AIR, 0, 3);
		this.setBlock(x + 5, y + 2, z + 4, Blocks.AIR, 0, 3);
		this.setBlock(x + 6, y + 2, z + 4, Blocks.AIR, 0, 3);
		this.setBlock(x + 7, y + 2, z + 4, Blocks.AIR, 0, 3);
		this.setBlock(x + 8, y + 2, z + 4, Blocks.AIR, 0, 3);
		this.setBlock(x + 9, y + 2, z + 4, Blocks.AIR, 0, 3);
		this.setBlock(x + 10, y + 2, z + 4, Blocks.STONEBRICK, 0, 3);
		this.setBlock(x + 0, y + 2, z + 5, Blocks.STONEBRICK, 0, 3);
		this.setBlock(x + 1, y + 2, z + 5, Blocks.CARPET, 15, 3);
		this.setBlock(x + 2, y + 2, z + 5, Blocks.AIR, 0, 3);
		this.setBlock(x + 3, y + 2, z + 5, Blocks.AIR, 0, 3);
		this.setBlock(x + 4, y + 2, z + 5, Blocks.AIR, 0, 3);
		this.setBlock(x + 5, y + 2, z + 5, Blocks.AIR, 0, 3);
		this.setBlock(x + 6, y + 2, z + 5, Blocks.AIR, 0, 3);
		this.setBlock(x + 7, y + 2, z + 5, Blocks.AIR, 0, 3);
		this.setBlock(x + 8, y + 2, z + 5, Blocks.AIR, 0, 3);
		this.setBlock(x + 9, y + 2, z + 5, Blocks.AIR, 0, 3);
		this.setBlock(x + 10, y + 2, z + 5, Blocks.STONEBRICK, 0, 3);
		this.setBlock(x + 0, y + 2, z + 6, Blocks.STONEBRICK, 0, 3);
		this.setBlock(x + 1, y + 2, z + 6, Blocks.CARPET, 15, 3);
		this.setBlock(x + 2, y + 2, z + 6, Blocks.AIR, 0, 3);
		this.setBlock(x + 3, y + 2, z + 6, Blocks.AIR, 0, 3);
		this.setBlock(x + 4, y + 2, z + 6, Blocks.AIR, 0, 3);
		this.setBlock(x + 5, y + 2, z + 6, Blocks.AIR, 0, 3);
		this.setBlock(x + 6, y + 2, z + 6, Blocks.AIR, 0, 3);
		this.setBlock(x + 7, y + 2, z + 6, Blocks.AIR, 0, 3);
		this.setBlock(x + 8, y + 2, z + 6, Blocks.AIR, 0, 3);
		this.setBlock(x + 9, y + 2, z + 6, Blocks.AIR, 0, 3);
		this.setBlock(x + 10, y + 2, z + 6, Blocks.STONEBRICK, 0, 3);
		this.setBlock(x + 0, y + 2, z + 7, Blocks.STONEBRICK, 0, 3);
		this.setBlock(x + 1, y + 2, z + 7, Blocks.AIR, 0, 3);
		this.setBlock(x + 2, y + 2, z + 7, Blocks.AIR, 0, 3);
		this.setBlock(x + 3, y + 2, z + 7, Blocks.AIR, 0, 3);
		this.setBlock(x + 4, y + 2, z + 7, Blocks.AIR, 0, 3);
		this.setBlock(x + 5, y + 2, z + 7, Blocks.AIR, 0, 3);
		this.setBlock(x + 6, y + 2, z + 7, Blocks.AIR, 0, 3);
		this.setBlock(x + 7, y + 2, z + 7, Blocks.AIR, 0, 3);
		this.setBlock(x + 8, y + 2, z + 7, Blocks.AIR, 0, 3);
		this.setBlock(x + 9, y + 2, z + 7, Blocks.AIR, 0, 3);
		this.setBlock(x + 10, y + 2, z + 7, Blocks.STONEBRICK, 0, 3);
		this.setBlock(x + 0, y + 2, z + 8, Blocks.STONEBRICK, 0, 3);
		this.setBlock(x + 1, y + 2, z + 8, Blocks.AIR, 0, 3);
		this.setBlock(x + 2, y + 2, z + 8, Blocks.AIR, 0, 3);
		this.setBlock(x + 3, y + 2, z + 8, Blocks.AIR, 0, 3);
		this.setBlock(x + 4, y + 2, z + 8, Blocks.AIR, 0, 3);
		this.setBlock(x + 5, y + 2, z + 8, Blocks.AIR, 0, 3);
		this.setBlock(x + 6, y + 2, z + 8, Blocks.AIR, 0, 3);
		this.setBlock(x + 7, y + 2, z + 8, Blocks.AIR, 0, 3);
		this.setBlock(x + 8, y + 2, z + 8, Blocks.AIR, 0, 3);
		this.setBlock(x + 9, y + 2, z + 8, Blocks.AIR, 0, 3);
		this.setBlock(x + 10, y + 2, z + 8, Blocks.STONEBRICK, 0, 3);
		this.setBlock(x + 1, y + 2, z + 9, Blocks.STONEBRICK, 0, 3);
		this.setBlock(x + 2, y + 2, z + 9, Blocks.AIR, 0, 3);
		this.setBlock(x + 3, y + 2, z + 9, Blocks.AIR, 0, 3);
		this.setBlock(x + 4, y + 2, z + 9, Blocks.AIR, 0, 3);
		this.setBlock(x + 5, y + 2, z + 9, Blocks.AIR, 0, 3);
		this.setBlock(x + 6, y + 2, z + 9, Blocks.AIR, 0, 3);
		this.setBlock(x + 7, y + 2, z + 9, Blocks.AIR, 0, 3);
		this.setBlock(x + 8, y + 2, z + 9, Blocks.AIR, 0, 3);
		this.setBlock(x + 9, y + 2, z + 9, Blocks.STONEBRICK, 0, 3);
		this.setBlock(x + 2, y + 2, z + 10, Blocks.STONEBRICK, 0, 3);
		this.setBlock(x + 3, y + 2, z + 10, Blocks.STONE_SLAB, 5, 3);
		this.setBlock(x + 4, y + 2, z + 10, Blocks.STONEBRICK, 0, 3);
		this.setBlock(x + 5, y + 2, z + 10, Blocks.AIR, 0, 3);
		this.setBlock(x + 6, y + 2, z + 10, Blocks.STONEBRICK, 0, 3);
		this.setBlock(x + 7, y + 2, z + 10, Blocks.STONE_SLAB, 5, 3);
		this.setBlock(x + 8, y + 2, z + 10, Blocks.STONEBRICK, 0, 3);
		this.setBlock(x + 2, y + 3, z + 0, Blocks.STONEBRICK, 0, 3);
		this.setBlock(x + 3, y + 3, z + 0, Blocks.STONEBRICK, 0, 3);
		this.setBlock(x + 4, y + 3, z + 0, Blocks.STONEBRICK, 0, 3);
		this.setBlock(x + 5, y + 3, z + 0, Blocks.STONEBRICK, 0, 3);
		this.setBlock(x + 6, y + 3, z + 0, Blocks.STONEBRICK, 0, 3);
		this.setBlock(x + 7, y + 3, z + 0, Blocks.STONEBRICK, 0, 3);
		this.setBlock(x + 8, y + 3, z + 0, Blocks.STONEBRICK, 0, 3);
		this.setBlock(x + 1, y + 3, z + 1, Blocks.STONEBRICK, 0, 3);
		this.setBlock(x + 2, y + 3, z + 1, Blocks.STONEBRICK, 0, 3);
		this.setBlock(x + 3, y + 3, z + 1, Blocks.STONEBRICK, 0, 3);
		this.setBlock(x + 4, y + 3, z + 1, Blocks.STONE_BRICK_STAIRS, 1, 3);
		this.setBlock(x + 5, y + 3, z + 1, Blocks.AIR, 0, 3);
		this.setBlock(x + 6, y + 3, z + 1, Blocks.AIR, 0, 3);
		this.setBlock(x + 7, y + 3, z + 1, Blocks.AIR, 0, 3);
		this.setBlock(x + 8, y + 3, z + 1, Blocks.AIR, 0, 3);
		this.setBlock(x + 9, y + 3, z + 1, Blocks.STONEBRICK, 0, 3);
		this.setBlock(x + 0, y + 3, z + 2, Blocks.STONEBRICK, 0, 3);
		this.setBlock(x + 1, y + 3, z + 2, Blocks.STONEBRICK, 0, 3);
		this.setBlock(x + 2, y + 3, z + 2, Blocks.STONEBRICK, 0, 3);
		this.setBlock(x + 3, y + 3, z + 2, Blocks.STONEBRICK, 0, 3);
		this.setBlock(x + 4, y + 3, z + 2, Blocks.STONE_BRICK_STAIRS, 1, 3);
		this.setBlock(x + 5, y + 3, z + 2, Blocks.AIR, 0, 3);
		this.setBlock(x + 6, y + 3, z + 2, Blocks.AIR, 0, 3);
		this.setBlock(x + 7, y + 3, z + 2, Blocks.AIR, 0, 3);
		this.setBlock(x + 8, y + 3, z + 2, Blocks.AIR, 0, 3);
		this.setBlock(x + 9, y + 3, z + 2, Blocks.AIR, 0, 3);
		this.setBlock(x + 10, y + 3, z + 2, Blocks.STONEBRICK, 0, 3);
		this.setBlock(x + 0, y + 3, z + 3, Blocks.STONEBRICK, 0, 3);
		this.setBlock(x + 1, y + 3, z + 3, Blocks.STONE_BRICK_STAIRS, 7, 3);
		this.setBlock(x + 2, y + 3, z + 3, Blocks.STONE_BRICK_STAIRS, 7, 3);
		this.setBlock(x + 3, y + 3, z + 3, Blocks.AIR, 0, 3);
		this.setBlock(x + 4, y + 3, z + 3, Blocks.AIR, 0, 3);
		this.setBlock(x + 5, y + 3, z + 3, Blocks.AIR, 0, 3);
		this.setBlock(x + 6, y + 3, z + 3, Blocks.AIR, 0, 3);
		this.setBlock(x + 7, y + 3, z + 3, Blocks.AIR, 0, 3);
		this.setBlock(x + 8, y + 3, z + 3, Blocks.AIR, 0, 3);
		this.setBlock(x + 9, y + 3, z + 3, Blocks.AIR, 0, 3);
		this.setBlock(x + 10, y + 3, z + 3, Blocks.STONEBRICK, 0, 3);
		this.setBlock(x + 0, y + 3, z + 4, Blocks.STONEBRICK, 0, 3);
		this.setBlock(x + 1, y + 3, z + 4, Blocks.AIR, 0, 3);
		this.setBlock(x + 2, y + 3, z + 4, Blocks.AIR, 0, 3);
		this.setBlock(x + 3, y + 3, z + 4, Blocks.AIR, 0, 3);
		this.setBlock(x + 4, y + 3, z + 4, Blocks.AIR, 0, 3);
		this.setBlock(x + 5, y + 3, z + 4, Blocks.AIR, 0, 3);
		this.setBlock(x + 6, y + 3, z + 4, Blocks.AIR, 0, 3);
		this.setBlock(x + 7, y + 3, z + 4, Blocks.AIR, 0, 3);
		this.setBlock(x + 8, y + 3, z + 4, Blocks.AIR, 0, 3);
		this.setBlock(x + 9, y + 3, z + 4, Blocks.AIR, 0, 3);
		this.setBlock(x + 10, y + 3, z + 4, Blocks.STONEBRICK, 0, 3);
		this.setBlock(x + 0, y + 3, z + 5, Blocks.STONEBRICK, 0, 3);
		this.setBlock(x + 1, y + 3, z + 5, Blocks.AIR, 0, 3);
		this.setBlock(x + 2, y + 3, z + 5, Blocks.AIR, 0, 3);
		this.setBlock(x + 3, y + 3, z + 5, Blocks.AIR, 0, 3);
		this.setBlock(x + 4, y + 3, z + 5, Blocks.AIR, 0, 3);
		this.setBlock(x + 5, y + 3, z + 5, Blocks.AIR, 0, 3);
		this.setBlock(x + 6, y + 3, z + 5, Blocks.AIR, 0, 3);
		this.setBlock(x + 7, y + 3, z + 5, Blocks.AIR, 0, 3);
		this.setBlock(x + 8, y + 3, z + 5, Blocks.AIR, 0, 3);
		this.setBlock(x + 9, y + 3, z + 5, Blocks.AIR, 0, 3);
		this.setBlock(x + 10, y + 3, z + 5, Blocks.STONEBRICK, 0, 3);
		this.setBlock(x + 0, y + 3, z + 6, Blocks.STONEBRICK, 0, 3);
		this.setBlock(x + 1, y + 3, z + 6, Blocks.AIR, 0, 3);
		this.setBlock(x + 2, y + 3, z + 6, Blocks.AIR, 0, 3);
		this.setBlock(x + 3, y + 3, z + 6, Blocks.AIR, 0, 3);
		this.setBlock(x + 4, y + 3, z + 6, Blocks.AIR, 0, 3);
		this.setBlock(x + 5, y + 3, z + 6, Blocks.AIR, 0, 3);
		this.setBlock(x + 6, y + 3, z + 6, Blocks.AIR, 0, 3);
		this.setBlock(x + 7, y + 3, z + 6, Blocks.AIR, 0, 3);
		this.setBlock(x + 8, y + 3, z + 6, Blocks.AIR, 0, 3);
		this.setBlock(x + 9, y + 3, z + 6, Blocks.AIR, 0, 3);
		this.setBlock(x + 10, y + 3, z + 6, Blocks.STONEBRICK, 0, 3);
		this.setBlock(x + 0, y + 3, z + 7, Blocks.STONEBRICK, 0, 3);
		this.setBlock(x + 1, y + 3, z + 7, Blocks.AIR, 0, 3);
		this.setBlock(x + 2, y + 3, z + 7, Blocks.AIR, 0, 3);
		this.setBlock(x + 3, y + 3, z + 7, Blocks.AIR, 0, 3);
		this.setBlock(x + 4, y + 3, z + 7, Blocks.AIR, 0, 3);
		this.setBlock(x + 5, y + 3, z + 7, Blocks.AIR, 0, 3);
		this.setBlock(x + 6, y + 3, z + 7, Blocks.AIR, 0, 3);
		this.setBlock(x + 7, y + 3, z + 7, Blocks.AIR, 0, 3);
		this.setBlock(x + 8, y + 3, z + 7, Blocks.AIR, 0, 3);
		this.setBlock(x + 9, y + 3, z + 7, Blocks.AIR, 0, 3);
		this.setBlock(x + 10, y + 3, z + 7, Blocks.STONEBRICK, 0, 3);
		this.setBlock(x + 0, y + 3, z + 8, Blocks.STONEBRICK, 0, 3);
		this.setBlock(x + 1, y + 3, z + 8, Blocks.AIR, 0, 3);
		this.setBlock(x + 2, y + 3, z + 8, Blocks.AIR, 0, 3);
		this.setBlock(x + 3, y + 3, z + 8, Blocks.AIR, 0, 3);
		this.setBlock(x + 4, y + 3, z + 8, Blocks.AIR, 0, 3);
		this.setBlock(x + 5, y + 3, z + 8, Blocks.AIR, 0, 3);
		this.setBlock(x + 6, y + 3, z + 8, Blocks.AIR, 0, 3);
		this.setBlock(x + 7, y + 3, z + 8, Blocks.AIR, 0, 3);
		this.setBlock(x + 8, y + 3, z + 8, Blocks.AIR, 0, 3);
		this.setBlock(x + 9, y + 3, z + 8, Blocks.AIR, 0, 3);
		this.setBlock(x + 10, y + 3, z + 8, Blocks.STONEBRICK, 0, 3);
		this.setBlock(x + 1, y + 3, z + 9, Blocks.STONEBRICK, 0, 3);
		this.setBlock(x + 2, y + 3, z + 9, Blocks.AIR, 0, 3);
		this.setBlock(x + 3, y + 3, z + 9, Blocks.AIR, 0, 3);
		this.setBlock(x + 4, y + 3, z + 9, Blocks.AIR, 0, 3);
		this.setBlock(x + 5, y + 3, z + 9, Blocks.AIR, 0, 3);
		this.setBlock(x + 6, y + 3, z + 9, Blocks.AIR, 0, 3);
		this.setBlock(x + 7, y + 3, z + 9, Blocks.AIR, 0, 3);
		this.setBlock(x + 8, y + 3, z + 9, Blocks.AIR, 0, 3);
		this.setBlock(x + 9, y + 3, z + 9, Blocks.STONEBRICK, 0, 3);
		this.setBlock(x + 2, y + 3, z + 10, Blocks.STONEBRICK, 0, 3);
		this.setBlock(x + 3, y + 3, z + 10, Blocks.STONE_SLAB, 13, 3);
		this.setBlock(x + 4, y + 3, z + 10, Blocks.STONEBRICK, 0, 3);
		this.setBlock(x + 5, y + 3, z + 10, Blocks.STONEBRICK, 0, 3);
		this.setBlock(x + 6, y + 3, z + 10, Blocks.STONEBRICK, 0, 3);
		this.setBlock(x + 7, y + 3, z + 10, Blocks.STONE_SLAB, 13, 3);
		this.setBlock(x + 8, y + 3, z + 10, Blocks.STONEBRICK, 0, 3);
		this.setBlock(x + 2, y + 4, z + 0, Blocks.STONEBRICK, 0, 3);
		this.setBlock(x + 3, y + 4, z + 0, Blocks.STONEBRICK, 0, 3);
		this.setBlock(x + 4, y + 4, z + 0, Blocks.STONEBRICK, 0, 3);
		this.setBlock(x + 5, y + 4, z + 0, Blocks.STONE_SLAB, 5, 3);
		this.setBlock(x + 6, y + 4, z + 0, Blocks.STONEBRICK, 0, 3);
		this.setBlock(x + 7, y + 4, z + 0, Blocks.STONEBRICK, 0, 3);
		this.setBlock(x + 8, y + 4, z + 0, Blocks.STONEBRICK, 0, 3);
		this.setBlock(x + 1, y + 4, z + 1, Blocks.STONEBRICK, 0, 3);
		this.setBlock(x + 2, y + 4, z + 1, Blocks.STONEBRICK, 0, 3);
		this.setBlock(x + 3, y + 4, z + 1, Blocks.STONE_BRICK_STAIRS, 1, 3);
		this.setBlock(x + 4, y + 4, z + 1, Blocks.AIR, 0, 3);
		this.setBlock(x + 5, y + 4, z + 1, Blocks.AIR, 0, 3);
		this.setBlock(x + 6, y + 4, z + 1, Blocks.AIR, 0, 3);
		this.setBlock(x + 7, y + 4, z + 1, Blocks.AIR, 0, 3);
		this.setBlock(x + 8, y + 4, z + 1, Blocks.AIR, 0, 3);
		this.setBlock(x + 9, y + 4, z + 1, Blocks.STONEBRICK, 0, 3);
		this.setBlock(x + 0, y + 4, z + 2, Blocks.STONEBRICK, 0, 3);
		this.setBlock(x + 1, y + 4, z + 2, Blocks.STONEBRICK, 0, 3);
		this.setBlock(x + 2, y + 4, z + 2, Blocks.STONEBRICK, 0, 3);
		this.setBlock(x + 3, y + 4, z + 2, Blocks.STONE_BRICK_STAIRS, 1, 3);
		this.setBlock(x + 4, y + 4, z + 2, Blocks.AIR, 0, 3);
		this.setBlock(x + 5, y + 4, z + 2, Blocks.AIR, 0, 3);
		this.setBlock(x + 6, y + 4, z + 2, Blocks.AIR, 0, 3);
		this.setBlock(x + 7, y + 4, z + 2, Blocks.AIR, 0, 3);
		this.setBlock(x + 8, y + 4, z + 2, Blocks.AIR, 0, 3);
		this.setBlock(x + 9, y + 4, z + 2, Blocks.AIR, 0, 3);
		this.setBlock(x + 10, y + 4, z + 2, Blocks.STONEBRICK, 0, 3);
		this.setBlock(x + 0, y + 4, z + 3, Blocks.STONEBRICK, 0, 3);
		this.setBlock(x + 1, y + 4, z + 3, Blocks.STONEBRICK, 0, 3);
		this.setBlock(x + 2, y + 4, z + 3, Blocks.STONEBRICK, 0, 3);
		this.setBlock(x + 3, y + 4, z + 3, Blocks.AIR, 0, 3);
		this.setBlock(x + 4, y + 4, z + 3, Blocks.AIR, 0, 3);
		this.setBlock(x + 5, y + 4, z + 3, Blocks.AIR, 0, 3);
		this.setBlock(x + 6, y + 4, z + 3, Blocks.AIR, 0, 3);
		this.setBlock(x + 7, y + 4, z + 3, Blocks.AIR, 0, 3);
		this.setBlock(x + 8, y + 4, z + 3, Blocks.AIR, 0, 3);
		this.setBlock(x + 9, y + 4, z + 3, Blocks.AIR, 0, 3);
		this.setBlock(x + 10, y + 4, z + 3, Blocks.STONEBRICK, 0, 3);
		this.setBlock(x + 0, y + 4, z + 4, Blocks.STONEBRICK, 0, 3);
		this.setBlock(x + 1, y + 4, z + 4, Blocks.STONE_BRICK_STAIRS, 7, 3);
		this.setBlock(x + 2, y + 4, z + 4, Blocks.STONE_BRICK_STAIRS, 7, 3);
		this.setBlock(x + 3, y + 4, z + 4, Blocks.AIR, 0, 3);
		this.setBlock(x + 4, y + 4, z + 4, Blocks.AIR, 0, 3);
		this.setBlock(x + 5, y + 4, z + 4, Blocks.AIR, 0, 3);
		this.setBlock(x + 6, y + 4, z + 4, Blocks.AIR, 0, 3);
		this.setBlock(x + 7, y + 4, z + 4, Blocks.AIR, 0, 3);
		this.setBlock(x + 8, y + 4, z + 4, Blocks.AIR, 0, 3);
		this.setBlock(x + 9, y + 4, z + 4, Blocks.AIR, 0, 3);
		this.setBlock(x + 10, y + 4, z + 4, Blocks.STONEBRICK, 0, 3);
		this.setBlock(x + 0, y + 4, z + 5, Blocks.STONEBRICK, 0, 3);
		this.setBlock(x + 1, y + 4, z + 5, Blocks.AIR, 0, 3);
		this.setBlock(x + 2, y + 4, z + 5, Blocks.AIR, 0, 3);
		this.setBlock(x + 3, y + 4, z + 5, Blocks.AIR, 0, 3);
		this.setBlock(x + 4, y + 4, z + 5, Blocks.AIR, 0, 3);
		this.setBlock(x + 5, y + 4, z + 5, Blocks.AIR, 0, 3);
		this.setBlock(x + 6, y + 4, z + 5, Blocks.AIR, 0, 3);
		this.setBlock(x + 7, y + 4, z + 5, Blocks.AIR, 0, 3);
		this.setBlock(x + 8, y + 4, z + 5, Blocks.AIR, 0, 3);
		this.setBlock(x + 9, y + 4, z + 5, Blocks.AIR, 0, 3);
		this.setBlock(x + 10, y + 4, z + 5, Blocks.STONEBRICK, 0, 3);
		this.setBlock(x + 0, y + 4, z + 6, Blocks.STONEBRICK, 0, 3);
		this.setBlock(x + 1, y + 4, z + 6, Blocks.AIR, 0, 3);
		this.setBlock(x + 2, y + 4, z + 6, Blocks.AIR, 0, 3);
		this.setBlock(x + 3, y + 4, z + 6, Blocks.AIR, 0, 3);
		this.setBlock(x + 4, y + 4, z + 6, Blocks.AIR, 0, 3);
		this.setBlock(x + 5, y + 4, z + 6, Blocks.AIR, 0, 3);
		this.setBlock(x + 6, y + 4, z + 6, Blocks.AIR, 0, 3);
		this.setBlock(x + 7, y + 4, z + 6, Blocks.AIR, 0, 3);
		this.setBlock(x + 8, y + 4, z + 6, Blocks.AIR, 0, 3);
		this.setBlock(x + 9, y + 4, z + 6, Blocks.AIR, 0, 3);
		this.setBlock(x + 10, y + 4, z + 6, Blocks.STONEBRICK, 0, 3);
		this.setBlock(x + 0, y + 4, z + 7, Blocks.STONEBRICK, 0, 3);
		this.setBlock(x + 1, y + 4, z + 7, Blocks.AIR, 0, 3);
		this.setBlock(x + 2, y + 4, z + 7, Blocks.AIR, 0, 3);
		this.setBlock(x + 3, y + 4, z + 7, Blocks.AIR, 0, 3);
		this.setBlock(x + 4, y + 4, z + 7, Blocks.AIR, 0, 3);
		this.setBlock(x + 5, y + 4, z + 7, Blocks.AIR, 0, 3);
		this.setBlock(x + 6, y + 4, z + 7, Blocks.AIR, 0, 3);
		this.setBlock(x + 7, y + 4, z + 7, Blocks.AIR, 0, 3);
		this.setBlock(x + 8, y + 4, z + 7, Blocks.AIR, 0, 3);
		this.setBlock(x + 9, y + 4, z + 7, Blocks.AIR, 0, 3);
		this.setBlock(x + 10, y + 4, z + 7, Blocks.STONEBRICK, 0, 3);
		this.setBlock(x + 0, y + 4, z + 8, Blocks.STONEBRICK, 0, 3);
		this.setBlock(x + 1, y + 4, z + 8, Blocks.AIR, 0, 3);
		this.setBlock(x + 2, y + 4, z + 8, Blocks.AIR, 0, 3);
		this.setBlock(x + 3, y + 4, z + 8, Blocks.MOB_SPAWNER, 0, 3);
		this.setBlock(x + 4, y + 4, z + 8, Blocks.AIR, 0, 3);
		this.setBlock(x + 5, y + 4, z + 8, Blocks.AIR, 0, 3);
		this.setBlock(x + 6, y + 4, z + 8, Blocks.AIR, 0, 3);
		this.setBlock(x + 7, y + 4, z + 8, Blocks.AIR, 0, 3);
		this.setBlock(x + 8, y + 4, z + 8, Blocks.AIR, 0, 3);
		this.setBlock(x + 9, y + 4, z + 8, Blocks.AIR, 0, 3);
		this.setBlock(x + 10, y + 4, z + 8, Blocks.STONEBRICK, 0, 3);
		this.setBlock(x + 1, y + 4, z + 9, Blocks.STONEBRICK, 0, 3);
		this.setBlock(x + 2, y + 4, z + 9, Blocks.AIR, 0, 3);
		this.setBlock(x + 3, y + 4, z + 9, Blocks.AIR, 0, 3);
		this.setBlock(x + 4, y + 4, z + 9, Blocks.AIR, 0, 3);
		this.setBlock(x + 5, y + 4, z + 9, Blocks.AIR, 0, 3);
		this.setBlock(x + 6, y + 4, z + 9, Blocks.AIR, 0, 3);
		this.setBlock(x + 7, y + 4, z + 9, Blocks.AIR, 0, 3);
		this.setBlock(x + 8, y + 4, z + 9, Blocks.AIR, 0, 3);
		this.setBlock(x + 9, y + 4, z + 9, Blocks.STONEBRICK, 0, 3);
		this.setBlock(x + 2, y + 4, z + 10, Blocks.STONEBRICK, 0, 3);
		this.setBlock(x + 3, y + 4, z + 10, Blocks.STONEBRICK, 0, 3);
		this.setBlock(x + 4, y + 4, z + 10, Blocks.STONEBRICK, 0, 3);
		this.setBlock(x + 5, y + 4, z + 10, Blocks.STONEBRICK, 0, 3);
		this.setBlock(x + 6, y + 4, z + 10, Blocks.STONEBRICK, 0, 3);
		this.setBlock(x + 7, y + 4, z + 10, Blocks.STONEBRICK, 0, 3);
		this.setBlock(x + 8, y + 4, z + 10, Blocks.STONEBRICK, 0, 3);
		this.setBlock(x + 2, y + 5, z + 0, Blocks.STONEBRICK, 0, 3);
		this.setBlock(x + 3, y + 5, z + 0, Blocks.STONEBRICK, 0, 3);
		this.setBlock(x + 4, y + 5, z + 0, Blocks.STONEBRICK, 0, 3);
		this.setBlock(x + 5, y + 5, z + 0, Blocks.STONE_SLAB, 13, 3);
		this.setBlock(x + 6, y + 5, z + 0, Blocks.STONEBRICK, 0, 3);
		this.setBlock(x + 7, y + 5, z + 0, Blocks.STONEBRICK, 0, 3);
		this.setBlock(x + 8, y + 5, z + 0, Blocks.STONEBRICK, 0, 3);
		this.setBlock(x + 1, y + 5, z + 1, Blocks.STONEBRICK, 0, 3);
		this.setBlock(x + 2, y + 5, z + 1, Blocks.AIR, 0, 3);
		this.setBlock(x + 3, y + 5, z + 1, Blocks.AIR, 0, 3);
		this.setBlock(x + 4, y + 5, z + 1, Blocks.AIR, 0, 3);
		this.setBlock(x + 5, y + 5, z + 1, Blocks.AIR, 0, 3);
		this.setBlock(x + 6, y + 5, z + 1, Blocks.AIR, 0, 3);
		this.setBlock(x + 7, y + 5, z + 1, Blocks.AIR, 0, 3);
		this.setBlock(x + 8, y + 5, z + 1, Blocks.AIR, 0, 3);
		this.setBlock(x + 9, y + 5, z + 1, Blocks.STONEBRICK, 0, 3);
		this.setBlock(x + 0, y + 5, z + 2, Blocks.STONEBRICK, 0, 3);
		this.setBlock(x + 1, y + 5, z + 2, Blocks.AIR, 0, 3);
		this.setBlock(x + 2, y + 5, z + 2, Blocks.AIR, 0, 3);
		this.setBlock(x + 3, y + 5, z + 2, Blocks.AIR, 0, 3);
		this.setBlock(x + 4, y + 5, z + 2, Blocks.AIR, 0, 3);
		this.setBlock(x + 5, y + 5, z + 2, Blocks.AIR, 0, 3);
		this.setBlock(x + 6, y + 5, z + 2, Blocks.AIR, 0, 3);
		this.setBlock(x + 7, y + 5, z + 2, Blocks.AIR, 0, 3);
		this.setBlock(x + 8, y + 5, z + 2, Blocks.AIR, 0, 3);
		this.setBlock(x + 9, y + 5, z + 2, Blocks.AIR, 0, 3);
		this.setBlock(x + 10, y + 5, z + 2, Blocks.STONEBRICK, 0, 3);
		this.setBlock(x + 0, y + 5, z + 3, Blocks.STONEBRICK, 0, 3);
		this.setBlock(x + 1, y + 5, z + 3, Blocks.STONE_BRICK_STAIRS, 2, 3);
		this.setBlock(x + 2, y + 5, z + 3, Blocks.STONE_BRICK_STAIRS, 2, 3);
		this.setBlock(x + 3, y + 5, z + 3, Blocks.AIR, 0, 3);
		this.setBlock(x + 4, y + 5, z + 3, Blocks.AIR, 0, 3);
		this.setBlock(x + 5, y + 5, z + 3, Blocks.AIR, 0, 3);
		this.setBlock(x + 6, y + 5, z + 3, Blocks.AIR, 0, 3);
		this.setBlock(x + 7, y + 5, z + 3, Blocks.AIR, 0, 3);
		this.setBlock(x + 8, y + 5, z + 3, Blocks.AIR, 0, 3);
		this.setBlock(x + 9, y + 5, z + 3, Blocks.AIR, 0, 3);
		this.setBlock(x + 10, y + 5, z + 3, Blocks.STONEBRICK, 0, 3);
		this.setBlock(x + 0, y + 5, z + 4, Blocks.STONEBRICK, 0, 3);
		this.setBlock(x + 1, y + 5, z + 4, Blocks.STONEBRICK, 0, 3);
		this.setBlock(x + 2, y + 5, z + 4, Blocks.STONEBRICK, 0, 3);
		this.setBlock(x + 3, y + 5, z + 4, Blocks.AIR, 0, 3);
		this.setBlock(x + 4, y + 5, z + 4, Blocks.AIR, 0, 3);
		this.setBlock(x + 5, y + 5, z + 4, Blocks.AIR, 0, 3);
		this.setBlock(x + 6, y + 5, z + 4, Blocks.AIR, 0, 3);
		this.setBlock(x + 7, y + 5, z + 4, Blocks.AIR, 0, 3);
		this.setBlock(x + 8, y + 5, z + 4, Blocks.AIR, 0, 3);
		this.setBlock(x + 9, y + 5, z + 4, Blocks.AIR, 0, 3);
		this.setBlock(x + 10, y + 5, z + 4, Blocks.STONEBRICK, 0, 3);
		this.setBlock(x + 0, y + 5, z + 5, Blocks.STONEBRICK, 0, 3);
		this.setBlock(x + 1, y + 5, z + 5, Blocks.STONE_BRICK_STAIRS, 7, 3);
		this.setBlock(x + 2, y + 5, z + 5, Blocks.STONE_BRICK_STAIRS, 7, 3);
		this.setBlock(x + 3, y + 5, z + 5, Blocks.AIR, 0, 3);
		this.setBlock(x + 4, y + 5, z + 5, Blocks.AIR, 0, 3);
		this.setBlock(x + 5, y + 5, z + 5, Blocks.AIR, 0, 3);
		this.setBlock(x + 6, y + 5, z + 5, Blocks.AIR, 0, 3);
		this.setBlock(x + 7, y + 5, z + 5, Blocks.AIR, 0, 3);
		this.setBlock(x + 8, y + 5, z + 5, Blocks.AIR, 0, 3);
		this.setBlock(x + 9, y + 5, z + 5, Blocks.AIR, 0, 3);
		this.setBlock(x + 10, y + 5, z + 5, Blocks.STONEBRICK, 0, 3);
		this.setBlock(x + 0, y + 5, z + 6, Blocks.STONEBRICK, 0, 3);
		this.setBlock(x + 1, y + 5, z + 6, Blocks.AIR, 0, 3);
		this.setBlock(x + 2, y + 5, z + 6, Blocks.AIR, 0, 3);
		this.setBlock(x + 3, y + 5, z + 6, Blocks.AIR, 0, 3);
		this.setBlock(x + 4, y + 5, z + 6, Blocks.AIR, 0, 3);
		this.setBlock(x + 5, y + 5, z + 6, Blocks.AIR, 0, 3);
		this.setBlock(x + 6, y + 5, z + 6, Blocks.AIR, 0, 3);
		this.setBlock(x + 7, y + 5, z + 6, Blocks.AIR, 0, 3);
		this.setBlock(x + 8, y + 5, z + 6, Blocks.AIR, 0, 3);
		this.setBlock(x + 9, y + 5, z + 6, Blocks.AIR, 0, 3);
		this.setBlock(x + 10, y + 5, z + 6, Blocks.STONEBRICK, 0, 3);
		this.setBlock(x + 0, y + 5, z + 7, Blocks.STONEBRICK, 0, 3);
		this.setBlock(x + 1, y + 5, z + 7, Blocks.AIR, 0, 3);
		this.setBlock(x + 2, y + 5, z + 7, Blocks.AIR, 0, 3);
		this.setBlock(x + 3, y + 5, z + 7, Blocks.AIR, 0, 3);
		this.setBlock(x + 4, y + 5, z + 7, Blocks.AIR, 0, 3);
		this.setBlock(x + 5, y + 5, z + 7, Blocks.AIR, 0, 3);
		this.setBlock(x + 6, y + 5, z + 7, Blocks.AIR, 0, 3);
		this.setBlock(x + 7, y + 5, z + 7, Blocks.AIR, 0, 3);
		this.setBlock(x + 8, y + 5, z + 7, Blocks.AIR, 0, 3);
		this.setBlock(x + 9, y + 5, z + 7, Blocks.AIR, 0, 3);
		this.setBlock(x + 10, y + 5, z + 7, Blocks.STONEBRICK, 0, 3);
		this.setBlock(x + 0, y + 5, z + 8, Blocks.STONEBRICK, 0, 3);
		this.setBlock(x + 1, y + 5, z + 8, Blocks.AIR, 0, 3);
		this.setBlock(x + 2, y + 5, z + 8, Blocks.AIR, 0, 3);
		this.setBlock(x + 3, y + 5, z + 8, Blocks.IRON_BARS, 0, 3);
		this.setBlock(x + 4, y + 5, z + 8, Blocks.AIR, 0, 3);
		this.setBlock(x + 5, y + 5, z + 8, Blocks.AIR, 0, 3);
		this.setBlock(x + 6, y + 5, z + 8, Blocks.AIR, 0, 3);
		this.setBlock(x + 7, y + 5, z + 8, Blocks.AIR, 0, 3);
		this.setBlock(x + 8, y + 5, z + 8, Blocks.AIR, 0, 3);
		this.setBlock(x + 9, y + 5, z + 8, Blocks.AIR, 0, 3);
		this.setBlock(x + 10, y + 5, z + 8, Blocks.STONEBRICK, 0, 3);
		this.setBlock(x + 1, y + 5, z + 9, Blocks.STONEBRICK, 0, 3);
		this.setBlock(x + 2, y + 5, z + 9, Blocks.AIR, 0, 3);
		this.setBlock(x + 3, y + 5, z + 9, Blocks.AIR, 0, 3);
		this.setBlock(x + 4, y + 5, z + 9, Blocks.AIR, 0, 3);
		this.setBlock(x + 5, y + 5, z + 9, Blocks.AIR, 0, 3);
		this.setBlock(x + 6, y + 5, z + 9, Blocks.AIR, 0, 3);
		this.setBlock(x + 7, y + 5, z + 9, Blocks.AIR, 0, 3);
		this.setBlock(x + 8, y + 5, z + 9, Blocks.AIR, 0, 3);
		this.setBlock(x + 9, y + 5, z + 9, Blocks.STONEBRICK, 0, 3);
		this.setBlock(x + 2, y + 5, z + 10, Blocks.STONEBRICK, 0, 3);
		this.setBlock(x + 3, y + 5, z + 10, Blocks.STONEBRICK, 0, 3);
		this.setBlock(x + 4, y + 5, z + 10, Blocks.STONEBRICK, 0, 3);
		this.setBlock(x + 5, y + 5, z + 10, Blocks.STONEBRICK, 0, 3);
		this.setBlock(x + 6, y + 5, z + 10, Blocks.STONEBRICK, 0, 3);
		this.setBlock(x + 7, y + 5, z + 10, Blocks.STONEBRICK, 0, 3);
		this.setBlock(x + 8, y + 5, z + 10, Blocks.STONEBRICK, 0, 3);
		this.setBlock(x + 2, y + 6, z + 0, Blocks.STONEBRICK, 0, 3);
		this.setBlock(x + 3, y + 6, z + 0, Blocks.STONEBRICK, 0, 3);
		this.setBlock(x + 4, y + 6, z + 0, Blocks.STONEBRICK, 0, 3);
		this.setBlock(x + 5, y + 6, z + 0, Blocks.STONEBRICK, 0, 3);
		this.setBlock(x + 6, y + 6, z + 0, Blocks.STONEBRICK, 0, 3);
		this.setBlock(x + 7, y + 6, z + 0, Blocks.STONEBRICK, 0, 3);
		this.setBlock(x + 8, y + 6, z + 0, Blocks.STONEBRICK, 0, 3);
		this.setBlock(x + 1, y + 6, z + 1, Blocks.STONEBRICK, 0, 3);
		this.setBlock(x + 2, y + 6, z + 1, Blocks.AIR, 0, 3);
		this.setBlock(x + 3, y + 6, z + 1, Blocks.AIR, 0, 3);
		this.setBlock(x + 4, y + 6, z + 1, Blocks.AIR, 0, 3);
		this.setBlock(x + 5, y + 6, z + 1, Blocks.AIR, 0, 3);
		this.setBlock(x + 6, y + 6, z + 1, Blocks.AIR, 0, 3);
		this.setBlock(x + 7, y + 6, z + 1, Blocks.AIR, 0, 3);
		this.setBlock(x + 8, y + 6, z + 1, Blocks.AIR, 0, 3);
		this.setBlock(x + 9, y + 6, z + 1, Blocks.STONEBRICK, 0, 3);
		this.setBlock(x + 0, y + 6, z + 2, Blocks.STONEBRICK, 0, 3);
		this.setBlock(x + 1, y + 6, z + 2, Blocks.AIR, 0, 3);
		this.setBlock(x + 2, y + 6, z + 2, Blocks.AIR, 0, 3);
		this.setBlock(x + 3, y + 6, z + 2, Blocks.AIR, 0, 3);
		this.setBlock(x + 4, y + 6, z + 2, Blocks.AIR, 0, 3);
		this.setBlock(x + 5, y + 6, z + 2, Blocks.AIR, 0, 3);
		this.setBlock(x + 6, y + 6, z + 2, Blocks.AIR, 0, 3);
		this.setBlock(x + 7, y + 6, z + 2, Blocks.AIR, 0, 3);
		this.setBlock(x + 8, y + 6, z + 2, Blocks.AIR, 0, 3);
		this.setBlock(x + 9, y + 6, z + 2, Blocks.AIR, 0, 3);
		this.setBlock(x + 10, y + 6, z + 2, Blocks.STONEBRICK, 0, 3);
		this.setBlock(x + 0, y + 6, z + 3, Blocks.STONEBRICK, 0, 3);
		this.setBlock(x + 1, y + 6, z + 3, Blocks.AIR, 0, 3);
		this.setBlock(x + 2, y + 6, z + 3, Blocks.AIR, 0, 3);
		this.setBlock(x + 3, y + 6, z + 3, Blocks.AIR, 0, 3);
		this.setBlock(x + 4, y + 6, z + 3, Blocks.AIR, 0, 3);
		this.setBlock(x + 5, y + 6, z + 3, Blocks.AIR, 0, 3);
		this.setBlock(x + 6, y + 6, z + 3, Blocks.AIR, 0, 3);
		this.setBlock(x + 7, y + 6, z + 3, Blocks.AIR, 0, 3);
		this.setBlock(x + 8, y + 6, z + 3, Blocks.AIR, 0, 3);
		this.setBlock(x + 9, y + 6, z + 3, Blocks.AIR, 0, 3);
		this.setBlock(x + 10, y + 6, z + 3, Blocks.STONEBRICK, 0, 3);
		this.setBlock(x + 0, y + 6, z + 4, Blocks.STONEBRICK, 0, 3);
		this.setBlock(x + 1, y + 6, z + 4, Blocks.STONE_BRICK_STAIRS, 2, 3);
		this.setBlock(x + 2, y + 6, z + 4, Blocks.STONE_BRICK_STAIRS, 2, 3);
		this.setBlock(x + 3, y + 6, z + 4, Blocks.AIR, 0, 3);
		this.setBlock(x + 4, y + 6, z + 4, Blocks.AIR, 0, 3);
		this.setBlock(x + 5, y + 6, z + 4, Blocks.AIR, 0, 3);
		this.setBlock(x + 6, y + 6, z + 4, Blocks.AIR, 0, 3);
		this.setBlock(x + 7, y + 6, z + 4, Blocks.AIR, 0, 3);
		this.setBlock(x + 8, y + 6, z + 4, Blocks.AIR, 0, 3);
		this.setBlock(x + 9, y + 6, z + 4, Blocks.AIR, 0, 3);
		this.setBlock(x + 10, y + 6, z + 4, Blocks.STONEBRICK, 0, 3);
		this.setBlock(x + 0, y + 6, z + 5, Blocks.STONEBRICK, 0, 3);
		this.setBlock(x + 1, y + 6, z + 5, Blocks.STONEBRICK, 0, 3);
		this.setBlock(x + 2, y + 6, z + 5, Blocks.STONEBRICK, 0, 3);
		this.setBlock(x + 3, y + 6, z + 5, Blocks.AIR, 0, 3);
		this.setBlock(x + 4, y + 6, z + 5, Blocks.AIR, 0, 3);
		this.setBlock(x + 5, y + 6, z + 5, Blocks.AIR, 0, 3);
		this.setBlock(x + 6, y + 6, z + 5, Blocks.AIR, 0, 3);
		this.setBlock(x + 7, y + 6, z + 5, Blocks.AIR, 0, 3);
		this.setBlock(x + 8, y + 6, z + 5, Blocks.AIR, 0, 3);
		this.setBlock(x + 9, y + 6, z + 5, Blocks.AIR, 0, 3);
		this.setBlock(x + 10, y + 6, z + 5, Blocks.STONEBRICK, 0, 3);
		this.setBlock(x + 0, y + 6, z + 6, Blocks.STONEBRICK, 0, 3);
		this.setBlock(x + 1, y + 6, z + 6, Blocks.STONE_BRICK_STAIRS, 7, 3);
		this.setBlock(x + 2, y + 6, z + 6, Blocks.STONE_BRICK_STAIRS, 7, 3);
		this.setBlock(x + 3, y + 6, z + 6, Blocks.AIR, 0, 3);
		this.setBlock(x + 4, y + 6, z + 6, Blocks.AIR, 0, 3);
		this.setBlock(x + 5, y + 6, z + 6, Blocks.AIR, 0, 3);
		this.setBlock(x + 6, y + 6, z + 6, Blocks.AIR, 0, 3);
		this.setBlock(x + 7, y + 6, z + 6, Blocks.AIR, 0, 3);
		this.setBlock(x + 8, y + 6, z + 6, Blocks.AIR, 0, 3);
		this.setBlock(x + 9, y + 6, z + 6, Blocks.AIR, 0, 3);
		this.setBlock(x + 10, y + 6, z + 6, Blocks.STONEBRICK, 0, 3);
		this.setBlock(x + 0, y + 6, z + 7, Blocks.STONEBRICK, 0, 3);
		this.setBlock(x + 1, y + 6, z + 7, Blocks.AIR, 0, 3);
		this.setBlock(x + 2, y + 6, z + 7, Blocks.AIR, 0, 3);
		this.setBlock(x + 3, y + 6, z + 7, Blocks.AIR, 0, 3);
		this.setBlock(x + 4, y + 6, z + 7, Blocks.AIR, 0, 3);
		this.setBlock(x + 5, y + 6, z + 7, Blocks.AIR, 0, 3);
		this.setBlock(x + 6, y + 6, z + 7, Blocks.AIR, 0, 3);
		this.setBlock(x + 7, y + 6, z + 7, Blocks.AIR, 0, 3);
		this.setBlock(x + 8, y + 6, z + 7, Blocks.AIR, 0, 3);
		this.setBlock(x + 9, y + 6, z + 7, Blocks.AIR, 0, 3);
		this.setBlock(x + 10, y + 6, z + 7, Blocks.STONEBRICK, 0, 3);
		this.setBlock(x + 0, y + 6, z + 8, Blocks.STONEBRICK, 0, 3);
		this.setBlock(x + 1, y + 6, z + 8, Blocks.AIR, 0, 3);
		this.setBlock(x + 2, y + 6, z + 8, Blocks.AIR, 0, 3);
		this.setBlock(x + 3, y + 6, z + 8, Blocks.IRON_BARS, 0, 3);
		this.setBlock(x + 4, y + 6, z + 8, Blocks.AIR, 0, 3);
		this.setBlock(x + 5, y + 6, z + 8, Blocks.AIR, 0, 3);
		this.setBlock(x + 6, y + 6, z + 8, Blocks.AIR, 0, 3);
		this.setBlock(x + 7, y + 6, z + 8, Blocks.AIR, 0, 3);
		this.setBlock(x + 8, y + 6, z + 8, Blocks.AIR, 0, 3);
		this.setBlock(x + 9, y + 6, z + 8, Blocks.AIR, 0, 3);
		this.setBlock(x + 10, y + 6, z + 8, Blocks.STONEBRICK, 0, 3);
		this.setBlock(x + 1, y + 6, z + 9, Blocks.STONEBRICK, 0, 3);
		this.setBlock(x + 2, y + 6, z + 9, Blocks.AIR, 0, 3);
		this.setBlock(x + 3, y + 6, z + 9, Blocks.AIR, 0, 3);
		this.setBlock(x + 4, y + 6, z + 9, Blocks.AIR, 0, 3);
		this.setBlock(x + 5, y + 6, z + 9, Blocks.AIR, 0, 3);
		this.setBlock(x + 6, y + 6, z + 9, Blocks.AIR, 0, 3);
		this.setBlock(x + 7, y + 6, z + 9, Blocks.AIR, 0, 3);
		this.setBlock(x + 8, y + 6, z + 9, Blocks.AIR, 0, 3);
		this.setBlock(x + 9, y + 6, z + 9, Blocks.STONEBRICK, 0, 3);
		this.setBlock(x + 2, y + 6, z + 10, Blocks.STONEBRICK, 0, 3);
		this.setBlock(x + 3, y + 6, z + 10, Blocks.STONEBRICK, 0, 3);
		this.setBlock(x + 4, y + 6, z + 10, Blocks.STONEBRICK, 0, 3);
		this.setBlock(x + 5, y + 6, z + 10, Blocks.STONEBRICK, 0, 3);
		this.setBlock(x + 6, y + 6, z + 10, Blocks.STONEBRICK, 0, 3);
		this.setBlock(x + 7, y + 6, z + 10, Blocks.STONEBRICK, 0, 3);
		this.setBlock(x + 8, y + 6, z + 10, Blocks.STONEBRICK, 0, 3);
		this.setBlock(x + 2, y + 7, z + 0, Blocks.STONEBRICK, 0, 3);
		this.setBlock(x + 3, y + 7, z + 0, Blocks.STONEBRICK, 0, 3);
		this.setBlock(x + 4, y + 7, z + 0, Blocks.STONEBRICK, 0, 3);
		this.setBlock(x + 5, y + 7, z + 0, Blocks.STONEBRICK, 0, 3);
		this.setBlock(x + 6, y + 7, z + 0, Blocks.STONEBRICK, 0, 3);
		this.setBlock(x + 7, y + 7, z + 0, Blocks.STONEBRICK, 0, 3);
		this.setBlock(x + 8, y + 7, z + 0, Blocks.STONEBRICK, 0, 3);
		this.setBlock(x + 1, y + 7, z + 1, Blocks.STONEBRICK, 0, 3);
		this.setBlock(x + 2, y + 7, z + 1, Blocks.AIR, 0, 3);
		this.setBlock(x + 3, y + 7, z + 1, Blocks.AIR, 0, 3);
		this.setBlock(x + 4, y + 7, z + 1, Blocks.AIR, 0, 3);
		this.setBlock(x + 5, y + 7, z + 1, Blocks.AIR, 0, 3);
		this.setBlock(x + 6, y + 7, z + 1, Blocks.AIR, 0, 3);
		this.setBlock(x + 7, y + 7, z + 1, Blocks.AIR, 0, 3);
		this.setBlock(x + 8, y + 7, z + 1, Blocks.AIR, 0, 3);
		this.setBlock(x + 9, y + 7, z + 1, Blocks.STONEBRICK, 0, 3);
		this.setBlock(x + 0, y + 7, z + 2, Blocks.STONEBRICK, 0, 3);
		this.setBlock(x + 1, y + 7, z + 2, Blocks.AIR, 0, 3);
		this.setBlock(x + 2, y + 7, z + 2, Blocks.AIR, 0, 3);
		this.setBlock(x + 3, y + 7, z + 2, Blocks.AIR, 0, 3);
		this.setBlock(x + 4, y + 7, z + 2, Blocks.AIR, 0, 3);
		this.setBlock(x + 5, y + 7, z + 2, Blocks.AIR, 0, 3);
		this.setBlock(x + 6, y + 7, z + 2, Blocks.AIR, 0, 3);
		this.setBlock(x + 7, y + 7, z + 2, Blocks.AIR, 0, 3);
		this.setBlock(x + 8, y + 7, z + 2, Blocks.AIR, 0, 3);
		this.setBlock(x + 9, y + 7, z + 2, Blocks.AIR, 0, 3);
		this.setBlock(x + 10, y + 7, z + 2, Blocks.STONEBRICK, 0, 3);
		this.setBlock(x + 0, y + 7, z + 3, Blocks.STONEBRICK, 0, 3);
		this.setBlock(x + 1, y + 7, z + 3, Blocks.AIR, 0, 3);
		this.setBlock(x + 2, y + 7, z + 3, Blocks.AIR, 0, 3);
		this.setBlock(x + 3, y + 7, z + 3, Blocks.AIR, 0, 3);
		this.setBlock(x + 4, y + 7, z + 3, Blocks.AIR, 0, 3);
		this.setBlock(x + 5, y + 7, z + 3, Blocks.AIR, 0, 3);
		this.setBlock(x + 6, y + 7, z + 3, Blocks.AIR, 0, 3);
		this.setBlock(x + 7, y + 7, z + 3, Blocks.AIR, 0, 3);
		this.setBlock(x + 8, y + 7, z + 3, Blocks.AIR, 0, 3);
		this.setBlock(x + 9, y + 7, z + 3, Blocks.AIR, 0, 3);
		this.setBlock(x + 10, y + 7, z + 3, Blocks.STONEBRICK, 0, 3);
		this.setBlock(x + 0, y + 7, z + 4, Blocks.STONEBRICK, 0, 3);
		this.setBlock(x + 1, y + 7, z + 4, Blocks.AIR, 0, 3);
		this.setBlock(x + 2, y + 7, z + 4, Blocks.AIR, 0, 3);
		this.setBlock(x + 3, y + 7, z + 4, Blocks.AIR, 0, 3);
		this.setBlock(x + 4, y + 7, z + 4, Blocks.AIR, 0, 3);
		this.setBlock(x + 5, y + 7, z + 4, Blocks.AIR, 0, 3);
		this.setBlock(x + 6, y + 7, z + 4, Blocks.AIR, 0, 3);
		this.setBlock(x + 7, y + 7, z + 4, Blocks.AIR, 0, 3);
		this.setBlock(x + 8, y + 7, z + 4, Blocks.AIR, 0, 3);
		this.setBlock(x + 9, y + 7, z + 4, Blocks.AIR, 0, 3);
		this.setBlock(x + 10, y + 7, z + 4, Blocks.STONEBRICK, 0, 3);
		this.setBlock(x + 0, y + 7, z + 5, Blocks.STONEBRICK, 0, 3);
		this.setBlock(x + 1, y + 7, z + 5, Blocks.STONE_BRICK_STAIRS, 2, 3);
		this.setBlock(x + 2, y + 7, z + 5, Blocks.STONE_BRICK_STAIRS, 2, 3);
		this.setBlock(x + 3, y + 7, z + 5, Blocks.AIR, 0, 3);
		this.setBlock(x + 4, y + 7, z + 5, Blocks.AIR, 0, 3);
		this.setBlock(x + 5, y + 7, z + 5, Blocks.AIR, 0, 3);
		this.setBlock(x + 6, y + 7, z + 5, Blocks.AIR, 0, 3);
		this.setBlock(x + 7, y + 7, z + 5, Blocks.AIR, 0, 3);
		this.setBlock(x + 8, y + 7, z + 5, Blocks.AIR, 0, 3);
		this.setBlock(x + 9, y + 7, z + 5, Blocks.AIR, 0, 3);
		this.setBlock(x + 10, y + 7, z + 5, Blocks.STONEBRICK, 0, 3);
		this.setBlock(x + 0, y + 7, z + 6, Blocks.STONEBRICK, 0, 3);
		this.setBlock(x + 1, y + 7, z + 6, Blocks.STONEBRICK, 0, 3);
		this.setBlock(x + 2, y + 7, z + 6, Blocks.STONEBRICK, 0, 3);
		this.setBlock(x + 3, y + 7, z + 6, Blocks.AIR, 0, 3);
		this.setBlock(x + 4, y + 7, z + 6, Blocks.AIR, 0, 3);
		this.setBlock(x + 5, y + 7, z + 6, Blocks.AIR, 0, 3);
		this.setBlock(x + 6, y + 7, z + 6, Blocks.AIR, 0, 3);
		this.setBlock(x + 7, y + 7, z + 6, Blocks.AIR, 0, 3);
		this.setBlock(x + 8, y + 7, z + 6, Blocks.AIR, 0, 3);
		this.setBlock(x + 9, y + 7, z + 6, Blocks.AIR, 0, 3);
		this.setBlock(x + 10, y + 7, z + 6, Blocks.STONEBRICK, 0, 3);
		this.setBlock(x + 0, y + 7, z + 7, Blocks.STONEBRICK, 0, 3);
		this.setBlock(x + 1, y + 7, z + 7, Blocks.STONE_BRICK_STAIRS, 7, 3);
		this.setBlock(x + 2, y + 7, z + 7, Blocks.STONE_BRICK_STAIRS, 7, 3);
		this.setBlock(x + 3, y + 7, z + 7, Blocks.AIR, 0, 3);
		this.setBlock(x + 4, y + 7, z + 7, Blocks.AIR, 0, 3);
		this.setBlock(x + 5, y + 7, z + 7, Blocks.AIR, 0, 3);
		this.setBlock(x + 6, y + 7, z + 7, Blocks.AIR, 0, 3);
		this.setBlock(x + 7, y + 7, z + 7, Blocks.AIR, 0, 3);
		this.setBlock(x + 8, y + 7, z + 7, Blocks.AIR, 0, 3);
		this.setBlock(x + 9, y + 7, z + 7, Blocks.AIR, 0, 3);
		this.setBlock(x + 10, y + 7, z + 7, Blocks.STONEBRICK, 0, 3);
		this.setBlock(x + 0, y + 7, z + 8, Blocks.STONEBRICK, 0, 3);
		this.setBlock(x + 1, y + 7, z + 8, Blocks.AIR, 0, 3);
		this.setBlock(x + 2, y + 7, z + 8, Blocks.AIR, 0, 3);
		this.setBlock(x + 3, y + 7, z + 8, Blocks.IRON_BARS, 0, 3);
		this.setBlock(x + 4, y + 7, z + 8, Blocks.AIR, 0, 3);
		this.setBlock(x + 5, y + 7, z + 8, Blocks.AIR, 0, 3);
		this.setBlock(x + 6, y + 7, z + 8, Blocks.AIR, 0, 3);
		this.setBlock(x + 7, y + 7, z + 8, Blocks.AIR, 0, 3);
		this.setBlock(x + 8, y + 7, z + 8, Blocks.AIR, 0, 3);
		this.setBlock(x + 9, y + 7, z + 8, Blocks.AIR, 0, 3);
		this.setBlock(x + 10, y + 7, z + 8, Blocks.STONEBRICK, 0, 3);
		this.setBlock(x + 1, y + 7, z + 9, Blocks.STONEBRICK, 0, 3);
		this.setBlock(x + 2, y + 7, z + 9, Blocks.AIR, 0, 3);
		this.setBlock(x + 3, y + 7, z + 9, Blocks.AIR, 0, 3);
		this.setBlock(x + 4, y + 7, z + 9, Blocks.AIR, 0, 3);
		this.setBlock(x + 5, y + 7, z + 9, Blocks.AIR, 0, 3);
		this.setBlock(x + 6, y + 7, z + 9, Blocks.AIR, 0, 3);
		this.setBlock(x + 7, y + 7, z + 9, Blocks.AIR, 0, 3);
		this.setBlock(x + 8, y + 7, z + 9, Blocks.AIR, 0, 3);
		this.setBlock(x + 9, y + 7, z + 9, Blocks.STONEBRICK, 0, 3);
		this.setBlock(x + 2, y + 7, z + 10, Blocks.STONEBRICK, 0, 3);
		this.setBlock(x + 3, y + 7, z + 10, Blocks.STONEBRICK, 0, 3);
		this.setBlock(x + 4, y + 7, z + 10, Blocks.STONEBRICK, 0, 3);
		this.setBlock(x + 5, y + 7, z + 10, Blocks.STONEBRICK, 0, 3);
		this.setBlock(x + 6, y + 7, z + 10, Blocks.STONEBRICK, 0, 3);
		this.setBlock(x + 7, y + 7, z + 10, Blocks.STONEBRICK, 0, 3);
		this.setBlock(x + 8, y + 7, z + 10, Blocks.STONEBRICK, 0, 3);
		this.setBlock(x + 2, y + 8, z + 0, Blocks.STONEBRICK, 0, 3);
		this.setBlock(x + 3, y + 8, z + 0, Blocks.STONEBRICK, 0, 3);
		this.setBlock(x + 4, y + 8, z + 0, Blocks.STONEBRICK, 0, 3);
		this.setBlock(x + 5, y + 8, z + 0, Blocks.STONEBRICK, 0, 3);
		this.setBlock(x + 6, y + 8, z + 0, Blocks.STONEBRICK, 0, 3);
		this.setBlock(x + 7, y + 8, z + 0, Blocks.STONEBRICK, 0, 3);
		this.setBlock(x + 8, y + 8, z + 0, Blocks.STONEBRICK, 0, 3);
		this.setBlock(x + 1, y + 8, z + 1, Blocks.STONEBRICK, 0, 3);
		this.setBlock(x + 2, y + 8, z + 1, Blocks.AIR, 0, 3);
		this.setBlock(x + 3, y + 8, z + 1, Blocks.AIR, 0, 3);
		this.setBlock(x + 4, y + 8, z + 1, Blocks.AIR, 0, 3);
		this.setBlock(x + 5, y + 8, z + 1, Blocks.AIR, 0, 3);
		this.setBlock(x + 6, y + 8, z + 1, Blocks.AIR, 0, 3);
		this.setBlock(x + 7, y + 8, z + 1, Blocks.AIR, 0, 3);
		this.setBlock(x + 8, y + 8, z + 1, Blocks.AIR, 0, 3);
		this.setBlock(x + 9, y + 8, z + 1, Blocks.STONEBRICK, 0, 3);
		this.setBlock(x + 0, y + 8, z + 2, Blocks.STONEBRICK, 0, 3);
		this.setBlock(x + 1, y + 8, z + 2, Blocks.AIR, 0, 3);
		this.setBlock(x + 2, y + 8, z + 2, Blocks.AIR, 0, 3);
		this.setBlock(x + 3, y + 8, z + 2, Blocks.AIR, 0, 3);
		this.setBlock(x + 4, y + 8, z + 2, Blocks.AIR, 0, 3);
		this.setBlock(x + 5, y + 8, z + 2, Blocks.AIR, 0, 3);
		this.setBlock(x + 6, y + 8, z + 2, Blocks.AIR, 0, 3);
		this.setBlock(x + 7, y + 8, z + 2, Blocks.AIR, 0, 3);
		this.setBlock(x + 8, y + 8, z + 2, Blocks.AIR, 0, 3);
		this.setBlock(x + 9, y + 8, z + 2, Blocks.AIR, 0, 3);
		this.setBlock(x + 10, y + 8, z + 2, Blocks.STONEBRICK, 0, 3);
		this.setBlock(x + 0, y + 8, z + 3, Blocks.STONEBRICK, 0, 3);
		this.setBlock(x + 1, y + 8, z + 3, Blocks.AIR, 0, 3);
		this.setBlock(x + 2, y + 8, z + 3, Blocks.AIR, 0, 3);
		this.setBlock(x + 3, y + 8, z + 3, Blocks.AIR, 0, 3);
		this.setBlock(x + 4, y + 8, z + 3, Blocks.AIR, 0, 3);
		this.setBlock(x + 5, y + 8, z + 3, Blocks.AIR, 0, 3);
		this.setBlock(x + 6, y + 8, z + 3, Blocks.AIR, 0, 3);
		this.setBlock(x + 7, y + 8, z + 3, Blocks.AIR, 0, 3);
		this.setBlock(x + 8, y + 8, z + 3, Blocks.AIR, 0, 3);
		this.setBlock(x + 9, y + 8, z + 3, Blocks.AIR, 0, 3);
		this.setBlock(x + 10, y + 8, z + 3, Blocks.STONEBRICK, 0, 3);
		this.setBlock(x + 0, y + 8, z + 4, Blocks.STONEBRICK, 0, 3);
		this.setBlock(x + 1, y + 8, z + 4, Blocks.AIR, 0, 3);
		this.setBlock(x + 2, y + 8, z + 4, Blocks.AIR, 0, 3);
		this.setBlock(x + 3, y + 8, z + 4, Blocks.AIR, 0, 3);
		this.setBlock(x + 4, y + 8, z + 4, Blocks.AIR, 0, 3);
		this.setBlock(x + 5, y + 8, z + 4, Blocks.AIR, 0, 3);
		this.setBlock(x + 6, y + 8, z + 4, Blocks.AIR, 0, 3);
		this.setBlock(x + 7, y + 8, z + 4, Blocks.AIR, 0, 3);
		this.setBlock(x + 8, y + 8, z + 4, Blocks.AIR, 0, 3);
		this.setBlock(x + 9, y + 8, z + 4, Blocks.AIR, 0, 3);
		this.setBlock(x + 10, y + 8, z + 4, Blocks.STONEBRICK, 0, 3);
		this.setBlock(x + 0, y + 8, z + 5, Blocks.STONEBRICK, 0, 3);
		this.setBlock(x + 1, y + 8, z + 5, Blocks.AIR, 0, 3);
		this.setBlock(x + 2, y + 8, z + 5, Blocks.AIR, 0, 3);
		this.setBlock(x + 3, y + 8, z + 5, Blocks.AIR, 0, 3);
		this.setBlock(x + 4, y + 8, z + 5, Blocks.AIR, 0, 3);
		this.setBlock(x + 5, y + 8, z + 5, Blocks.AIR, 0, 3);
		this.setBlock(x + 6, y + 8, z + 5, Blocks.AIR, 0, 3);
		this.setBlock(x + 7, y + 8, z + 5, Blocks.AIR, 0, 3);
		this.setBlock(x + 8, y + 8, z + 5, Blocks.AIR, 0, 3);
		this.setBlock(x + 9, y + 8, z + 5, Blocks.AIR, 0, 3);
		this.setBlock(x + 10, y + 8, z + 5, Blocks.STONEBRICK, 0, 3);
		this.setBlock(x + 0, y + 8, z + 6, Blocks.STONEBRICK, 0, 3);
		this.setBlock(x + 1, y + 8, z + 6, Blocks.STONE_BRICK_STAIRS, 2, 3);
		this.setBlock(x + 2, y + 8, z + 6, Blocks.STONE_BRICK_STAIRS, 2, 3);
		this.setBlock(x + 3, y + 8, z + 6, Blocks.AIR, 0, 3);
		this.setBlock(x + 4, y + 8, z + 6, Blocks.AIR, 0, 3);
		this.setBlock(x + 5, y + 8, z + 6, Blocks.AIR, 0, 3);
		this.setBlock(x + 6, y + 8, z + 6, Blocks.AIR, 0, 3);
		this.setBlock(x + 7, y + 8, z + 6, Blocks.AIR, 0, 3);
		this.setBlock(x + 8, y + 8, z + 6, Blocks.AIR, 0, 3);
		this.setBlock(x + 9, y + 8, z + 6, Blocks.AIR, 0, 3);
		this.setBlock(x + 10, y + 8, z + 6, Blocks.STONEBRICK, 0, 3);
		this.setBlock(x + 0, y + 8, z + 7, Blocks.STONEBRICK, 0, 3);
		this.setBlock(x + 1, y + 8, z + 7, Blocks.STONEBRICK, 0, 3);
		this.setBlock(x + 2, y + 8, z + 7, Blocks.STONEBRICK, 0, 3);
		this.setBlock(x + 3, y + 8, z + 7, Blocks.AIR, 0, 3);
		this.setBlock(x + 4, y + 8, z + 7, Blocks.AIR, 0, 3);
		this.setBlock(x + 5, y + 8, z + 7, Blocks.AIR, 0, 3);
		this.setBlock(x + 6, y + 8, z + 7, Blocks.AIR, 0, 3);
		this.setBlock(x + 7, y + 8, z + 7, Blocks.AIR, 0, 3);
		this.setBlock(x + 8, y + 8, z + 7, Blocks.AIR, 0, 3);
		this.setBlock(x + 9, y + 8, z + 7, Blocks.AIR, 0, 3);
		this.setBlock(x + 10, y + 8, z + 7, Blocks.STONEBRICK, 0, 3);
		this.setBlock(x + 0, y + 8, z + 8, Blocks.STONEBRICK, 0, 3);
		this.setBlock(x + 1, y + 8, z + 8, Blocks.STONEBRICK, 0, 3);
		this.setBlock(x + 2, y + 8, z + 8, Blocks.STONEBRICK, 0, 3);
		this.setBlock(x + 3, y + 8, z + 8, Blocks.STONE_BRICK_STAIRS, 5, 3);
		this.setBlock(x + 4, y + 8, z + 8, Blocks.AIR, 0, 3);
		this.setBlock(x + 5, y + 8, z + 8, Blocks.AIR, 0, 3);
		this.setBlock(x + 6, y + 8, z + 8, Blocks.AIR, 0, 3);
		this.setBlock(x + 7, y + 8, z + 8, Blocks.AIR, 0, 3);
		this.setBlock(x + 8, y + 8, z + 8, Blocks.AIR, 0, 3);
		this.setBlock(x + 9, y + 8, z + 8, Blocks.AIR, 0, 3);
		this.setBlock(x + 10, y + 8, z + 8, Blocks.STONEBRICK, 0, 3);
		this.setBlock(x + 1, y + 8, z + 9, Blocks.STONEBRICK, 0, 3);
		this.setBlock(x + 2, y + 8, z + 9, Blocks.STONEBRICK, 0, 3);
		this.setBlock(x + 3, y + 8, z + 9, Blocks.STONE_BRICK_STAIRS, 5, 3);
		this.setBlock(x + 4, y + 8, z + 9, Blocks.AIR, 0, 3);
		this.setBlock(x + 5, y + 8, z + 9, Blocks.AIR, 0, 3);
		this.setBlock(x + 6, y + 8, z + 9, Blocks.AIR, 0, 3);
		this.setBlock(x + 7, y + 8, z + 9, Blocks.AIR, 0, 3);
		this.setBlock(x + 8, y + 8, z + 9, Blocks.AIR, 0, 3);
		this.setBlock(x + 9, y + 8, z + 9, Blocks.STONEBRICK, 0, 3);
		this.setBlock(x + 2, y + 8, z + 10, Blocks.STONEBRICK, 0, 3);
		this.setBlock(x + 3, y + 8, z + 10, Blocks.STONEBRICK, 0, 3);
		this.setBlock(x + 4, y + 8, z + 10, Blocks.STONEBRICK, 0, 3);
		this.setBlock(x + 5, y + 8, z + 10, Blocks.STONEBRICK, 0, 3);
		this.setBlock(x + 6, y + 8, z + 10, Blocks.STONEBRICK, 0, 3);
		this.setBlock(x + 7, y + 8, z + 10, Blocks.STONEBRICK, 0, 3);
		this.setBlock(x + 8, y + 8, z + 10, Blocks.STONEBRICK, 0, 3);
		this.setBlock(x + 2, y + 9, z + 0, Blocks.STONEBRICK, 0, 3);
		this.setBlock(x + 3, y + 9, z + 0, Blocks.STONEBRICK, 0, 3);
		this.setBlock(x + 4, y + 9, z + 0, Blocks.STONEBRICK, 0, 3);
		this.setBlock(x + 5, y + 9, z + 0, Blocks.STONEBRICK, 0, 3);
		this.setBlock(x + 6, y + 9, z + 0, Blocks.STONEBRICK, 0, 3);
		this.setBlock(x + 7, y + 9, z + 0, Blocks.STONEBRICK, 0, 3);
		this.setBlock(x + 8, y + 9, z + 0, Blocks.STONEBRICK, 0, 3);
		this.setBlock(x + 1, y + 9, z + 1, Blocks.STONEBRICK, 0, 3);
		this.setBlock(x + 2, y + 9, z + 1, Blocks.AIR, 0, 3);
		this.setBlock(x + 3, y + 9, z + 1, Blocks.AIR, 0, 3);
		this.setBlock(x + 4, y + 9, z + 1, Blocks.AIR, 0, 3);
		this.setBlock(x + 5, y + 9, z + 1, Blocks.AIR, 0, 3);
		this.setBlock(x + 6, y + 9, z + 1, Blocks.AIR, 0, 3);
		this.setBlock(x + 7, y + 9, z + 1, Blocks.AIR, 0, 3);
		this.setBlock(x + 8, y + 9, z + 1, Blocks.AIR, 0, 3);
		this.setBlock(x + 9, y + 9, z + 1, Blocks.STONEBRICK, 0, 3);
		this.setBlock(x + 0, y + 9, z + 2, Blocks.STONEBRICK, 0, 3);
		this.setBlock(x + 1, y + 9, z + 2, Blocks.AIR, 0, 3);
		this.setBlock(x + 2, y + 9, z + 2, Blocks.AIR, 0, 3);
		this.setBlock(x + 3, y + 9, z + 2, Blocks.AIR, 0, 3);
		this.setBlock(x + 4, y + 9, z + 2, Blocks.AIR, 0, 3);
		this.setBlock(x + 5, y + 9, z + 2, Blocks.AIR, 0, 3);
		this.setBlock(x + 6, y + 9, z + 2, Blocks.AIR, 0, 3);
		this.setBlock(x + 7, y + 9, z + 2, Blocks.AIR, 0, 3);
		this.setBlock(x + 8, y + 9, z + 2, Blocks.AIR, 0, 3);
		this.setBlock(x + 9, y + 9, z + 2, Blocks.AIR, 0, 3);
		this.setBlock(x + 10, y + 9, z + 2, Blocks.STONEBRICK, 0, 3);
		this.setBlock(x + 0, y + 9, z + 3, Blocks.STONEBRICK, 0, 3);
		this.setBlock(x + 1, y + 9, z + 3, Blocks.AIR, 0, 3);
		this.setBlock(x + 2, y + 9, z + 3, Blocks.AIR, 0, 3);
		this.setBlock(x + 3, y + 9, z + 3, Blocks.AIR, 0, 3);
		this.setBlock(x + 4, y + 9, z + 3, Blocks.AIR, 0, 3);
		this.setBlock(x + 5, y + 9, z + 3, Blocks.AIR, 0, 3);
		this.setBlock(x + 6, y + 9, z + 3, Blocks.AIR, 0, 3);
		this.setBlock(x + 7, y + 9, z + 3, Blocks.AIR, 0, 3);
		this.setBlock(x + 8, y + 9, z + 3, Blocks.AIR, 0, 3);
		this.setBlock(x + 9, y + 9, z + 3, Blocks.AIR, 0, 3);
		this.setBlock(x + 10, y + 9, z + 3, Blocks.STONEBRICK, 0, 3);
		this.setBlock(x + 0, y + 9, z + 4, Blocks.STONEBRICK, 0, 3);
		this.setBlock(x + 1, y + 9, z + 4, Blocks.AIR, 0, 3);
		this.setBlock(x + 2, y + 9, z + 4, Blocks.AIR, 0, 3);
		this.setBlock(x + 3, y + 9, z + 4, Blocks.AIR, 0, 3);
		this.setBlock(x + 4, y + 9, z + 4, Blocks.AIR, 0, 3);
		this.setBlock(x + 5, y + 9, z + 4, Blocks.AIR, 0, 3);
		this.setBlock(x + 6, y + 9, z + 4, Blocks.AIR, 0, 3);
		this.setBlock(x + 7, y + 9, z + 4, Blocks.AIR, 0, 3);
		this.setBlock(x + 8, y + 9, z + 4, Blocks.AIR, 0, 3);
		this.setBlock(x + 9, y + 9, z + 4, Blocks.AIR, 0, 3);
		this.setBlock(x + 10, y + 9, z + 4, Blocks.STONEBRICK, 0, 3);
		this.setBlock(x + 0, y + 9, z + 5, Blocks.STONEBRICK, 0, 3);
		this.setBlock(x + 1, y + 9, z + 5, Blocks.AIR, 0, 3);
		this.setBlock(x + 2, y + 9, z + 5, Blocks.AIR, 0, 3);
		this.setBlock(x + 3, y + 9, z + 5, Blocks.AIR, 0, 3);
		this.setBlock(x + 4, y + 9, z + 5, Blocks.AIR, 0, 3);
		this.setBlock(x + 5, y + 9, z + 5, Blocks.AIR, 0, 3);
		this.setBlock(x + 6, y + 9, z + 5, Blocks.AIR, 0, 3);
		this.setBlock(x + 7, y + 9, z + 5, Blocks.AIR, 0, 3);
		this.setBlock(x + 8, y + 9, z + 5, Blocks.AIR, 0, 3);
		this.setBlock(x + 9, y + 9, z + 5, Blocks.AIR, 0, 3);
		this.setBlock(x + 10, y + 9, z + 5, Blocks.STONEBRICK, 0, 3);
		this.setBlock(x + 0, y + 9, z + 6, Blocks.STONEBRICK, 0, 3);
		this.setBlock(x + 1, y + 9, z + 6, Blocks.AIR, 0, 3);
		this.setBlock(x + 2, y + 9, z + 6, Blocks.AIR, 0, 3);
		this.setBlock(x + 3, y + 9, z + 6, Blocks.AIR, 0, 3);
		this.setBlock(x + 4, y + 9, z + 6, Blocks.AIR, 0, 3);
		this.setBlock(x + 5, y + 9, z + 6, Blocks.AIR, 0, 3);
		this.setBlock(x + 6, y + 9, z + 6, Blocks.AIR, 0, 3);
		this.setBlock(x + 7, y + 9, z + 6, Blocks.AIR, 0, 3);
		this.setBlock(x + 8, y + 9, z + 6, Blocks.AIR, 0, 3);
		this.setBlock(x + 9, y + 9, z + 6, Blocks.AIR, 0, 3);
		this.setBlock(x + 10, y + 9, z + 6, Blocks.STONEBRICK, 0, 3);
		this.setBlock(x + 0, y + 9, z + 7, Blocks.STONEBRICK, 0, 3);
		this.setBlock(x + 1, y + 9, z + 7, Blocks.STONE_BRICK_STAIRS, 2, 3);
		this.setBlock(x + 2, y + 9, z + 7, Blocks.STONE_BRICK_STAIRS, 2, 3);
		this.setBlock(x + 3, y + 9, z + 7, Blocks.AIR, 0, 3);
		this.setBlock(x + 4, y + 9, z + 7, Blocks.AIR, 0, 3);
		this.setBlock(x + 5, y + 9, z + 7, Blocks.AIR, 0, 3);
		this.setBlock(x + 6, y + 9, z + 7, Blocks.AIR, 0, 3);
		this.setBlock(x + 7, y + 9, z + 7, Blocks.AIR, 0, 3);
		this.setBlock(x + 8, y + 9, z + 7, Blocks.MOB_SPAWNER, 0, 3);
		this.setBlock(x + 9, y + 9, z + 7, Blocks.AIR, 0, 3);
		this.setBlock(x + 10, y + 9, z + 7, Blocks.STONEBRICK, 0, 3);
		this.setBlock(x + 0, y + 9, z + 8, Blocks.STONEBRICK, 0, 3);
		this.setBlock(x + 1, y + 9, z + 8, Blocks.STONEBRICK, 0, 3);
		this.setBlock(x + 2, y + 9, z + 8, Blocks.STONEBRICK, 0, 3);
		this.setBlock(x + 3, y + 9, z + 8, Blocks.STONEBRICK, 0, 3);
		this.setBlock(x + 4, y + 9, z + 8, Blocks.STONE_BRICK_STAIRS, 5, 3);
		this.setBlock(x + 5, y + 9, z + 8, Blocks.AIR, 0, 3);
		this.setBlock(x + 6, y + 9, z + 8, Blocks.AIR, 0, 3);
		this.setBlock(x + 7, y + 9, z + 8, Blocks.AIR, 0, 3);
		this.setBlock(x + 8, y + 9, z + 8, Blocks.AIR, 0, 3);
		this.setBlock(x + 9, y + 9, z + 8, Blocks.AIR, 0, 3);
		this.setBlock(x + 10, y + 9, z + 8, Blocks.STONEBRICK, 0, 3);
		this.setBlock(x + 1, y + 9, z + 9, Blocks.STONEBRICK, 0, 3);
		this.setBlock(x + 2, y + 9, z + 9, Blocks.STONEBRICK, 0, 3);
		this.setBlock(x + 3, y + 9, z + 9, Blocks.MOB_SPAWNER, 0, 3);
		this.setBlock(x + 4, y + 9, z + 9, Blocks.STONE_BRICK_STAIRS, 5, 3);
		this.setBlock(x + 5, y + 9, z + 9, Blocks.AIR, 0, 3);
		this.setBlock(x + 6, y + 9, z + 9, Blocks.AIR, 0, 3);
		this.setBlock(x + 7, y + 9, z + 9, Blocks.AIR, 0, 3);
		this.setBlock(x + 8, y + 9, z + 9, Blocks.AIR, 0, 3);
		this.setBlock(x + 9, y + 9, z + 9, Blocks.STONEBRICK, 0, 3);
		this.setBlock(x + 2, y + 9, z + 10, Blocks.STONEBRICK, 0, 3);
		this.setBlock(x + 3, y + 9, z + 10, Blocks.STONEBRICK, 0, 3);
		this.setBlock(x + 4, y + 9, z + 10, Blocks.STONEBRICK, 0, 3);
		this.setBlock(x + 5, y + 9, z + 10, Blocks.STONEBRICK, 0, 3);
		this.setBlock(x + 6, y + 9, z + 10, Blocks.STONEBRICK, 0, 3);
		this.setBlock(x + 7, y + 9, z + 10, Blocks.STONEBRICK, 0, 3);
		this.setBlock(x + 8, y + 9, z + 10, Blocks.STONEBRICK, 0, 3);
		this.setBlock(x + 2, y + 10, z + 0, Blocks.STONEBRICK, 0, 3);
		this.setBlock(x + 3, y + 10, z + 0, Blocks.STONEBRICK, 0, 3);
		this.setBlock(x + 4, y + 10, z + 0, Blocks.STONEBRICK, 0, 3);
		this.setBlock(x + 5, y + 10, z + 0, Blocks.STONEBRICK, 0, 3);
		this.setBlock(x + 6, y + 10, z + 0, Blocks.STONEBRICK, 0, 3);
		this.setBlock(x + 7, y + 10, z + 0, Blocks.STONEBRICK, 0, 3);
		this.setBlock(x + 8, y + 10, z + 0, Blocks.STONEBRICK, 0, 3);
		this.setBlock(x + 1, y + 10, z + 1, Blocks.STONEBRICK, 0, 3);
		this.setBlock(x + 2, y + 10, z + 1, Blocks.AIR, 0, 3);
		this.setBlock(x + 3, y + 10, z + 1, Blocks.AIR, 0, 3);
		this.setBlock(x + 4, y + 10, z + 1, Blocks.AIR, 0, 3);
		this.setBlock(x + 5, y + 10, z + 1, Blocks.AIR, 0, 3);
		this.setBlock(x + 6, y + 10, z + 1, Blocks.AIR, 0, 3);
		this.setBlock(x + 7, y + 10, z + 1, Blocks.AIR, 0, 3);
		this.setBlock(x + 8, y + 10, z + 1, Blocks.AIR, 0, 3);
		this.setBlock(x + 9, y + 10, z + 1, Blocks.STONEBRICK, 0, 3);
		this.setBlock(x + 0, y + 10, z + 2, Blocks.STONEBRICK, 0, 3);
		this.setBlock(x + 1, y + 10, z + 2, Blocks.AIR, 0, 3);
		this.setBlock(x + 2, y + 10, z + 2, Blocks.AIR, 0, 3);
		this.setBlock(x + 3, y + 10, z + 2, Blocks.AIR, 0, 3);
		this.setBlock(x + 4, y + 10, z + 2, Blocks.AIR, 0, 3);
		this.setBlock(x + 5, y + 10, z + 2, Blocks.AIR, 0, 3);
		this.setBlock(x + 6, y + 10, z + 2, Blocks.AIR, 0, 3);
		this.setBlock(x + 7, y + 10, z + 2, Blocks.AIR, 0, 3);
		this.setBlock(x + 8, y + 10, z + 2, Blocks.AIR, 0, 3);
		this.setBlock(x + 9, y + 10, z + 2, Blocks.AIR, 0, 3);
		this.setBlock(x + 10, y + 10, z + 2, Blocks.STONEBRICK, 0, 3);
		this.setBlock(x + 0, y + 10, z + 3, Blocks.STONEBRICK, 0, 3);
		this.setBlock(x + 1, y + 10, z + 3, Blocks.AIR, 0, 3);
		this.setBlock(x + 2, y + 10, z + 3, Blocks.AIR, 0, 3);
		this.setBlock(x + 3, y + 10, z + 3, Blocks.AIR, 0, 3);
		this.setBlock(x + 4, y + 10, z + 3, Blocks.AIR, 0, 3);
		this.setBlock(x + 5, y + 10, z + 3, Blocks.AIR, 0, 3);
		this.setBlock(x + 6, y + 10, z + 3, Blocks.AIR, 0, 3);
		this.setBlock(x + 7, y + 10, z + 3, Blocks.AIR, 0, 3);
		this.setBlock(x + 8, y + 10, z + 3, Blocks.AIR, 0, 3);
		this.setBlock(x + 9, y + 10, z + 3, Blocks.AIR, 0, 3);
		this.setBlock(x + 10, y + 10, z + 3, Blocks.STONEBRICK, 0, 3);
		this.setBlock(x + 0, y + 10, z + 4, Blocks.STONEBRICK, 0, 3);
		this.setBlock(x + 1, y + 10, z + 4, Blocks.AIR, 0, 3);
		this.setBlock(x + 2, y + 10, z + 4, Blocks.AIR, 0, 3);
		this.setBlock(x + 3, y + 10, z + 4, Blocks.AIR, 0, 3);
		this.setBlock(x + 4, y + 10, z + 4, Blocks.AIR, 0, 3);
		this.setBlock(x + 5, y + 10, z + 4, Blocks.AIR, 0, 3);
		this.setBlock(x + 6, y + 10, z + 4, Blocks.AIR, 0, 3);
		this.setBlock(x + 7, y + 10, z + 4, Blocks.AIR, 0, 3);
		this.setBlock(x + 8, y + 10, z + 4, Blocks.AIR, 0, 3);
		this.setBlock(x + 9, y + 10, z + 4, Blocks.AIR, 0, 3);
		this.setBlock(x + 10, y + 10, z + 4, Blocks.STONEBRICK, 0, 3);
		this.setBlock(x + 0, y + 10, z + 5, Blocks.STONE_SLAB, 5, 3);
		this.setBlock(x + 1, y + 10, z + 5, Blocks.AIR, 0, 3);
		this.setBlock(x + 2, y + 10, z + 5, Blocks.AIR, 0, 3);
		this.setBlock(x + 3, y + 10, z + 5, Blocks.AIR, 0, 3);
		this.setBlock(x + 4, y + 10, z + 5, Blocks.AIR, 0, 3);
		this.setBlock(x + 5, y + 10, z + 5, Blocks.AIR, 0, 3);
		this.setBlock(x + 6, y + 10, z + 5, Blocks.AIR, 0, 3);
		this.setBlock(x + 7, y + 10, z + 5, Blocks.AIR, 0, 3);
		this.setBlock(x + 8, y + 10, z + 5, Blocks.AIR, 0, 3);
		this.setBlock(x + 9, y + 10, z + 5, Blocks.AIR, 0, 3);
		this.setBlock(x + 10, y + 10, z + 5, Blocks.STONEBRICK, 0, 3);
		this.setBlock(x + 0, y + 10, z + 6, Blocks.STONEBRICK, 0, 3);
		this.setBlock(x + 1, y + 10, z + 6, Blocks.AIR, 0, 3);
		this.setBlock(x + 2, y + 10, z + 6, Blocks.AIR, 0, 3);
		this.setBlock(x + 3, y + 10, z + 6, Blocks.AIR, 0, 3);
		this.setBlock(x + 4, y + 10, z + 6, Blocks.AIR, 0, 3);
		this.setBlock(x + 5, y + 10, z + 6, Blocks.AIR, 0, 3);
		this.setBlock(x + 6, y + 10, z + 6, Blocks.AIR, 0, 3);
		this.setBlock(x + 7, y + 10, z + 6, Blocks.AIR, 0, 3);
		this.setBlock(x + 8, y + 10, z + 6, Blocks.AIR, 0, 3);
		this.setBlock(x + 9, y + 10, z + 6, Blocks.AIR, 0, 3);
		this.setBlock(x + 10, y + 10, z + 6, Blocks.STONEBRICK, 0, 3);
		this.setBlock(x + 0, y + 10, z + 7, Blocks.STONEBRICK, 0, 3);
		this.setBlock(x + 1, y + 10, z + 7, Blocks.AIR, 0, 3);
		this.setBlock(x + 2, y + 10, z + 7, Blocks.AIR, 0, 3);
		this.setBlock(x + 3, y + 10, z + 7, Blocks.AIR, 0, 3);
		this.setBlock(x + 4, y + 10, z + 7, Blocks.AIR, 0, 3);
		this.setBlock(x + 5, y + 10, z + 7, Blocks.AIR, 0, 3);
		this.setBlock(x + 6, y + 10, z + 7, Blocks.AIR, 0, 3);
		this.setBlock(x + 7, y + 10, z + 7, Blocks.AIR, 0, 3);
		this.setBlock(x + 8, y + 10, z + 7, Blocks.IRON_BARS, 0, 3);
		this.setBlock(x + 9, y + 10, z + 7, Blocks.AIR, 0, 3);
		this.setBlock(x + 10, y + 10, z + 7, Blocks.STONEBRICK, 0, 3);
		this.setBlock(x + 0, y + 10, z + 8, Blocks.STONEBRICK, 0, 3);
		this.setBlock(x + 1, y + 10, z + 8, Blocks.AIR, 0, 3);
		this.setBlock(x + 2, y + 10, z + 8, Blocks.AIR, 0, 3);
		this.setBlock(x + 3, y + 10, z + 8, Blocks.STONE_BRICK_STAIRS, 0, 3);
		this.setBlock(x + 4, y + 10, z + 8, Blocks.STONEBRICK, 0, 3);
		this.setBlock(x + 5, y + 10, z + 8, Blocks.STONE_BRICK_STAIRS, 5, 3);
		this.setBlock(x + 6, y + 10, z + 8, Blocks.AIR, 0, 3);
		this.setBlock(x + 7, y + 10, z + 8, Blocks.AIR, 0, 3);
		this.setBlock(x + 8, y + 10, z + 8, Blocks.AIR, 0, 3);
		this.setBlock(x + 9, y + 10, z + 8, Blocks.AIR, 0, 3);
		this.setBlock(x + 10, y + 10, z + 8, Blocks.STONEBRICK, 0, 3);
		this.setBlock(x + 1, y + 10, z + 9, Blocks.STONEBRICK, 0, 3);
		this.setBlock(x + 2, y + 10, z + 9, Blocks.AIR, 0, 3);
		this.setBlock(x + 3, y + 10, z + 9, Blocks.STONE_BRICK_STAIRS, 0, 3);
		this.setBlock(x + 4, y + 10, z + 9, Blocks.STONEBRICK, 0, 3);
		this.setBlock(x + 5, y + 10, z + 9, Blocks.STONE_BRICK_STAIRS, 5, 3);
		this.setBlock(x + 6, y + 10, z + 9, Blocks.AIR, 0, 3);
		this.setBlock(x + 7, y + 10, z + 9, Blocks.AIR, 0, 3);
		this.setBlock(x + 8, y + 10, z + 9, Blocks.AIR, 0, 3);
		this.setBlock(x + 9, y + 10, z + 9, Blocks.STONEBRICK, 0, 3);
		this.setBlock(x + 2, y + 10, z + 10, Blocks.STONEBRICK, 0, 3);
		this.setBlock(x + 3, y + 10, z + 10, Blocks.STONEBRICK, 0, 3);
		this.setBlock(x + 4, y + 10, z + 10, Blocks.STONEBRICK, 0, 3);
		this.setBlock(x + 5, y + 10, z + 10, Blocks.STONEBRICK, 0, 3);
		this.setBlock(x + 6, y + 10, z + 10, Blocks.STONEBRICK, 0, 3);
		this.setBlock(x + 7, y + 10, z + 10, Blocks.STONEBRICK, 0, 3);
		this.setBlock(x + 8, y + 10, z + 10, Blocks.STONEBRICK, 0, 3);
		this.setBlock(x + 2, y + 11, z + 0, Blocks.STONEBRICK, 0, 3);
		this.setBlock(x + 3, y + 11, z + 0, Blocks.STONEBRICK, 0, 3);
		this.setBlock(x + 4, y + 11, z + 0, Blocks.STONEBRICK, 0, 3);
		this.setBlock(x + 5, y + 11, z + 0, Blocks.STONEBRICK, 0, 3);
		this.setBlock(x + 6, y + 11, z + 0, Blocks.STONEBRICK, 0, 3);
		this.setBlock(x + 7, y + 11, z + 0, Blocks.STONEBRICK, 0, 3);
		this.setBlock(x + 8, y + 11, z + 0, Blocks.STONEBRICK, 0, 3);
		this.setBlock(x + 1, y + 11, z + 1, Blocks.STONEBRICK, 0, 3);
		this.setBlock(x + 2, y + 11, z + 1, Blocks.AIR, 0, 3);
		this.setBlock(x + 3, y + 11, z + 1, Blocks.AIR, 0, 3);
		this.setBlock(x + 4, y + 11, z + 1, Blocks.AIR, 0, 3);
		this.setBlock(x + 5, y + 11, z + 1, Blocks.AIR, 0, 3);
		this.setBlock(x + 6, y + 11, z + 1, Blocks.AIR, 0, 3);
		this.setBlock(x + 7, y + 11, z + 1, Blocks.AIR, 0, 3);
		this.setBlock(x + 8, y + 11, z + 1, Blocks.AIR, 0, 3);
		this.setBlock(x + 9, y + 11, z + 1, Blocks.STONEBRICK, 0, 3);
		this.setBlock(x + 0, y + 11, z + 2, Blocks.STONEBRICK, 0, 3);
		this.setBlock(x + 1, y + 11, z + 2, Blocks.AIR, 0, 3);
		this.setBlock(x + 2, y + 11, z + 2, Blocks.AIR, 0, 3);
		this.setBlock(x + 3, y + 11, z + 2, Blocks.AIR, 0, 3);
		this.setBlock(x + 4, y + 11, z + 2, Blocks.AIR, 0, 3);
		this.setBlock(x + 5, y + 11, z + 2, Blocks.AIR, 0, 3);
		this.setBlock(x + 6, y + 11, z + 2, Blocks.AIR, 0, 3);
		this.setBlock(x + 7, y + 11, z + 2, Blocks.AIR, 0, 3);
		this.setBlock(x + 8, y + 11, z + 2, Blocks.AIR, 0, 3);
		this.setBlock(x + 9, y + 11, z + 2, Blocks.AIR, 0, 3);
		this.setBlock(x + 10, y + 11, z + 2, Blocks.STONEBRICK, 0, 3);
		this.setBlock(x + 0, y + 11, z + 3, Blocks.STONEBRICK, 0, 3);
		this.setBlock(x + 1, y + 11, z + 3, Blocks.AIR, 0, 3);
		this.setBlock(x + 2, y + 11, z + 3, Blocks.AIR, 0, 3);
		this.setBlock(x + 3, y + 11, z + 3, Blocks.AIR, 0, 3);
		this.setBlock(x + 4, y + 11, z + 3, Blocks.AIR, 0, 3);
		this.setBlock(x + 5, y + 11, z + 3, Blocks.AIR, 0, 3);
		this.setBlock(x + 6, y + 11, z + 3, Blocks.AIR, 0, 3);
		this.setBlock(x + 7, y + 11, z + 3, Blocks.AIR, 0, 3);
		this.setBlock(x + 8, y + 11, z + 3, Blocks.AIR, 0, 3);
		this.setBlock(x + 9, y + 11, z + 3, Blocks.AIR, 0, 3);
		this.setBlock(x + 10, y + 11, z + 3, Blocks.STONEBRICK, 0, 3);
		this.setBlock(x + 0, y + 11, z + 4, Blocks.STONEBRICK, 0, 3);
		this.setBlock(x + 1, y + 11, z + 4, Blocks.AIR, 0, 3);
		this.setBlock(x + 2, y + 11, z + 4, Blocks.AIR, 0, 3);
		this.setBlock(x + 3, y + 11, z + 4, Blocks.AIR, 0, 3);
		this.setBlock(x + 4, y + 11, z + 4, Blocks.AIR, 0, 3);
		this.setBlock(x + 5, y + 11, z + 4, Blocks.AIR, 0, 3);
		this.setBlock(x + 6, y + 11, z + 4, Blocks.AIR, 0, 3);
		this.setBlock(x + 7, y + 11, z + 4, Blocks.AIR, 0, 3);
		this.setBlock(x + 8, y + 11, z + 4, Blocks.AIR, 0, 3);
		this.setBlock(x + 9, y + 11, z + 4, Blocks.AIR, 0, 3);
		this.setBlock(x + 10, y + 11, z + 4, Blocks.STONEBRICK, 0, 3);
		this.setBlock(x + 0, y + 11, z + 5, Blocks.STONE_SLAB, 13, 3);
		this.setBlock(x + 1, y + 11, z + 5, Blocks.AIR, 0, 3);
		this.setBlock(x + 2, y + 11, z + 5, Blocks.AIR, 0, 3);
		this.setBlock(x + 3, y + 11, z + 5, Blocks.AIR, 0, 3);
		this.setBlock(x + 4, y + 11, z + 5, Blocks.AIR, 0, 3);
		this.setBlock(x + 5, y + 11, z + 5, Blocks.AIR, 0, 3);
		this.setBlock(x + 6, y + 11, z + 5, Blocks.AIR, 0, 3);
		this.setBlock(x + 7, y + 11, z + 5, Blocks.AIR, 0, 3);
		this.setBlock(x + 8, y + 11, z + 5, Blocks.AIR, 0, 3);
		this.setBlock(x + 9, y + 11, z + 5, Blocks.AIR, 0, 3);
		this.setBlock(x + 10, y + 11, z + 5, Blocks.STONEBRICK, 0, 3);
		this.setBlock(x + 0, y + 11, z + 6, Blocks.STONEBRICK, 0, 3);
		this.setBlock(x + 1, y + 11, z + 6, Blocks.AIR, 0, 3);
		this.setBlock(x + 2, y + 11, z + 6, Blocks.AIR, 0, 3);
		this.setBlock(x + 3, y + 11, z + 6, Blocks.AIR, 0, 3);
		this.setBlock(x + 4, y + 11, z + 6, Blocks.AIR, 0, 3);
		this.setBlock(x + 5, y + 11, z + 6, Blocks.AIR, 0, 3);
		this.setBlock(x + 6, y + 11, z + 6, Blocks.AIR, 0, 3);
		this.setBlock(x + 7, y + 11, z + 6, Blocks.AIR, 0, 3);
		this.setBlock(x + 8, y + 11, z + 6, Blocks.AIR, 0, 3);
		this.setBlock(x + 9, y + 11, z + 6, Blocks.AIR, 0, 3);
		this.setBlock(x + 10, y + 11, z + 6, Blocks.STONEBRICK, 0, 3);
		this.setBlock(x + 0, y + 11, z + 7, Blocks.STONEBRICK, 0, 3);
		this.setBlock(x + 1, y + 11, z + 7, Blocks.AIR, 0, 3);
		this.setBlock(x + 2, y + 11, z + 7, Blocks.AIR, 0, 3);
		this.setBlock(x + 3, y + 11, z + 7, Blocks.AIR, 0, 3);
		this.setBlock(x + 4, y + 11, z + 7, Blocks.AIR, 0, 3);
		this.setBlock(x + 5, y + 11, z + 7, Blocks.AIR, 0, 3);
		this.setBlock(x + 6, y + 11, z + 7, Blocks.AIR, 0, 3);
		this.setBlock(x + 7, y + 11, z + 7, Blocks.AIR, 0, 3);
		this.setBlock(x + 8, y + 11, z + 7, Blocks.IRON_BARS, 0, 3);
		this.setBlock(x + 9, y + 11, z + 7, Blocks.AIR, 0, 3);
		this.setBlock(x + 10, y + 11, z + 7, Blocks.STONEBRICK, 0, 3);
		this.setBlock(x + 0, y + 11, z + 8, Blocks.STONEBRICK, 0, 3);
		this.setBlock(x + 1, y + 11, z + 8, Blocks.AIR, 0, 3);
		this.setBlock(x + 2, y + 11, z + 8, Blocks.AIR, 0, 3);
		this.setBlock(x + 3, y + 11, z + 8, Blocks.AIR, 0, 3);
		this.setBlock(x + 4, y + 11, z + 8, Blocks.STONE_BRICK_STAIRS, 0, 3);
		this.setBlock(x + 5, y + 11, z + 8, Blocks.STONEBRICK, 0, 3);
		this.setBlock(x + 6, y + 11, z + 8, Blocks.STONE_BRICK_STAIRS, 5, 3);
		this.setBlock(x + 7, y + 11, z + 8, Blocks.AIR, 0, 3);
		this.setBlock(x + 8, y + 11, z + 8, Blocks.AIR, 0, 3);
		this.setBlock(x + 9, y + 11, z + 8, Blocks.AIR, 0, 3);
		this.setBlock(x + 10, y + 11, z + 8, Blocks.STONEBRICK, 0, 3);
		this.setBlock(x + 1, y + 11, z + 9, Blocks.STONEBRICK, 0, 3);
		this.setBlock(x + 2, y + 11, z + 9, Blocks.AIR, 0, 3);
		this.setBlock(x + 3, y + 11, z + 9, Blocks.AIR, 0, 3);
		this.setBlock(x + 4, y + 11, z + 9, Blocks.STONE_BRICK_STAIRS, 0, 3);
		this.setBlock(x + 5, y + 11, z + 9, Blocks.STONEBRICK, 0, 3);
		this.setBlock(x + 6, y + 11, z + 9, Blocks.STONE_BRICK_STAIRS, 5, 3);
		this.setBlock(x + 7, y + 11, z + 9, Blocks.AIR, 0, 3);
		this.setBlock(x + 8, y + 11, z + 9, Blocks.AIR, 0, 3);
		this.setBlock(x + 9, y + 11, z + 9, Blocks.STONEBRICK, 0, 3);
		this.setBlock(x + 2, y + 11, z + 10, Blocks.STONEBRICK, 0, 3);
		this.setBlock(x + 3, y + 11, z + 10, Blocks.STONEBRICK, 0, 3);
		this.setBlock(x + 4, y + 11, z + 10, Blocks.STONEBRICK, 0, 3);
		this.setBlock(x + 5, y + 11, z + 10, Blocks.STONEBRICK, 0, 3);
		this.setBlock(x + 6, y + 11, z + 10, Blocks.STONEBRICK, 0, 3);
		this.setBlock(x + 7, y + 11, z + 10, Blocks.STONEBRICK, 0, 3);
		this.setBlock(x + 8, y + 11, z + 10, Blocks.STONEBRICK, 0, 3);
		this.setBlock(x + 2, y + 12, z + 0, Blocks.STONEBRICK, 0, 3);
		this.setBlock(x + 3, y + 12, z + 0, Blocks.STONEBRICK, 0, 3);
		this.setBlock(x + 4, y + 12, z + 0, Blocks.STONEBRICK, 0, 3);
		this.setBlock(x + 5, y + 12, z + 0, Blocks.STONEBRICK, 0, 3);
		this.setBlock(x + 6, y + 12, z + 0, Blocks.STONEBRICK, 0, 3);
		this.setBlock(x + 7, y + 12, z + 0, Blocks.STONEBRICK, 0, 3);
		this.setBlock(x + 8, y + 12, z + 0, Blocks.STONEBRICK, 0, 3);
		this.setBlock(x + 1, y + 12, z + 1, Blocks.STONEBRICK, 0, 3);
		this.setBlock(x + 2, y + 12, z + 1, Blocks.AIR, 0, 3);
		this.setBlock(x + 3, y + 12, z + 1, Blocks.AIR, 0, 3);
		this.setBlock(x + 4, y + 12, z + 1, Blocks.AIR, 0, 3);
		this.setBlock(x + 5, y + 12, z + 1, Blocks.AIR, 0, 3);
		this.setBlock(x + 6, y + 12, z + 1, Blocks.AIR, 0, 3);
		this.setBlock(x + 7, y + 12, z + 1, Blocks.AIR, 0, 3);
		this.setBlock(x + 8, y + 12, z + 1, Blocks.AIR, 0, 3);
		this.setBlock(x + 9, y + 12, z + 1, Blocks.STONEBRICK, 0, 3);
		this.setBlock(x + 0, y + 12, z + 2, Blocks.STONEBRICK, 0, 3);
		this.setBlock(x + 1, y + 12, z + 2, Blocks.AIR, 0, 3);
		this.setBlock(x + 2, y + 12, z + 2, Blocks.AIR, 0, 3);
		this.setBlock(x + 3, y + 12, z + 2, Blocks.AIR, 0, 3);
		this.setBlock(x + 4, y + 12, z + 2, Blocks.AIR, 0, 3);
		this.setBlock(x + 5, y + 12, z + 2, Blocks.AIR, 0, 3);
		this.setBlock(x + 6, y + 12, z + 2, Blocks.AIR, 0, 3);
		this.setBlock(x + 7, y + 12, z + 2, Blocks.AIR, 0, 3);
		this.setBlock(x + 8, y + 12, z + 2, Blocks.AIR, 0, 3);
		this.setBlock(x + 9, y + 12, z + 2, Blocks.AIR, 0, 3);
		this.setBlock(x + 10, y + 12, z + 2, Blocks.STONEBRICK, 0, 3);
		this.setBlock(x + 0, y + 12, z + 3, Blocks.STONEBRICK, 0, 3);
		this.setBlock(x + 1, y + 12, z + 3, Blocks.AIR, 0, 3);
		this.setBlock(x + 2, y + 12, z + 3, Blocks.AIR, 0, 3);
		this.setBlock(x + 3, y + 12, z + 3, Blocks.AIR, 0, 3);
		this.setBlock(x + 4, y + 12, z + 3, Blocks.AIR, 0, 3);
		this.setBlock(x + 5, y + 12, z + 3, Blocks.AIR, 0, 3);
		this.setBlock(x + 6, y + 12, z + 3, Blocks.AIR, 0, 3);
		this.setBlock(x + 7, y + 12, z + 3, Blocks.AIR, 0, 3);
		this.setBlock(x + 8, y + 12, z + 3, Blocks.AIR, 0, 3);
		this.setBlock(x + 9, y + 12, z + 3, Blocks.AIR, 0, 3);
		this.setBlock(x + 10, y + 12, z + 3, Blocks.STONEBRICK, 0, 3);
		this.setBlock(x + 0, y + 12, z + 4, Blocks.STONEBRICK, 0, 3);
		this.setBlock(x + 1, y + 12, z + 4, Blocks.AIR, 0, 3);
		this.setBlock(x + 2, y + 12, z + 4, Blocks.AIR, 0, 3);
		this.setBlock(x + 3, y + 12, z + 4, Blocks.AIR, 0, 3);

		generate_r02(world, rand, x, y, z);
		return true;

	}
	public boolean generate_r02(World world, Random rand, int x, int y, int z)
	{

		this.setBlock(x + 4, y + 12, z + 4, Blocks.AIR, 0, 3);
		this.setBlock(x + 5, y + 12, z + 4, Blocks.AIR, 0, 3);
		this.setBlock(x + 6, y + 12, z + 4, Blocks.AIR, 0, 3);
		this.setBlock(x + 7, y + 12, z + 4, Blocks.AIR, 0, 3);
		this.setBlock(x + 8, y + 12, z + 4, Blocks.AIR, 0, 3);
		this.setBlock(x + 9, y + 12, z + 4, Blocks.AIR, 0, 3);
		this.setBlock(x + 10, y + 12, z + 4, Blocks.STONEBRICK, 0, 3);
		this.setBlock(x + 0, y + 12, z + 5, Blocks.STONEBRICK, 0, 3);
		this.setBlock(x + 1, y + 12, z + 5, Blocks.AIR, 0, 3);
		this.setBlock(x + 2, y + 12, z + 5, Blocks.AIR, 0, 3);
		this.setBlock(x + 3, y + 12, z + 5, Blocks.AIR, 0, 3);
		this.setBlock(x + 4, y + 12, z + 5, Blocks.AIR, 0, 3);
		this.setBlock(x + 5, y + 12, z + 5, Blocks.AIR, 0, 3);
		this.setBlock(x + 6, y + 12, z + 5, Blocks.AIR, 0, 3);
		this.setBlock(x + 7, y + 12, z + 5, Blocks.AIR, 0, 3);
		this.setBlock(x + 8, y + 12, z + 5, Blocks.AIR, 0, 3);
		this.setBlock(x + 9, y + 12, z + 5, Blocks.AIR, 0, 3);
		this.setBlock(x + 10, y + 12, z + 5, Blocks.STONEBRICK, 0, 3);
		this.setBlock(x + 0, y + 12, z + 6, Blocks.STONEBRICK, 0, 3);
		this.setBlock(x + 1, y + 12, z + 6, Blocks.AIR, 0, 3);
		this.setBlock(x + 2, y + 12, z + 6, Blocks.AIR, 0, 3);
		this.setBlock(x + 3, y + 12, z + 6, Blocks.AIR, 0, 3);
		this.setBlock(x + 4, y + 12, z + 6, Blocks.AIR, 0, 3);
		this.setBlock(x + 5, y + 12, z + 6, Blocks.AIR, 0, 3);
		this.setBlock(x + 6, y + 12, z + 6, Blocks.AIR, 0, 3);
		this.setBlock(x + 7, y + 12, z + 6, Blocks.AIR, 0, 3);
		this.setBlock(x + 8, y + 12, z + 6, Blocks.AIR, 0, 3);
		this.setBlock(x + 9, y + 12, z + 6, Blocks.AIR, 0, 3);
		this.setBlock(x + 10, y + 12, z + 6, Blocks.STONEBRICK, 0, 3);
		this.setBlock(x + 0, y + 12, z + 7, Blocks.STONEBRICK, 0, 3);
		this.setBlock(x + 1, y + 12, z + 7, Blocks.AIR, 0, 3);
		this.setBlock(x + 2, y + 12, z + 7, Blocks.AIR, 0, 3);
		this.setBlock(x + 3, y + 12, z + 7, Blocks.AIR, 0, 3);
		this.setBlock(x + 4, y + 12, z + 7, Blocks.AIR, 0, 3);
		this.setBlock(x + 5, y + 12, z + 7, Blocks.AIR, 0, 3);
		this.setBlock(x + 6, y + 12, z + 7, Blocks.AIR, 0, 3);
		this.setBlock(x + 7, y + 12, z + 7, Blocks.AIR, 0, 3);
		this.setBlock(x + 8, y + 12, z + 7, Blocks.IRON_BARS, 0, 3);
		this.setBlock(x + 9, y + 12, z + 7, Blocks.AIR, 0, 3);
		this.setBlock(x + 10, y + 12, z + 7, Blocks.STONEBRICK, 0, 3);
		this.setBlock(x + 0, y + 12, z + 8, Blocks.STONEBRICK, 0, 3);
		this.setBlock(x + 1, y + 12, z + 8, Blocks.AIR, 0, 3);
		this.setBlock(x + 2, y + 12, z + 8, Blocks.AIR, 0, 3);
		this.setBlock(x + 3, y + 12, z + 8, Blocks.AIR, 0, 3);
		this.setBlock(x + 4, y + 12, z + 8, Blocks.AIR, 0, 3);
		this.setBlock(x + 5, y + 12, z + 8, Blocks.STONE_BRICK_STAIRS, 0, 3);
		this.setBlock(x + 6, y + 12, z + 8, Blocks.STONEBRICK, 0, 3);
		this.setBlock(x + 7, y + 12, z + 8, Blocks.STONE_BRICK_STAIRS, 5, 3);
		this.setBlock(x + 8, y + 12, z + 8, Blocks.AIR, 0, 3);
		this.setBlock(x + 9, y + 12, z + 8, Blocks.AIR, 0, 3);
		this.setBlock(x + 10, y + 12, z + 8, Blocks.STONEBRICK, 0, 3);
		this.setBlock(x + 1, y + 12, z + 9, Blocks.STONEBRICK, 0, 3);
		this.setBlock(x + 2, y + 12, z + 9, Blocks.AIR, 0, 3);
		this.setBlock(x + 3, y + 12, z + 9, Blocks.AIR, 0, 3);
		this.setBlock(x + 4, y + 12, z + 9, Blocks.AIR, 0, 3);
		this.setBlock(x + 5, y + 12, z + 9, Blocks.STONE_BRICK_STAIRS, 0, 3);
		this.setBlock(x + 6, y + 12, z + 9, Blocks.STONEBRICK, 0, 3);
		this.setBlock(x + 7, y + 12, z + 9, Blocks.STONE_BRICK_STAIRS, 5, 3);
		this.setBlock(x + 8, y + 12, z + 9, Blocks.AIR, 0, 3);
		this.setBlock(x + 9, y + 12, z + 9, Blocks.STONEBRICK, 0, 3);
		this.setBlock(x + 2, y + 12, z + 10, Blocks.STONEBRICK, 0, 3);
		this.setBlock(x + 3, y + 12, z + 10, Blocks.STONEBRICK, 0, 3);
		this.setBlock(x + 4, y + 12, z + 10, Blocks.STONEBRICK, 0, 3);
		this.setBlock(x + 5, y + 12, z + 10, Blocks.STONEBRICK, 0, 3);
		this.setBlock(x + 6, y + 12, z + 10, Blocks.STONEBRICK, 0, 3);
		this.setBlock(x + 7, y + 12, z + 10, Blocks.STONEBRICK, 0, 3);
		this.setBlock(x + 8, y + 12, z + 10, Blocks.STONEBRICK, 0, 3);
		this.setBlock(x + 2, y + 13, z + 0, Blocks.STONEBRICK, 0, 3);
		this.setBlock(x + 3, y + 13, z + 0, Blocks.STONEBRICK, 0, 3);
		this.setBlock(x + 4, y + 13, z + 0, Blocks.STONEBRICK, 0, 3);
		this.setBlock(x + 5, y + 13, z + 0, Blocks.STONEBRICK, 0, 3);
		this.setBlock(x + 6, y + 13, z + 0, Blocks.STONEBRICK, 0, 3);
		this.setBlock(x + 7, y + 13, z + 0, Blocks.STONEBRICK, 0, 3);
		this.setBlock(x + 8, y + 13, z + 0, Blocks.STONEBRICK, 0, 3);
		this.setBlock(x + 1, y + 13, z + 1, Blocks.STONEBRICK, 0, 3);
		this.setBlock(x + 2, y + 13, z + 1, Blocks.AIR, 0, 3);
		this.setBlock(x + 3, y + 13, z + 1, Blocks.AIR, 0, 3);
		this.setBlock(x + 4, y + 13, z + 1, Blocks.AIR, 0, 3);
		this.setBlock(x + 5, y + 13, z + 1, Blocks.AIR, 0, 3);
		this.setBlock(x + 6, y + 13, z + 1, Blocks.AIR, 0, 3);
		this.setBlock(x + 7, y + 13, z + 1, Blocks.AIR, 0, 3);
		this.setBlock(x + 8, y + 13, z + 1, Blocks.AIR, 0, 3);
		this.setBlock(x + 9, y + 13, z + 1, Blocks.STONEBRICK, 0, 3);
		this.setBlock(x + 0, y + 13, z + 2, Blocks.STONEBRICK, 0, 3);
		this.setBlock(x + 1, y + 13, z + 2, Blocks.AIR, 0, 3);
		this.setBlock(x + 2, y + 13, z + 2, Blocks.AIR, 0, 3);
		this.setBlock(x + 3, y + 13, z + 2, Blocks.AIR, 0, 3);
		this.setBlock(x + 4, y + 13, z + 2, Blocks.AIR, 0, 3);
		this.setBlock(x + 5, y + 13, z + 2, Blocks.AIR, 0, 3);
		this.setBlock(x + 6, y + 13, z + 2, Blocks.AIR, 0, 3);
		this.setBlock(x + 7, y + 13, z + 2, Blocks.AIR, 0, 3);
		this.setBlock(x + 8, y + 13, z + 2, Blocks.AIR, 0, 3);
		this.setBlock(x + 9, y + 13, z + 2, Blocks.AIR, 0, 3);
		this.setBlock(x + 10, y + 13, z + 2, Blocks.STONEBRICK, 0, 3);
		this.setBlock(x + 0, y + 13, z + 3, Blocks.STONEBRICK, 0, 3);
		this.setBlock(x + 1, y + 13, z + 3, Blocks.AIR, 0, 3);
		this.setBlock(x + 2, y + 13, z + 3, Blocks.AIR, 0, 3);
		this.setBlock(x + 3, y + 13, z + 3, Blocks.AIR, 0, 3);
		this.setBlock(x + 4, y + 13, z + 3, Blocks.AIR, 0, 3);
		this.setBlock(x + 5, y + 13, z + 3, Blocks.AIR, 0, 3);
		this.setBlock(x + 6, y + 13, z + 3, Blocks.AIR, 0, 3);
		this.setBlock(x + 7, y + 13, z + 3, Blocks.AIR, 0, 3);
		this.setBlock(x + 8, y + 13, z + 3, Blocks.AIR, 0, 3);
		this.setBlock(x + 9, y + 13, z + 3, Blocks.AIR, 0, 3);
		this.setBlock(x + 10, y + 13, z + 3, Blocks.STONEBRICK, 0, 3);
		this.setBlock(x + 0, y + 13, z + 4, Blocks.STONEBRICK, 0, 3);
		this.setBlock(x + 1, y + 13, z + 4, Blocks.AIR, 0, 3);
		this.setBlock(x + 2, y + 13, z + 4, Blocks.AIR, 0, 3);
		this.setBlock(x + 3, y + 13, z + 4, Blocks.AIR, 0, 3);
		this.setBlock(x + 4, y + 13, z + 4, Blocks.AIR, 0, 3);
		this.setBlock(x + 5, y + 13, z + 4, Blocks.AIR, 0, 3);
		this.setBlock(x + 6, y + 13, z + 4, Blocks.AIR, 0, 3);
		this.setBlock(x + 7, y + 13, z + 4, Blocks.AIR, 0, 3);
		this.setBlock(x + 8, y + 13, z + 4, Blocks.AIR, 0, 3);
		this.setBlock(x + 9, y + 13, z + 4, Blocks.AIR, 0, 3);
		this.setBlock(x + 10, y + 13, z + 4, Blocks.STONEBRICK, 0, 3);
		this.setBlock(x + 0, y + 13, z + 5, Blocks.STONEBRICK, 0, 3);
		this.setBlock(x + 1, y + 13, z + 5, Blocks.AIR, 0, 3);
		this.setBlock(x + 2, y + 13, z + 5, Blocks.AIR, 0, 3);
		this.setBlock(x + 3, y + 13, z + 5, Blocks.AIR, 0, 3);
		this.setBlock(x + 4, y + 13, z + 5, Blocks.AIR, 0, 3);
		this.setBlock(x + 5, y + 13, z + 5, Blocks.AIR, 0, 3);
		this.setBlock(x + 6, y + 13, z + 5, Blocks.AIR, 0, 3);
		this.setBlock(x + 7, y + 13, z + 5, Blocks.AIR, 0, 3);
		this.setBlock(x + 8, y + 13, z + 5, Blocks.AIR, 0, 3);
		this.setBlock(x + 9, y + 13, z + 5, Blocks.AIR, 0, 3);
		this.setBlock(x + 10, y + 13, z + 5, Blocks.STONEBRICK, 0, 3);
		this.setBlock(x + 0, y + 13, z + 6, Blocks.STONEBRICK, 0, 3);
		this.setBlock(x + 1, y + 13, z + 6, Blocks.AIR, 0, 3);
		this.setBlock(x + 2, y + 13, z + 6, Blocks.AIR, 0, 3);
		this.setBlock(x + 3, y + 13, z + 6, Blocks.AIR, 0, 3);
		this.setBlock(x + 4, y + 13, z + 6, Blocks.AIR, 0, 3);
		this.setBlock(x + 5, y + 13, z + 6, Blocks.AIR, 0, 3);
		this.setBlock(x + 6, y + 13, z + 6, Blocks.AIR, 0, 3);
		this.setBlock(x + 7, y + 13, z + 6, Blocks.AIR, 0, 3);
		this.setBlock(x + 8, y + 13, z + 6, Blocks.AIR, 0, 3);
		this.setBlock(x + 9, y + 13, z + 6, Blocks.AIR, 0, 3);
		this.setBlock(x + 10, y + 13, z + 6, Blocks.STONEBRICK, 0, 3);
		this.setBlock(x + 0, y + 13, z + 7, Blocks.STONEBRICK, 0, 3);
		this.setBlock(x + 1, y + 13, z + 7, Blocks.AIR, 0, 3);
		this.setBlock(x + 2, y + 13, z + 7, Blocks.AIR, 0, 3);
		this.setBlock(x + 3, y + 13, z + 7, Blocks.AIR, 0, 3);
		this.setBlock(x + 4, y + 13, z + 7, Blocks.AIR, 0, 3);
		this.setBlock(x + 5, y + 13, z + 7, Blocks.AIR, 0, 3);
		this.setBlock(x + 6, y + 13, z + 7, Blocks.AIR, 0, 3);
		this.setBlock(x + 7, y + 13, z + 7, Blocks.AIR, 0, 3);
		this.setBlock(x + 8, y + 13, z + 7, Blocks.STONE_BRICK_STAIRS, 6, 3);
		this.setBlock(x + 9, y + 13, z + 7, Blocks.STONE_BRICK_STAIRS, 6, 3);
		this.setBlock(x + 10, y + 13, z + 7, Blocks.STONEBRICK, 0, 3);
		this.setBlock(x + 0, y + 13, z + 8, Blocks.STONEBRICK, 0, 3);
		this.setBlock(x + 1, y + 13, z + 8, Blocks.AIR, 0, 3);
		this.setBlock(x + 2, y + 13, z + 8, Blocks.AIR, 0, 3);
		this.setBlock(x + 3, y + 13, z + 8, Blocks.AIR, 0, 3);
		this.setBlock(x + 4, y + 13, z + 8, Blocks.AIR, 0, 3);
		this.setBlock(x + 5, y + 13, z + 8, Blocks.AIR, 0, 3);
		this.setBlock(x + 6, y + 13, z + 8, Blocks.STONE_BRICK_STAIRS, 0, 3);
		this.setBlock(x + 7, y + 13, z + 8, Blocks.STONEBRICK, 0, 3);
		this.setBlock(x + 8, y + 13, z + 8, Blocks.STONEBRICK, 0, 3);
		this.setBlock(x + 9, y + 13, z + 8, Blocks.STONEBRICK, 0, 3);
		this.setBlock(x + 10, y + 13, z + 8, Blocks.STONEBRICK, 0, 3);
		this.setBlock(x + 1, y + 13, z + 9, Blocks.STONEBRICK, 0, 3);
		this.setBlock(x + 2, y + 13, z + 9, Blocks.AIR, 0, 3);
		this.setBlock(x + 3, y + 13, z + 9, Blocks.AIR, 0, 3);
		this.setBlock(x + 4, y + 13, z + 9, Blocks.AIR, 0, 3);
		this.setBlock(x + 5, y + 13, z + 9, Blocks.AIR, 0, 3);
		this.setBlock(x + 6, y + 13, z + 9, Blocks.STONE_BRICK_STAIRS, 0, 3);
		this.setBlock(x + 7, y + 13, z + 9, Blocks.STONEBRICK, 0, 3);
		this.setBlock(x + 8, y + 13, z + 9, Blocks.STONEBRICK, 0, 3);
		this.setBlock(x + 9, y + 13, z + 9, Blocks.STONEBRICK, 0, 3);
		this.setBlock(x + 2, y + 13, z + 10, Blocks.STONEBRICK, 0, 3);
		this.setBlock(x + 3, y + 13, z + 10, Blocks.STONEBRICK, 0, 3);
		this.setBlock(x + 4, y + 13, z + 10, Blocks.STONEBRICK, 0, 3);
		this.setBlock(x + 5, y + 13, z + 10, Blocks.STONEBRICK, 0, 3);
		this.setBlock(x + 6, y + 13, z + 10, Blocks.STONEBRICK, 0, 3);
		this.setBlock(x + 7, y + 13, z + 10, Blocks.STONEBRICK, 0, 3);
		this.setBlock(x + 8, y + 13, z + 10, Blocks.STONEBRICK, 0, 3);
		this.setBlock(x + 2, y + 14, z + 0, Blocks.STONEBRICK, 0, 3);
		this.setBlock(x + 3, y + 14, z + 0, Blocks.STONEBRICK, 0, 3);
		this.setBlock(x + 4, y + 14, z + 0, Blocks.STONEBRICK, 0, 3);
		this.setBlock(x + 5, y + 14, z + 0, Blocks.STONEBRICK, 0, 3);
		this.setBlock(x + 6, y + 14, z + 0, Blocks.STONEBRICK, 0, 3);
		this.setBlock(x + 7, y + 14, z + 0, Blocks.STONEBRICK, 0, 3);
		this.setBlock(x + 8, y + 14, z + 0, Blocks.STONEBRICK, 0, 3);
		this.setBlock(x + 1, y + 14, z + 1, Blocks.STONEBRICK, 0, 3);
		this.setBlock(x + 2, y + 14, z + 1, Blocks.AIR, 0, 3);
		this.setBlock(x + 3, y + 14, z + 1, Blocks.AIR, 0, 3);
		this.setBlock(x + 4, y + 14, z + 1, Blocks.AIR, 0, 3);
		this.setBlock(x + 5, y + 14, z + 1, Blocks.AIR, 0, 3);
		this.setBlock(x + 6, y + 14, z + 1, Blocks.AIR, 0, 3);
		this.setBlock(x + 7, y + 14, z + 1, Blocks.AIR, 0, 3);
		this.setBlock(x + 8, y + 14, z + 1, Blocks.AIR, 0, 3);
		this.setBlock(x + 9, y + 14, z + 1, Blocks.STONEBRICK, 0, 3);
		this.setBlock(x + 0, y + 14, z + 2, Blocks.STONEBRICK, 0, 3);
		this.setBlock(x + 1, y + 14, z + 2, Blocks.AIR, 0, 3);
		this.setBlock(x + 2, y + 14, z + 2, Blocks.AIR, 0, 3);
		this.setBlock(x + 3, y + 14, z + 2, Blocks.AIR, 0, 3);
		this.setBlock(x + 4, y + 14, z + 2, Blocks.AIR, 0, 3);
		this.setBlock(x + 5, y + 14, z + 2, Blocks.AIR, 0, 3);
		this.setBlock(x + 6, y + 14, z + 2, Blocks.AIR, 0, 3);
		this.setBlock(x + 7, y + 14, z + 2, Blocks.MOB_SPAWNER, 0, 3);
		this.setBlock(x + 8, y + 14, z + 2, Blocks.AIR, 0, 3);
		this.setBlock(x + 9, y + 14, z + 2, Blocks.AIR, 0, 3);
		this.setBlock(x + 10, y + 14, z + 2, Blocks.STONEBRICK, 0, 3);
		this.setBlock(x + 0, y + 14, z + 3, Blocks.STONEBRICK, 0, 3);
		this.setBlock(x + 1, y + 14, z + 3, Blocks.AIR, 0, 3);
		this.setBlock(x + 2, y + 14, z + 3, Blocks.AIR, 0, 3);
		this.setBlock(x + 3, y + 14, z + 3, Blocks.AIR, 0, 3);
		this.setBlock(x + 4, y + 14, z + 3, Blocks.AIR, 0, 3);
		this.setBlock(x + 5, y + 14, z + 3, Blocks.AIR, 0, 3);
		this.setBlock(x + 6, y + 14, z + 3, Blocks.AIR, 0, 3);
		this.setBlock(x + 7, y + 14, z + 3, Blocks.AIR, 0, 3);
		this.setBlock(x + 8, y + 14, z + 3, Blocks.AIR, 0, 3);
		this.setBlock(x + 9, y + 14, z + 3, Blocks.AIR, 0, 3);
		this.setBlock(x + 10, y + 14, z + 3, Blocks.STONEBRICK, 0, 3);
		this.setBlock(x + 0, y + 14, z + 4, Blocks.STONEBRICK, 0, 3);
		this.setBlock(x + 1, y + 14, z + 4, Blocks.AIR, 0, 3);
		this.setBlock(x + 2, y + 14, z + 4, Blocks.AIR, 0, 3);
		this.setBlock(x + 3, y + 14, z + 4, Blocks.AIR, 0, 3);
		this.setBlock(x + 4, y + 14, z + 4, Blocks.AIR, 0, 3);
		this.setBlock(x + 5, y + 14, z + 4, Blocks.AIR, 0, 3);
		this.setBlock(x + 6, y + 14, z + 4, Blocks.AIR, 0, 3);
		this.setBlock(x + 7, y + 14, z + 4, Blocks.AIR, 0, 3);
		this.setBlock(x + 8, y + 14, z + 4, Blocks.AIR, 0, 3);
		this.setBlock(x + 9, y + 14, z + 4, Blocks.AIR, 0, 3);
		this.setBlock(x + 10, y + 14, z + 4, Blocks.STONEBRICK, 0, 3);
		this.setBlock(x + 0, y + 14, z + 5, Blocks.STONEBRICK, 0, 3);
		this.setBlock(x + 1, y + 14, z + 5, Blocks.AIR, 0, 3);
		this.setBlock(x + 2, y + 14, z + 5, Blocks.AIR, 0, 3);
		this.setBlock(x + 3, y + 14, z + 5, Blocks.AIR, 0, 3);
		this.setBlock(x + 4, y + 14, z + 5, Blocks.AIR, 0, 3);
		this.setBlock(x + 5, y + 14, z + 5, Blocks.AIR, 0, 3);
		this.setBlock(x + 6, y + 14, z + 5, Blocks.AIR, 0, 3);
		this.setBlock(x + 7, y + 14, z + 5, Blocks.AIR, 0, 3);
		this.setBlock(x + 8, y + 14, z + 5, Blocks.AIR, 0, 3);
		this.setBlock(x + 9, y + 14, z + 5, Blocks.AIR, 0, 3);
		this.setBlock(x + 10, y + 14, z + 5, Blocks.STONEBRICK, 0, 3);
		this.setBlock(x + 0, y + 14, z + 6, Blocks.STONEBRICK, 0, 3);
		this.setBlock(x + 1, y + 14, z + 6, Blocks.AIR, 0, 3);
		this.setBlock(x + 2, y + 14, z + 6, Blocks.AIR, 0, 3);
		this.setBlock(x + 3, y + 14, z + 6, Blocks.AIR, 0, 3);
		this.setBlock(x + 4, y + 14, z + 6, Blocks.AIR, 0, 3);
		this.setBlock(x + 5, y + 14, z + 6, Blocks.AIR, 0, 3);
		this.setBlock(x + 6, y + 14, z + 6, Blocks.AIR, 0, 3);
		this.setBlock(x + 7, y + 14, z + 6, Blocks.AIR, 0, 3);
		this.setBlock(x + 8, y + 14, z + 6, Blocks.STONE_BRICK_STAIRS, 6, 3);
		this.setBlock(x + 9, y + 14, z + 6, Blocks.STONE_BRICK_STAIRS, 6, 3);
		this.setBlock(x + 10, y + 14, z + 6, Blocks.STONEBRICK, 0, 3);
		this.setBlock(x + 0, y + 14, z + 7, Blocks.STONEBRICK, 0, 3);
		this.setBlock(x + 1, y + 14, z + 7, Blocks.AIR, 0, 3);
		this.setBlock(x + 2, y + 14, z + 7, Blocks.AIR, 0, 3);
		this.setBlock(x + 3, y + 14, z + 7, Blocks.AIR, 0, 3);
		this.setBlock(x + 4, y + 14, z + 7, Blocks.AIR, 0, 3);
		this.setBlock(x + 5, y + 14, z + 7, Blocks.AIR, 0, 3);
		this.setBlock(x + 6, y + 14, z + 7, Blocks.AIR, 0, 3);
		this.setBlock(x + 7, y + 14, z + 7, Blocks.AIR, 0, 3);
		this.setBlock(x + 8, y + 14, z + 7, Blocks.STONEBRICK, 0, 3);
		this.setBlock(x + 9, y + 14, z + 7, Blocks.MOB_SPAWNER, 0, 3);
		this.setBlock(x + 10, y + 14, z + 7, Blocks.STONEBRICK, 0, 3);
		this.setBlock(x + 0, y + 14, z + 8, Blocks.STONEBRICK, 0, 3);
		this.setBlock(x + 1, y + 14, z + 8, Blocks.AIR, 0, 3);
		this.setBlock(x + 2, y + 14, z + 8, Blocks.AIR, 0, 3);
		this.setBlock(x + 3, y + 14, z + 8, Blocks.AIR, 0, 3);
		this.setBlock(x + 4, y + 14, z + 8, Blocks.AIR, 0, 3);
		this.setBlock(x + 5, y + 14, z + 8, Blocks.AIR, 0, 3);
		this.setBlock(x + 6, y + 14, z + 8, Blocks.AIR, 0, 3);
		this.setBlock(x + 7, y + 14, z + 8, Blocks.STONE_BRICK_STAIRS, 0, 3);
		this.setBlock(x + 8, y + 14, z + 8, Blocks.STONEBRICK, 0, 3);
		this.setBlock(x + 9, y + 14, z + 8, Blocks.STONEBRICK, 0, 3);
		this.setBlock(x + 10, y + 14, z + 8, Blocks.STONEBRICK, 0, 3);
		this.setBlock(x + 1, y + 14, z + 9, Blocks.STONEBRICK, 0, 3);
		this.setBlock(x + 2, y + 14, z + 9, Blocks.AIR, 0, 3);
		this.setBlock(x + 3, y + 14, z + 9, Blocks.AIR, 0, 3);
		this.setBlock(x + 4, y + 14, z + 9, Blocks.AIR, 0, 3);
